Workbook

Sheet PUNTUALIDAD
A1: id | B1: id_servicio | C1: des | D1: Tipo de Viaje | E1: car | F1: shift | G1: group | H1: start_date | I1: start_time | J1: start_eta | K1: start_status | L1: end_date | M1: end_time | N1: end_eta | O1: end_status | P1: operador | Q1: no. de nomina | R1: Sem Via | S1: SALIDA | T1: LLEGADA | U1: Estatus Salida | V1: Estatus Llegada | W1: Estatus | X1: Semana | Y1: Puntualidad | Z1: concat | AA1: supervisor2 | AB1: gte | AC1: CONCAT2 | AD1: ID Ruta | AE1: Turno | AF1: Dashtrax
A2: 175716336 | B2: E-MOL-T1-R0010 | C2: Tlaquepaque 1 | D2: N | E2: 13294 | F2: IN | G2: MOLEX | H2: 46243 | I2: 0.19097222 | J2: 0.19791667 | K2: done | L2: 46243 | M2: 0.26041667 | N2: 0.26064815 | O2: done | P2: GUTIERREZ ROSALES ABNER ABRAHAM | Q2: 14118625 | R2: 33 | S2: 0.0069444444 | T2: 0.00023148148 | U2: Inicia tarde | V2: Llega a Tiempo | W2: Inicia tarde-Llega a Tiempo | X2: 33 | Y2: NO | Z2: Tlaquepaque 1MOLEX | AA2: VICTOR C. | AB2: Leopoldo V. | AC2: MOLEXTlaquepaque 1 | AD2: E-MOL-R0010 | AE2: T1 | AF2: Tlaquepaque 1-R0010-04:35
A3: 175715031 | B3: E-SAN-T1-R0427 | C3: Dominical Tesistan Miramar | D3: N | E3: 5474 | F3: IN | G3: SANMINA GDL | H3: 46243 | I3: 0.19444444 | J3: 0.20138889 | K3: done | L3: 46243 | M3: 0.26736111 | N3: 0.26826389 | O3: done | P3: JEUDY X WANDY | Q3: 14117400 | R3: 33 | S3: 0.0069444444 | T3: 0.00090277778 | U3: Inicia tarde | V3: Llega a Tiempo | W3: Inicia tarde-Llega a Tiempo | X3: 33 | Y3: NO | Z3: Dominical Tesistan MiramarSANMINA GDL | AA3: PABLO F. | AB3: Felipe M. | AC3: SANMINA GDLDominical Tesistan Miramar | AD3: E-SAN-R0427 | AE3: T1 | AF3: Dominical Tesistan Miramar-R0427-04:40
A4: 175718425 | B4: E-PIS-T1-R0027 | C4: Las Juntas | D4: N | E4: 4432 | F4: IN | G4: PIS-PISA | H4: 46243 | I4: 0.19444444 | J4: 0.19791667 | K4: done | L4: 46243 | M4: 0.26736111 | N4: 0.25284722 | O4: done | P4: RIQUER HERNANDEZ ERWIN ALEXI | Q4: 14123920 | R4: 33 | S4: 0.0034722222 | T4: -0.014513889 | U4: Inicia tarde | V4: Llega a Tiempo | W4: Inicia tarde-Llega a Tiempo | X4: 33 | Y4: NO | Z4: Las JuntasPIS-PISA | AA4: DAVID C. | AB4: Felipe M. | AC4: PIS-PISALas Juntas | AD4: E-PIS-R0027 | AE4: T1 | AF4: Las Juntas-R0027-04:40
A5: 175714307 | B5: E-ZLT-T1-R0009 | C5: Poncitlan | D5: N | E5: 13842 | F5: IN | G5: ZOLTEK GDL | H5: 46243 | I5: 0.19583333 | J5: 0.21180556 | K5: done | L5: 46243 | M5: 0.26041667 | N5: 0.27068287 | O5: done | P5: NUÑEZ CABRERA ERICK NAZARET | Q5: 14119701 | R5: 33 | S5: 0.015972222 | T5: 0.010266204 | U5: Inicia tarde | V5: Llega tarde | W5: Inicia tarde-Llega tarde | X5: 33 | Y5: NO | Z5: PoncitlanZOLTEK GDL | AA5: CARLOS C. | AB5: Ilse M. | AC5: ZOLTEK GDLPoncitlan | AD5: E-ZLT-R0009 | AE5: T1 | AF5: Poncitlan-R0009-04:42
A6: 175710555 | B6: E-CUP-T1-R0001 | C6: Chulavista | D6: N | E6: 6384 | F6: IN | G6: CUPRUM GDL | H6: 46243 | I6: 0.20138889 | J6: 0.20694444 | K6: done | L6: 46243 | M6: 0.24652778 | N6: 0.24583333 | O6: done | P6: OROZCO GUERRERO GERARDO DANIEL | Q6: 14122871 | R6: 33 | S6: 0.0055555556 | T6: -0.00069444444 | U6: Inicia tarde | V6: Llega a Tiempo | W6: Inicia tarde-Llega a Tiempo | X6: 33 | Y6: NO | Z6: ChulavistaCUPRUM GDL | AA6: DAVID M | AB6: Ilse M. | AC6: CUPRUM GDLChulavista | AD6: E-CUP-R0001 | AE6: T1 | AF6: Chulavista-R0001-04:50
A7: 175767594 | B7: E-SAN-T1-R0060 | C7: Arquitectura | D7: N | E7: 11209 | F7: IN | G7: SANMINA GDL | H7: 46243 | I7: 0.20138889 | J7: 0.23194444 | K7: done | L7: 46243 | M7: 0.26736111 | N7: 0.26388889 | O7: done | P7: CUENCA PERAL BONFILIO | Q7: 14122230 | R7: 33 | S7: 0.030555556 | T7: -0.0034722222 | U7: Inicia tarde | V7: Llega a Tiempo | W7: Inicia tarde-Llega a Tiempo | X7: 33 | Y7: NO | Z7: ArquitecturaSANMINA GDL | AA7: PABLO F. | AB7: Felipe M. | AC7: SANMINA GDLArquitectura | AD7: E-SAN-R0060 | AE7: T1 | AF7: Arquitectura-R0060-04:50
A8: 175714736 | B8: E-SM4-T1-R0129 | C8: Dominical San Sebastian 2 T1 | D8: N | E8: 7915 | F8: IN | G8: SANMINA TLAJOMULCO | H8: 46243 | I8: 0.20208333 | J8: 0.21458333 | K8: done | L8: 46243 | M8: 0.26736111 | N8: 0.25585648 | O8: done | P8: GONZALEZ VACA EDGAR ARTURO | Q8: 14119324 | R8: 33 | S8: 0.0125 | T8: -0.01150463 | U8: Inicia tarde | V8: Llega a Tiempo | W8: Inicia tarde-Llega a Tiempo | X8: 33 | Y8: NO | Z8: Dominical San Sebastian 2 T1SANMINA TLAJOMULCO | AA8: CUAUHTEMOC M. | AB8: Felipe M. | AC8: SANMINA TLAJOMULCODominical San Sebastian 2 T1 | AD8: E-SM4-R0129 | AE8: T1 | AF8: Dominical San Sebastian 2 T1-R0129-04:51
A9: 175714733 | B9: E-SM4-T1-R0128 | C9: Dominical Prepa 13 - Balcone de Santa Maria | D9: N | E9: 15993 | F9: IN | G9: SANMINA TLAJOMULCO | H9: 46243 | I9: 0.20486111 | J9: 0.21041667 | K9: done | L9: 46243 | M9: 0.26736111 | N9: 0.26722222 | O9: done | P9: HERNANDEZ ORTEGA RAUL | Q9: 14103952 | R9: 33 | S9: 0.0055555556 | T9: -0.00013888889 | U9: Inicia tarde | V9: Llega a Tiempo | W9: Inicia tarde-Llega a Tiempo | X9: 33 | Y9: NO | Z9: Dominical Prepa 13 - Balcone de Santa MariaSANMINA TLAJOMULCO | AA9: CUAUHTEMOC M. | AB9: Felipe M. | AC9: SANMINA TLAJOMULCODominical Prepa 13 - Balcone de Santa Maria | AD9: E-SM4-R0128 | AE9: T1 | AF9: Dominical Prepa 13 - Balcone de Santa Maria-R0128-04:55
A10: 175714751 | B10: E-SM4-T1-R0137 | C10: Dominical Santa Fe 3 | D10: N | E10: 16769 | F10: IN | G10: SANMINA TLAJOMULCO | H10: 46243 | I10: 0.20833333 | J10: 0.21388889 | K10: done | L10: 46243 | M10: 0.26736111 | N10: 0.24962963 | O10: done | P10: RAMOS DELGADO FRANCISCO | Q10: 14108916 | R10: 33 | S10: 0.0055555556 | T10: -0.017731481 | U10: Inicia tarde | V10: Llega a Tiempo | W10: Inicia tarde-Llega a Tiempo | X10: 33 | Y10: NO | Z10: Dominical Santa Fe 3SANMINA TLAJOMULCO | AA10: CUAUHTEMOC M. | AB10: Felipe M. | AC10: SANMINA TLAJOMULCODominical Santa Fe 3 | AD10: E-SM4-R0137 | AE10: T1 | AF10: Dominical Santa Fe 3-R0137-05:00
A11: 175718461 | B11: E-PIS-T1-R0045 | C11: Santa Anita | D11: N | E11: 4875 | F11: IN | G11: PIS-PISA | H11: 46243 | I11: 0.20833333 | J11: 0.21319444 | K11: done | L11: 46243 | M11: 0.26736111 | N11: 0.25277778 | O11: done | P11: JUAREZ FAVELA JULIO CESAR | Q11: 14123004 | R11: 33 | S11: 0.0048611111 | T11: -0.014583333 | U11: Inicia tarde | V11: Llega a Tiempo | W11: Inicia tarde-Llega a Tiempo | X11: 33 | Y11: NO | Z11: Santa AnitaPIS-PISA | AA11: DAVID C. | AB11: Felipe M. | AC11: PIS-PISASanta Anita | AD11: E-PIS-R0045 | AE11: T1 | AF11: Santa Anita-R0045-05:00
A12: 175762267 | B12: E-SK1-T1-R0029 | C12: Lomas del Sur | D12: N | E12: 13409 | F12: IN | G12: SANMINA KAMPUS 16 | H12: 46243 | I12: 0.20833333 | J12: 0.22777778 | K12: done | L12: 46243 | M12: 0.26736111 | N12: 0.27903935 | O12: done | P12: MENDOZA DE LUCIO NICOLAS JOSE | Q12: 14123334 | R12: 33 | S12: 0.019444444 | T12: 0.011678241 | U12: Inicia tarde | V12: Llega tarde | W12: Inicia tarde-Llega tarde | X12: 33 | Y12: NO | Z12: Lomas del SurSANMINA KAMPUS 16 | AA12: BRIAN A. | AB12: Felipe M. | AC12: SANMINA KAMPUS 16Lomas del Sur | AD12: E-SK1-R0029 | AE12: T1 | AF12: Lomas del Sur-R0029-05:00
A13: 175713605 | B13: E-SK1-T1-R0015 | C13: Chulavista 2 T1 | D13: N | E13: 16734 | F13: IN | G13: SANMINA KAMPUS 16 | H13: 46243 | I13: 0.21180556 | J13: 0.21666667 | K13: done | L13: 46243 | M13: 0.26736111 | N13: 0.25275463 | O13: done | P13: VAZQUEZ FLORES FABIAN | Q13: 14107967 | R13: 33 | S13: 0.0048611111 | T13: -0.014606481 | U13: Inicia tarde | V13: Llega a Tiempo | W13: Inicia tarde-Llega a Tiempo | X13: 33 | Y13: NO | Z13: Chulavista 2 T1SANMINA KAMPUS 16 | AA13: BRIAN A. | AB13: Felipe M. | AC13: SANMINA KAMPUS 16Chulavista 2 T1 | AD13: E-SK1-R0015 | AE13: T1 | AF13: Chulavista 2 T1-R0015-05:05
... A20: 175718828 | B20: E-PIS-T1-R0091 | C20: La Noria | D20: N | E20: 4532 | F20: IN | G20: PIS-PISA | H20: 46243 | I20: 0.22569444 | J20: 0.23125 | K20: done | L20: 46243 | M20: 0.26736111 | N20: 0.25138889 | O20: done | P20: CHAVEZ CADENA ALBERTO | Q20: 14121158 | R20: 33 | S20: 0.0055555556 | T20: -0.015972222 | U20: Inicia tarde | V20: Llega a Tiempo | W20: Inicia tarde-Llega a Tiempo | X20: 33 | Y20: NO | Z20: La NoriaPIS-PISA | AA20: DAVID C. | AB20: Felipe M. | AC20: PIS-PISALa Noria | AD20: E-PIS-R0091 | AE20: T1 | AF20: La Noria-R0091-05:25
A21: 175715903 | B21: E-FOX-T1-R0025 | C21: Oblatos 1 | D21: N | E21: 15320 | F21: IN | G21: FOXCONN | H21: 46243 | I21: 0.22916667 | J21: 0.23402778 | K21: done | L21: 46243 | M21: 0.28125 | N21: 0.27149306 | O21: done | P21: OPERADOR NO REGISTRADO | R21: 33 | S21: 0.0048611111 | T21: -0.0097569444 | U21: Inicia tarde | V21: Llega a Tiempo | W21: Inicia tarde-Llega a Tiempo | X21: 33 | Y21: NO | Z21: Oblatos 1FOXCONN | AA21: CANDELAS | AB21: Leopoldo V. | AC21: FOXCONNOblatos 1 | AD21: E-FOX-R0025 | AE21: T1 | AF21: Oblatos 1-R0025-05:30
A22: 175718138 | B22: E-FOX-T1-R0098 | C22: El Colli | D22: N | E22: 14692 | F22: IN | G22: FOXCONN | H22: 46243 | I22: 0.22916667 | J22: 0.23680556 | K22: done | L22: 46243 | M22: 0.28125 | N22: 0.27041667 | O22: done | P22: REA PINEDO SALVADOR MANUEL | Q22: 14123725 | R22: 33 | S22: 0.0076388889 | T22: -0.010833333 | U22: Inicia tarde | V22: Llega a Tiempo | W22: Inicia tarde-Llega a Tiempo | X22: 33 | Y22: NO | Z22: El ColliFOXCONN | AA22: CANDELAS | AB22: Leopoldo V. | AC22: FOXCONNEl Colli | AD22: E-FOX-R0098 | AE22: T1 | AF22: El Colli-R0098-05:30
A23: 175716159 | B23: E-FOX-T1-R0036 | C23: Santa Fe 1 | D23: N | E23: 13754 | F23: IN | G23: FOXCONN | H23: 46243 | I23: 0.23263889 | J23: 0.24097222 | K23: done | L23: 46243 | M23: 0.28125 | N23: 0.26243056 | O23: done | P23: ROLDAN CASTILLO HECTOR MISAEL | Q23: 14118889 | R23: 33 | S23: 0.0083333333 | T23: -0.018819444 | U23: Inicia tarde | V23: Llega a Tiempo | W23: Inicia tarde-Llega a Tiempo | X23: 33 | Y23: NO | Z23: Santa Fe 1FOXCONN | AA23: DIEGOVO. | AB23: Leopoldo V. | AC23: FOXCONNSanta Fe 1 | AD23: E-FOX-R0036 | AE23: T1 | AF23: Santa Fe 1-R0036-05:35
A24: 175717361 | B24: E-FOX-T1-R0073 | C24: Valle De Tejeda | D24: N | E24: 13847 | F24: IN | G24: FOXCONN | H24: 46243 | I24: 0.23263889 | J24: 0.24166667 | K24: done | L24: 46243 | M24: 0.28125 | N24: 0.27049769 | O24: done | P24: TORRES GUARDADO JOSE LUIS | Q24: 14104599 | R24: 33 | S24: 0.0090277778 | T24: -0.010752315 | U24: Inicia tarde | V24: Llega a Tiempo | W24: Inicia tarde-Llega a Tiempo | X24: 33 | Y24: NO | Z24: Valle De TejedaFOXCONN | AA24: WENDY H. | AB24: Leopoldo V. | AC24: FOXCONNValle De Tejeda | AD24: E-FOX-R0073 | AE24: T1 | AF24: Valle De Tejeda-R0073-05:35
A25: 175718578 | B25: E-FOX-T1-R0114 | C25: Tonala 2 | D25: N | E25: 13289 | F25: IN | G25: FOXCONN | H25: 46243 | I25: 0.24166667 | J25: 0.24791667 | K25: done | L25: 46243 | M25: 0.28125 | N25: 0.27028935 | O25: done | P25: GARCIA ROMERO JOSE ALFREDO | Q25: 14118956 | R25: 33 | S25: 0.00625 | T25: -0.010960648 | U25: Inicia tarde | V25: Llega a Tiempo | W25: Inicia tarde-Llega a Tiempo | X25: 33 | Y25: NO | Z25: Tonala 2FOXCONN | AA25: CANDELAS | AB25: Leopoldo V. | AC25: FOXCONNTonala 2 | AD25: E-FOX-R0114 | AE25: T1 | AF25: Tonala 2-R0114-05:48
A26: 175717615 | B26: E-FOX-T1-R0086 | C26: Las Villas | D26: N | E26: 13512 | F26: IN | G26: FOXCONN | H26: 46243 | I26: 0.25 | J26: 0.26666667 | K26: done | L26: 46243 | M26: 0.28125 | N26: 0.28310185 | O26: done | P26: SANCHEZ BUENROSTRO BRYAN ALEJANDRO | Q26: 14123246 | R26: 33 | S26: 0.016666667 | T26: 0.0018518519 | U26: Inicia tarde | V26: Llega a Tiempo | W26: Inicia tarde-Llega a Tiempo | X26: 33 | Y26: NO | Z26: Las VillasFOXCONN | AA26: DIEGOVO. | AB26: Leopoldo V. | AC26: FOXCONNLas Villas | AD26: E-FOX-R0086 | AE26: T1 | AF26: Las Villas-R0086-06:00
A27: 175710556 | B27: E-CUP-T2-R0001 | C27: Chulavista | D27: N | E27: 6384 | F27: IN | G27: CUPRUM GDL | H27: 46243 | I27: 0.51388889 | J27: 0.52222222 | K27: done | L27: 46243 | M27: 0.57986111 | N27: 0.59166667 | O27: done | P27: OROZCO GUERRERO GERARDO DANIEL | Q27: 14122871 | R27: 33 | S27: 0.0083333333 | T27: 0.011805556 | U27: Inicia tarde | V27: Llega tarde | W27: Inicia tarde-Llega tarde | X27: 33 | Y27: NO | Z27: ChulavistaCUPRUM GDL | AA27: DAVID M | AB27: Ilse M. | AC27: CUPRUM GDLChulavista | AD27: E-CUP-R0001 | AE27: T2 | AF27: Chulavista-R0001-12:20
A28: 175710013 | B28: E-PEP-T2-R0001 | C28: Moctezuma Santa Fe | D28: N | E28: 10363 | F28: IN | G28: PEPSICO GDL | H28: 46243 | I28: 0.52083333 | J28: 0.52430556 | K28: done | L28: 46243 | M28: 0.60416667 | N28: 0.57460648 | O28: done | P28: NUNGARAY BUENROSTRO SALVADOR | Q28: 14119018 | R28: 33 | S28: 0.0034722222 | T28: -0.029560185 | U28: Inicia tarde | V28: Llega a Tiempo | W28: Inicia tarde-Llega a Tiempo | X28: 33 | Y28: NO | Z28: Moctezuma Santa FePEPSICO GDL | AA28: DANIEL | AB28: Leopoldo V. | AC28: PEPSICO GDLMoctezuma Santa Fe | AD28: E-PEP-R0001 | AE28: T2 | AF28: Moctezuma Santa Fe-R0001-12:30
A29: 175714308 | B29: E-ZLT-T2-R0009 | C29: Poncitlan | D29: N | E29: 13728 | F29: IN | G29: ZOLTEK GDL | H29: 46243 | I29: 0.52083333 | J29: 0.53125 | K29: done | L29: 46243 | M29: 0.59375 | N29: 0.58751157 | O29: done | P29: RAMOS ANGUIANO SERGIO DAVID | Q29: 14102288 | R29: 33 | S29: 0.010416667 | T29: -0.0062384259 | U29: Inicia tarde | V29: Llega a Tiempo | W29: Inicia tarde-Llega a Tiempo | X29: 33 | Y29: NO | Z29: PoncitlanZOLTEK GDL | AA29: CARLOS C. | AB29: Ilse M. | AC29: ZOLTEK GDLPoncitlan | AD29: E-ZLT-R0009 | AE29: T2 | AF29: Poncitlan-R0009-12:30
A30: 175715520 | B30: E-HER-T2-R0017 | C30: Arenales | D30: N | E30: 15192 | F30: IN | G30: HERSHEYS | H30: 46243 | I30: 0.52083333 | J30: 0.52569444 | K30: done | L30: 46243 | M30: 0.60416667 | N30: 0.56725694 | O30: done | P30: VACA BRAVO CARLOS GONZALO | Q30: 14110039 | R30: 33 | S30: 0.0048611111 | T30: -0.036909722 | U30: Inicia tarde | V30: Llega a Tiempo | W30: Inicia tarde-Llega a Tiempo | X30: 33 | Y30: NO | Z30: ArenalesHERSHEYS | AA30: CARLOS C. | AB30: Ilse M. | AC30: HERSHEYSArenales | AD30: E-HER-R0017 | AE30: T2 | AF30: Arenales-R0017-12:30
A31: 175713902 | B31: E-PEM-T2-R0013 | C31: Mixing Santa Fe | D31: N | E31: 10743 | F31: IN | G31: PEPSICO MIXING | H31: 46243 | I31: 0.52777778 | J31: 0.53125 | K31: done | L31: 46243 | M31: 0.60416667 | N31: 0.60096065 | O31: done | P31: DEL TORO MARTINEZ HECTOR JOSE | Q31: 14103470 | R31: 33 | S31: 0.0034722222 | T31: -0.0032060185 | U31: Inicia tarde | V31: Llega a Tiempo | W31: Inicia tarde-Llega a Tiempo | X31: 33 | Y31: NO | Z31: Mixing Santa FePEPSICO MIXING | AA31: DANIEL | AB31: Leopoldo V. | AC31: PEPSICO MIXINGMixing Santa Fe | AD31: E-PEM-R0013 | AE31: T2 | AF31: Mixing Santa Fe-R0013-12:40
A32: 175713633 | B32: E-SK1-T2-R0028 | C32: Juanacatlan | D32: N | E32: 16733 | F32: IN | G32: SANMINA KAMPUS 16 | H32: 46243 | I32: 0.53958333 | J32: 0.54444444 | K32: done | L32: 46243 | M32: 0.60069444 | N32: 0.58489583 | O32: done | P32: CORTES ARMENTA HERNAN | Q32: 14103106 | R32: 33 | S32: 0.0048611111 | T32: -0.015798611 | U32: Inicia tarde | V32: Llega a Tiempo | W32: Inicia tarde-Llega a Tiempo | X32: 33 | Y32: NO | Z32: JuanacatlanSANMINA KAMPUS 16 | AA32: BRIAN A. | AB32: Felipe M. | AC32: SANMINA KAMPUS 16Juanacatlan | AD32: E-SK1-R0028 | AE32: T2 | AF32: Juanacatlan-R0028-12:57
A33: 175715029 | B33: E-SAN-T2-R0425 | C33: Dominical Jauja-San pedrito T1 y T2 | D33: N | E33: 16743 | F33: IN | G33: SANMINA GDL | H33: 46243 | I33: 0.54166667 | J33: 0.54791667 | K33: done | L33: 46243 | M33: 0.60069444 | N33: 0.59111111 | O33: done | P33: TABARES FLORES OSCAR ALEJAND | Q33: 14100731 | R33: 33 | S33: 0.00625 | T33: -0.0095833333 | U33: Inicia tarde | V33: Llega a Tiempo | W33: Inicia tarde-Llega a Tiempo | X33: 33 | Y33: NO | Z33: Dominical Jauja-San pedrito T1 y T2SANMINA GDL | AA33: PABLO F. | AB33: Felipe M. | AC33: SANMINA GDLDominical Jauja-San pedrito T1 y T2 | AD33: E-SAN-R0425 | AE33: T2 | AF33: Dominical Jauja-San pedrito T1 y T2-R0425-13:00
... A43: 175718825 | B43: E-PIS-T2-R0089 | C43: Valle Dorado | D43: N | E43: 4411 | F43: IN | G43: PIS-PISA | H43: 46243 | I43: 0.70833333 | J43: 0.71666667 | K43: done | L43: 46243 | M43: 0.76736111 | N43: 0.75540509 | O43: done | P43: PANTOJA PERALES ALAN KERIM | Q43: 14123080 | R43: 33 | S43: 0.0083333333 | T43: -0.011956019 | U43: Inicia tarde | V43: Llega a Tiempo | W43: Inicia tarde-Llega a Tiempo | X43: 33 | Y43: NO | Z43: Valle DoradoPIS-PISA | AA43: DAVID C. | AB43: Felipe M. | AC43: PIS-PISAValle Dorado | AD43: E-PIS-R0089 | AE43: T2 | AF43: Valle Dorado-R0089-17:00
A44: 175713572 | B44: E-PAQ-T2-R0007 | C44: Juan de la Barrera Fin de semana | D44: N | E44: 12897 | F44: IN | G44: PAQUETEXPRESS GDL | H44: 46243 | I44: 0.72152778 | J44: 0.725 | K44: done | L44: 46243 | M44: 0.79166667 | N44: 0.78528935 | O44: done | P44: VALLADOLID MARTINEZ LUIS ALEJANDRO | Q44: 14122809 | R44: 33 | S44: 0.0034722222 | T44: -0.0063773148 | U44: Inicia tarde | V44: Llega a Tiempo | W44: Inicia tarde-Llega a Tiempo | X44: 33 | Y44: NO | Z44: Juan de la Barrera Fin de semanaPAQUETEXPRESS GDL | AA44: DAVID D. | AB44: Leopoldo V. | AC44: PAQUETEXPRESS GDLJuan de la Barrera Fin de semana | AD44: #N/A | AE44: T2 | AF44: Juan de la Barrera Fin de semana-R0007-17:19
A45: 175718837 | B45: E-PIS-T2-R0095 | C45: Las Vias | D45: N | E45: 4534 | F45: IN | G45: PIS-PISA | H45: 46243 | I45: 0.72222222 | J45: 0.72986111 | K45: done | L45: 46243 | M45: 0.76736111 | N45: 0.75138889 | O45: done | P45: DELGADILLO SANCHEZ EDSON FABIA | Q45: 14122113 | R45: 33 | S45: 0.0076388889 | T45: -0.015972222 | U45: Inicia tarde | V45: Llega a Tiempo | W45: Inicia tarde-Llega a Tiempo | X45: 33 | Y45: NO | Z45: Las ViasPIS-PISA | AA45: DAVID C. | AB45: Felipe M. | AC45: PIS-PISALas Vias | AD45: E-PIS-R0095 | AE45: T2 | AF45: Las Vias-R0095-17:20
A46: 175710014 | B46: E-PEP-T3-R0001 | C46: Moctezuma Santa Fe | D46: N | E46: 10363 | F46: IN | G46: PEPSICO GDL | H46: 46243 | I46: 0.79166667 | J46: 0.79791667 | K46: done | L46: 46243 | M46: 0.86111111 | N46: 0.84425926 | O46: done | P46: NUNGARAY BUENROSTRO SALVADOR | Q46: 14119018 | R46: 33 | S46: 0.00625 | T46: -0.016851852 | U46: Inicia tarde | V46: Llega a Tiempo | W46: Inicia tarde-Llega a Tiempo | X46: 33 | Y46: NO | Z46: Moctezuma Santa FePEPSICO GDL | AA46: DANIEL | AB46: Leopoldo V. | AC46: PEPSICO GDLMoctezuma Santa Fe | AD46: E-PEP-R0001 | AE46: T3 | AF46: Moctezuma Santa Fe-R0001-19:00
A47: 175710560 | B47: E-CUP-T1-R0002 | C47: Polanco | D47: N | E47: 14891 | F47: IN | G47: CUPRUM GDL | H47: 46243 | I47: 0.81944444 | J47: 0.82291667 | K47: done | L47: 46243 | M47: 0.88888889 | N47: 0.87083333 | O47: done | P47: MUÑOZ PLASCENCIA DAVID RAUDEL | Q47: 14122495 | R47: 33 | S47: 0.0034722222 | T47: -0.018055556 | U47: Inicia tarde | V47: Llega a Tiempo | W47: Inicia tarde-Llega a Tiempo | X47: 33 | Y47: NO | Z47: PolancoCUPRUM GDL | AA47: DAVID M | AB47: Ilse M. | AC47: CUPRUM GDLPolanco | AD47: E-CUP-R0002 | AE47: T1 | AF47: Polanco-R0002-19:40
A48: 175710557 | B48: E-CUP-T3-R0001 | C48: Chulavista | D48: N | E48: 6384 | F48: IN | G48: CUPRUM GDL | H48: 46243 | I48: 0.83680556 | J48: 0.84097222 | K48: done | L48: 46243 | M48: 0.88888889 | N48: 0.88611111 | O48: done | P48: OROZCO GUERRERO GERARDO DANIEL | Q48: 14122871 | R48: 33 | S48: 0.0041666667 | T48: -0.0027777778 | U48: Inicia tarde | V48: Llega a Tiempo | W48: Inicia tarde-Llega a Tiempo | X48: 33 | Y48: NO | Z48: ChulavistaCUPRUM GDL | AA48: DAVID M | AB48: Ilse M. | AC48: CUPRUM GDLChulavista | AD48: E-CUP-R0001 | AE48: T3 | AF48: Chulavista-R0001-20:05
A49: 175716995 | B49: E-HLL-T3-R0039 | C49: Mezcala | D49: N | E49: 5538 | F49: IN | G49: HELLA GDL | H49: 46243 | I49: 0.84027778 | J49: 0.84513889 | K49: done | L49: 46243 | M49: 0.90625 | N49: 0.89722222 | O49: done | P49: VELAZQUEZ MENDEZ CESAR ARMANDO | Q49: 14122928 | R49: 33 | S49: 0.0048611111 | T49: -0.0090277778 | U49: Inicia tarde | V49: Llega a Tiempo | W49: Inicia tarde-Llega a Tiempo | X49: 33 | Y49: NO | Z49: MezcalaHELLA GDL | AA49: SIMON / EUGI | AB49: Ilse M. | AC49: HELLA GDLMezcala | AD49: E-HLL-R0039 | AE49: T3 | AF49: Mezcala-R0039-20:10
A50: 175716560 | B50: E-HER-T3-R0039 | C50: Tonala-Tateposco Dominical | D50: N | E50: 15765 | F50: IN | G50: HERSHEYS | H50: 46243 | I50: 0.85069444 | J50: 0.85416667 | K50: done | L50: 46243 | M50: 0.91666667 | N50: 0.89652778 | O50: done | P50: OLMEDO LORETO SERGIO MOISES AN | Q50: 14113198 | R50: 33 | S50: 0.0034722222 | T50: -0.020138889 | U50: Inicia tarde | V50: Llega a Tiempo | W50: Inicia tarde-Llega a Tiempo | X50: 33 | Y50: NO | Z50: Tonala-Tateposco DominicalHERSHEYS | AA50: CARLOS C. | AB50: Ilse M. | AC50: HERSHEYSTonala-Tateposco Dominical | AD50: E-HER-R0039 | AE50: T3 | AF50: Tonala-Tateposco Dominical-R0039-20:25
A51: 175717031 | B51: E-HLL-T3-R0057 | C51: Capilla | D51: N | E51: 11828 | F51: IN | G51: HELLA GDL | H51: 46243 | I51: 0.86458333 | J51: 0.87152778 | K51: done | L51: 46243 | M51: 0.90625 | N51: 0.89930556 | O51: done | P51: C.RUIZ PEREZ EUGUI | Q51: 14109002 | R51: 33 | S51: 0.0069444444 | T51: -0.0069444444 | U51: Inicia tarde | V51: Llega a Tiempo | W51: Inicia tarde-Llega a Tiempo | X51: 33 | Y51: NO | Z51: CapillaHELLA GDL | AA51: SIMON / EUGI | AB51: Ilse M. | AC51: HELLA GDLCapilla | AD51: E-HLL-R0057 | AE51: T3 | AF51: Capilla-R0057-20:45
A52: 175719526 | B52: E-SAN-T3-R0504 | C52: Dominical Zapopan | D52: N | E52: 4985 | F52: IN | G52: SANMINA GDL | H52: 46243 | I52: 0.86458333 | J52: 0.87152778 | K52: done | L52: 46243 | M52: 0.93402778 | N52: 0.93194444 | O52: done | P52: VILLAGRAN PEREZ ARMANDO | Q52: 14115536 | R52: 33 | S52: 0.0069444444 | T52: -0.0020833333 | U52: Inicia tarde | V52: Llega a Tiempo | W52: Inicia tarde-Llega a Tiempo | X52: 33 | Y52: NO | Z52: Dominical ZapopanSANMINA GDL | AA52: PABLO F. | AB52: Felipe M. | AC52: SANMINA GDLDominical Zapopan | AD52: E-SAN-R0504 | AE52: T3 | AF52: Dominical Zapopan-R0504-20:45
A53: 175713694 | B53: E-SK1-T3-R0042 | C53: Tonala T1 y T3 | D53: N | E53: 6983 | F53: IN | G53: SANMINA KAMPUS 16 | H53: 46243 | I53: 0.86805556 | J53: 0.98472222 | K53: done | L53: 46243 | M53: 0.93402778 | O53: start | P53: SANCHEZ BUSTAMANTE JUAN DIEGO | Q53: 14122320 | R53: 33 | S53: 0.11666667 | T53: -0.93402778 | U53: Inicia tarde | V53: Llega a Tiempo | W53: Inicia tarde-Llega a Tiempo | X53: 33 | Y53: NO | Z53: Tonala T1 y T3SANMINA KAMPUS 16 | AA53: BRIAN A. | AB53: Felipe M. | AC53: SANMINA KAMPUS 16Tonala T1 y T3 | AD53: E-SK1-R0042 | AE53: T3 | AF53: Tonala T1 y T3-R0042-20:50
A54: 175713625 | B54: E-SK1-T3-R0025 | C54: Juan Pablo II | D54: N | E54: 13844 | F54: IN | G54: SANMINA KAMPUS 16 | H54: 46243 | I54: 0.875 | J54: 0.87986111 | K54: done | L54: 46243 | M54: 0.93402778 | N54: 0.91805556 | O54: done | P54: TELLES PADILLA JOSE MANUEL | Q54: 14108222 | R54: 33 | S54: 0.0048611111 | T54: -0.015972222 | U54: Inicia tarde | V54: Llega a Tiempo | W54: Inicia tarde-Llega a Tiempo | X54: 33 | Y54: NO | Z54: Juan Pablo IISANMINA KAMPUS 16 | AA54: BRIAN A. | AB54: Felipe M. | AC54: SANMINA KAMPUS 16Juan Pablo II | AD54: E-SK1-R0025 | AE54: T3 | AF54: Juan Pablo II-R0025-21:00
A55: 175718984 | B55: E-SM4-T3-R0235 | C55: Dominical Santa Fe 1 T2 y T3 | D55: N | E55: 15996 | F55: IN | G55: SANMINA TLAJOMULCO | H55: 46243 | I55: 0.875 | J55: 0.87847222 | K55: done | L55: 46243 | M55: 0.93402778 | N55: 0.92430556 | O55: done | P55: GUERRERO CORTES SERGIO RICARDO | Q55: 14107393 | R55: 33 | S55: 0.0034722222 | T55: -0.0097222222 | U55: Inicia tarde | V55: Llega a Tiempo | W55: Inicia tarde-Llega a Tiempo | X55: 33 | Y55: NO | Z55: Dominical Santa Fe 1 T2 y T3SANMINA TLAJOMULCO | AA55: CUAUHTEMOC M. | AB55: Felipe M. | AC55: SANMINA TLAJOMULCODominical Santa Fe 1 T2 y T3 | AD55: E-SM4-R0235 | AE55: T3 | AF55: Dominical Santa Fe 1 T2 y T3-R0235-21:00
...

Sheet DMAS
A1: udn | B1: driver_name | C1: 46243 | D1: 46242 | E1: 46241 | F1: 46240 | G1: 46239 | H1: 46238 | I1: 46237 | J1: Nomina | K1: CEROS | L1: LOGUEO
A2: LIPU GDL | B2: GARCIA SALCEDO FRANCISCO JAVIE | C2: 4.63 | D2: 6.35 | E2: 8.1399 | F2: 6.2999 | G2: 5.9 | H2: 3.62 | I2: 1.77 | J2: 14109436 | K2: =COUNTIF(C2:I2,0) -> 0 | L2: =IF(K2>1,"NO LOGUEO","LOGUEO") -> LOGUEO
A3: LIPU GDL | B3: GARCIA RAZO VICTOR MANUEL | C3: 1.2 | D3: 3.46 | E3: 7.01 | F3: 6.51 | G3: 6.34 | H3: 5.05 | I3: 2.3 | J3: 14121809 | K3: =COUNTIF(C3:I3,0) -> 0 | L3: =IF(K3>1,"NO LOGUEO","LOGUEO") -> LOGUEO
A4: LIPU GDL | B4: AGUINAGA GUERRERO JOSE DAMIA | C4: 0.52 | D4: 7.01 | E4: 5.12 | F4: 8.31 | G4: 5.37 | H4: 8.78 | I4: 5.91 | J4: 14121728 | K4: =COUNTIF(C4:I4,0) -> 0 | L4: =IF(K4>1,"NO LOGUEO","LOGUEO") -> LOGUEO
A5: LIPU GDL | B5: DE LA CRUZ PLASCENCIA ARMANDO | C5: 10.53 | D5: 6.26 | E5: 2.69 | F5: 3.13 | G5: 2.9699 | H5: 3.35 | I5: 4.57 | J5: 14121733 | K5: =COUNTIF(C5:I5,0) -> 0 | L5: =IF(K5>1,"NO LOGUEO","LOGUEO") -> LOGUEO
A6: LIPU GDL | B6: SERRANO MACHUCA MARTIN DE JESU | C6: 4.25 | D6: 3.06 | E6: 7.97 | F6: 8.47 | G6: 5.1099 | H6: 4.5599 | I6: 8.33 | J6: 14104315 | K6: =COUNTIF(C6:I6,0) -> 0 | L6: =IF(K6>1,"NO LOGUEO","LOGUEO") -> LOGUEO
A7: LIPU GDL | B7: PROCOPIO MENDOZA JUAN FERNANDO | C7: 0.59 | D7: 8.61 | E7: 9.2 | F7: 13.18 | G7: 9.16 | H7: 10.19 | I7: 9.33 | J7: 14121522 | K7: =COUNTIF(C7:I7,0) -> 0 | L7: =IF(K7>1,"NO LOGUEO","LOGUEO") -> LOGUEO
A8: LIPU GDL | B8: PINEDA VELAZQUEZ PASCUAL | C8: 4.9499 | D8: 5.03 | E8: 8.03 | F8: 8.4599 | G8: 6.2 | H8: 6.6 | I8: 4.6899 | J8: 14118892 | K8: =COUNTIF(C8:I8,0) -> 0 | L8: =IF(K8>1,"NO LOGUEO","LOGUEO") -> LOGUEO
A9: LIPU GDL | B9: SANTOS GOMEZ ARTURO | C9: 5.1899 | D9: 4.92 | E9: 1.8 | F9: 2.41 | G9: 4.1 | H9: 3.49 | I9: 4.47 | J9: 14112124 | K9: =COUNTIF(C9:I9,0) -> 0 | L9: =IF(K9>1,"NO LOGUEO","LOGUEO") -> LOGUEO
A10: LIPU GDL | B10: CHAVEZ MORA CESAR ADRIAN | C10: 4.26 | D10: 11.38 | E10: 11.7 | F10: 10.28 | G10: 9.3899 | H10: 11.36 | I10: 10.2899 | J10: 14121523 | K10: =COUNTIF(C10:I10,0) -> 0 | L10: =IF(K10>1,"NO LOGUEO","LOGUEO") -> LOGUEO
A11: LIPU GDL | B11: JIMENEZ QUIROZ JAVIER DE JESUS | C11: 1.6 | D11: 4.05 | E11: 5.8 | F11: 5.38 | G11: 5.8 | H11: 5.2 | I11: 4.45 | J11: 14119517 | K11: =COUNTIF(C11:I11,0) -> 0 | L11: =IF(K11>1,"NO LOGUEO","LOGUEO") -> LOGUEO
A12: LIPU GDL | B12: CLARO ROSALES JOSE MARIA | C12: 6.35 | D12: 1.72 | E12: 6.77 | F12: 3.1399 | G12: 6.35 | H12: 3.13 | I12: 6.8699 | J12: 14120850 | K12: =COUNTIF(C12:I12,0) -> 0 | L12: =IF(K12>1,"NO LOGUEO","LOGUEO") -> LOGUEO
A13: LIPU GDL | B13: REYES MARTINEZ MIGUEL ANGEL | C13: 5.87 | D13: 6.3599 | E13: 8.75 | F13: 8.1 | G13: 8.62 | H13: 7.9599 | I13: 7.5799 | J13: 14118184 | K13: =COUNTIF(C13:I13,0) -> 0 | L13: =IF(K13>1,"NO LOGUEO","LOGUEO") -> LOGUEO
... A221: LIPU GDL | B221: SANCHEZ PONCE JOSE ALBERTO | C221: 0 | D221: 9.4 | E221: 12.7399 | F221: 4.63 | G221: 8.59 | H221: 11.39 | I221: 5.55 | J221: 14100902 | K221: =COUNTIF(C221:I221,0) -> 1 | L221: =IF(K221>1,"NO LOGUEO","LOGUEO") -> LOGUEO
A222: LIPU GDL | B222: P.MARTINEZ LOPEZ PEDRO ALBERTO | C222: 0 | D222: 0.95 | E222: 2.47 | F222: 1.03 | G222: 1.22 | H222: 1.28 | I222: 1.92 | K222: =COUNTIF(C222:I222,0) -> 1 | L222: =IF(K222>1,"NO LOGUEO","LOGUEO") -> LOGUEO
A223: LIPU GDL | B223: ESPARZA OCHOA ARMANDO | C223: 4.4799 | D223: 5.75 | E223: 4.46 | F223: 0 | G223: 3.45 | H223: 6.05 | I223: 3.47 | J223: 14121543 | K223: =COUNTIF(C223:I223,0) -> 1 | L223: =IF(K223>1,"NO LOGUEO","LOGUEO") -> LOGUEO
A224: LIPU GDL | B224: GARCIA GARCIA RUBEN | C224: 0 | D224: 2.96 | E224: 3.17 | F224: 3.13 | G224: 3.02 | H224: 3.24 | I224: 3.1 | J224: 14114709 | K224: =COUNTIF(C224:I224,0) -> 1 | L224: =IF(K224>1,"NO LOGUEO","LOGUEO") -> LOGUEO
A225: LIPU GDL | B225: CHAVEZ RUIZ ARMANDO | C225: 0 | D225: 4.24 | E225: 6.29 | F225: 6.1999 | G225: 6.2699 | H225: 7.41 | I225: 5.71 | J225: 14121784 | K225: =COUNTIF(C225:I225,0) -> 1 | L225: =IF(K225>1,"NO LOGUEO","LOGUEO") -> LOGUEO
A226: LIPU GDL | B226: DE LA ROSA PORTUGAL ALBERTO | C226: 4.82 | D226: 4.4 | E226: 0 | F226: 5.38 | G226: 6.91 | H226: 6.1 | I226: 5.29 | J226: 14121672 | K226: =COUNTIF(C226:I226,0) -> 1 | L226: =IF(K226>1,"NO LOGUEO","LOGUEO") -> LOGUEO
A227: LIPU GDL | B227: GONZALEZ GERARDO URIEL | C227: 5.0599 | D227: 6.42 | E227: 6.93 | F227: 3.65 | G227: 0 | H227: 5.4 | I227: 7.05 | J227: 14121398 | K227: =COUNTIF(C227:I227,0) -> 1 | L227: =IF(K227>1,"NO LOGUEO","LOGUEO") -> LOGUEO
A228: LIPU GDL | B228: GUILLEN VEGA GUILLERMO | C228: 0 | D228: 12.46 | E228: 4.63 | F228: 4.9499 | G228: 8.28 | H228: 3.75 | I228: 8.9899 | J228: 14121545 | K228: =COUNTIF(C228:I228,0) -> 1 | L228: =IF(K228>1,"NO LOGUEO","LOGUEO") -> LOGUEO
A229: LIPU GDL | B229: LOPEZ RAYMUNDO ROBERTO | C229: 0 | D229: 9.7399 | E229: 4.51 | F229: 5.22 | G229: 1.2 | H229: 5.95 | I229: 7.99 | J229: 14100843 | K229: =COUNTIF(C229:I229,0) -> 1 | L229: =IF(K229>1,"NO LOGUEO","LOGUEO") -> LOGUEO
A230: LIPU GDL | B230: DIAZ BLANQUET ROSA JANNET | C230: 0 | D230: 4.18 | E230: 1.3699 | F230: 1.0299 | G230: 4.85 | H230: 8.02 | I230: 6.57 | J230: 14110604 | K230: =COUNTIF(C230:I230,0) -> 1 | L230: =IF(K230>1,"NO LOGUEO","LOGUEO") -> LOGUEO
A231: LIPU GDL | B231: AVILES BRITO JORGE | C231: 8.76 | D231: 0 | E231: 9.87 | F231: 9.4599 | G231: 8.7299 | H231: 2.65 | I231: 2.37 | J231: 14123985 | K231: =COUNTIF(C231:I231,0) -> 1 | L231: =IF(K231>1,"NO LOGUEO","LOGUEO") -> LOGUEO
A232: LIPU GDL | B232: CRUZ GUTIERREZ ALFREDO | C232: 0 | D232: 4.32 | E232: 6.98 | F232: 6.84 | G232: 6.93 | H232: 6.84 | I232: 6.42 | J232: 14100897 | K232: =COUNTIF(C232:I232,0) -> 1 | L232: =IF(K232>1,"NO LOGUEO","LOGUEO") -> LOGUEO
A233: LIPU GDL | B233: CASTILLO FUENTES MIGUEL | C233: 0 | D233: 7.46 | E233: 7.07 | F233: 5.6199 | G233: 8.8799 | H233: 6.91 | I233: 6.61 | J233: 14112730 | K233: =COUNTIF(C233:I233,0) -> 1 | L233: =IF(K233>1,"NO LOGUEO","LOGUEO") -> LOGUEO
A234: LIPU GDL | B234: RODRIGUEZ LOPEZ ANGEL ALBERTO | C234: 3.09 | D234: 6.66 | E234: 9.65 | F234: 3.55 | G234: 0 | H234: 7.34 | I234: 7.18 | J234: 14120925 | K234: =COUNTIF(C234:I234,0) -> 1 | L234: =IF(K234>1,"NO LOGUEO","LOGUEO") -> LOGUEO
... A434: LIPU GDL | B434: RAMIREZ MEDINA JULIAN | C434: 2.7599 | D434: 9.44 | E434: 9.07 | F434: 8.9699 | G434: 6.42 | H434: 7.4999 | I434: 0 | J434: 14119825 | K434: =COUNTIF(C434:I434,0) -> 1 | L434: =IF(K434>1,"NO LOGUEO","LOGUEO") -> LOGUEO
A435: LIPU GDL | B435: P.ALVAREZ REYES JAIRO DE JESUS | C435: 0 | D435: 1.33 | E435: 2.02 | F435: 0.4 | G435: 0.95 | H435: 2.0299 | I435: 1.71 | K435: =COUNTIF(C435:I435,0) -> 1 | L435: =IF(K435>1,"NO LOGUEO","LOGUEO") -> LOGUEO
A436: LIPU GDL | B436: RUIZ PALAFOX FRANCISCO JAVIER | C436: 11.27 | D436: 0 | E436: 4.2 | F436: 9.24 | G436: 3.68 | H436: 7.99 | I436: 4.91 | J436: 14123846 | K436: =COUNTIF(C436:I436,0) -> 1 | L436: =IF(K436>1,"NO LOGUEO","LOGUEO") -> LOGUEO
A437: LIPU GDL | B437: MARTINEZ PATRICIO ANGEL ULISES | C437: 6.89 | D437: 10.49 | E437: 8.1599 | F437: 0 | G437: 7.01 | H437: 6.87 | I437: 9.4199 | J437: 14119958 | K437: =COUNTIF(C437:I437,0) -> 1 | L437: =IF(K437>1,"NO LOGUEO","LOGUEO") -> LOGUEO
A438: LIPU GDL | B438: ROSAS MARTINEZ VICTOR FELIPE | C438: 2.62 | D438: 7.9199 | E438: 11.33 | F438: 9.37 | G438: 9.31 | H438: 4.04 | I438: 0 | J438: 14113140 | K438: =COUNTIF(C438:I438,0) -> 1 | L438: =IF(K438>1,"NO LOGUEO","LOGUEO") -> LOGUEO
A439: LIPU GDL | B439: GAYTAN PINEDO CARLOS ENRIQUE | C439: 0 | D439: 6.67 | E439: 9.13 | F439: 8.77 | G439: 8.0599 | H439: 6.89 | I439: 6.6 | J439: 14106438 | K439: =COUNTIF(C439:I439,0) -> 1 | L439: =IF(K439>1,"NO LOGUEO","LOGUEO") -> LOGUEO
A440: LIPU GDL | B440: RAMIREZ RUIZ RAUL | C440: 0 | D440: 12.26 | E440: 9.46 | F440: 11.2 | G440: 10.42 | H440: 11.03 | I440: 11.58 | J440: 14107081 | K440: =COUNTIF(C440:I440,0) -> 1 | L440: =IF(K440>1,"NO LOGUEO","LOGUEO") -> LOGUEO
A441: LIPU GDL | B441: ARIAS PATINO JOSE MANUEL | C441: 6.32 | D441: 6.81 | E441: 6.3199 | F441: 4.16 | G441: 0 | H441: 5.73 | I441: 9.36 | J441: 14122617 | K441: =COUNTIF(C441:I441,0) -> 1 | L441: =IF(K441>1,"NO LOGUEO","LOGUEO") -> LOGUEO
A442: LIPU GDL | B442: DEL TORO MARTINEZ HECTOR JOSE | C442: 10.45 | D442: 11.8 | E442: 11.9 | F442: 8.93 | G442: 0 | H442: 6.83 | I442: 13.48 | J442: 14103470 | K442: =COUNTIF(C442:I442,0) -> 1 | L442: =IF(K442>1,"NO LOGUEO","LOGUEO") -> LOGUEO
A443: LIPU GDL | B443: PLASCENCIA ESQUIVEL FRANCISCO | C443: 0 | D443: 8.75 | E443: 4.05 | F443: 8.92 | G443: 9.1 | H443: 8.7899 | I443: 8.61 | J443: 14106066 | K443: =COUNTIF(C443:I443,0) -> 1 | L443: =IF(K443>1,"NO LOGUEO","LOGUEO") -> LOGUEO
A444: LIPU GDL | B444: ROBLES DEADEL LAZARO | C444: 4.98 | D444: 2.84 | E444: 0 | F444: 5.05 | G444: 3.42 | H444: 6.66 | I444: 2.48 | J444: 14100732 | K444: =COUNTIF(C444:I444,0) -> 1 | L444: =IF(K444>1,"NO LOGUEO","LOGUEO") -> LOGUEO
A445: LIPU GDL | B445: LOERA GOMEZ FRANCISCO | C445: 0 | D445: 8.1499 | E445: 8.71 | F445: 8.01 | G445: 8.49 | H445: 7.6199 | I445: 7.78 | J445: 14111557 | K445: =COUNTIF(C445:I445,0) -> 1 | L445: =IF(K445>1,"NO LOGUEO","LOGUEO") -> LOGUEO
A446: LIPU GDL | B446: RAMOS ANGUIANO SERGIO DAVID | C446: 7.9 | D446: 8.12 | E446: 7.88 | F446: 7.7499 | G446: 7.47 | H446: 0 | I446: 8.1 | J446: 14102288 | K446: =COUNTIF(C446:I446,0) -> 1 | L446: =IF(K446>1,"NO LOGUEO","LOGUEO") -> LOGUEO
...

Sheet ACUMULADO
A1: agrupador | B1: concepto | C1: clave | D1: nombre_completo | E1: periodo | F1: importe
A2: PRESTACIONES | B2: AYUDA ESCOLAR | C2: 14111261 | D2: CASTILLO GRADILLA OSCAR EMILIO | E2: S34 | F2: 2350
A3: PRESTACIONES | B3: AYUDA ESCOLAR | C3: 14111336 | D3: MARTINEZ RODRIGUEZ ELIAS | E3: S34 | F3: 2350
A4: PRESTACIONES | B4: AYUDA ESCOLAR | C4: 14223379 | D4: CAMACHO MARTINEZ OSCAR RAMON | E4: S34 | F4: 2350
A5: PRESTACIONES | B5: AYUDA ESCOLAR | C5: 14223826 | D5: HONORATO PLASCENCIA EDGAR ANTONIO | E5: S34 | F5: 2350
A6: PRESTACIONES | B6: AYUDA ESCOLAR | C6: 14100716 | D6: AMBRIZ MERCADO MARTIN | E6: S34 | F6: 2350
A7: PRESTACIONES | B7: AYUDA ESCOLAR | C7: 14100726 | D7: GUZMAN MUNGUIA LUIS JAVIER | E7: S34 | F7: 2350
A8: PRESTACIONES | B8: AYUDA ESCOLAR | C8: 14100731 | D8: TABARES FLORES OSCAR ALEJANDRO | E8: S34 | F8: 2350
A9: PRESTACIONES | B9: AYUDA ESCOLAR | C9: 14100740 | D9: OLIVARES HERNANDEZ GABRIEL | E9: S34 | F9: 2350
A10: PRESTACIONES | B10: AYUDA ESCOLAR | C10: 14102081 | D10: OLEA SANCHEZ JOSE LUIS | E10: S34 | F10: 2350
A11: PRESTACIONES | B11: AYUDA ESCOLAR | C11: 14103936 | D11: GUTIERREZ GALINDO CARLOS DE JESUS | E11: S34 | F11: 2350
A12: PRESTACIONES | B12: AYUDA ESCOLAR | C12: 14104315 | D12: SERRANO MACHUCA MARTIN DE JESUS | E12: S34 | F12: 2350
A13: PRESTACIONES | B13: AYUDA ESCOLAR | C13: 14104316 | D13: COBIAN AYALA EDGAR | E13: S34 | F13: 2350
... A3795: PRESTACIONES | B3795: VIAJES ADICIONALES | C3795: 16122298 | D3795: VALENCIA HERNANDEZ ARMANDO | E3795: S34 | F3795: 525

Sheet NOMINA
A4: clave. | B4: nombre completo. | C4: afiliacion al i.m.s.s.
A5: 14100713 | B5: OLVERA BARAJAS ISMAEL | C5: 04887081141
A6: 14100714 | B6: RAMIREZ RODRIGUEZ JESUS | C6: 04826628101
A7: 14100716 | B7: AMBRIZ MERCADO MARTIN | C7: 04876544273
A8: 14100718 | B8: MARTINEZ OCHOA PAULO | C8: 75947416485
A9: 14100721 | B9: GUTIERREZ VELEZ FRANCISCO | C9: 54856770802
A10: 14100724 | B10: ORTIZ GARCIA LUIS ALBERTO | C10: 04038364792
A11: 14100725 | B11: NAJAR LOPEZ JOSE SERGIO | C11: 21856620527
A12: 14100726 | B12: GUZMAN MUNGUIA LUIS JAVIER | C12: 04917302921
A13: 14100727 | B13: ALONZO PEREZ JOSE REYES | C13: 04856736626
A14: 14100729 | B14: LARIOS ALCARAZ EDUARDO | C14: 54816597899
A15: 14100731 | B15: TABARES FLORES OSCAR ALEJANDRO | C15: 56937408260
A16: 14100732 | B16: ROBLES DEADEL LAZARO | C16: 04015903042
... A619: 14123629 | B619: GONZALEZ ROMERO NESTOR IVAN | C619: 49159446050

Sheet RENDIMIENTO
A2: CLAVE | B2: NOMBRE | C2: F.INGRESO | D2: UNIDAD | E2: META | F2: REDIMIENTO OBTENIDO | G2: TOTAL A PAGAR | H2: SEMANA DE RETROACTIVO
A3: 14100714 | B3: RAMIREZ RODRIGUEZ JESUS | C3: 2019-01-11 | D3: LIPU | E3: 3.5126734 | F3: 3.5967005 | G3: 355.58
A4: 14100718 | B4: MARTINEZ OCHOA PAULO | C4: 2017-05-01 | D4: LIPU | E4: 11.418646 | F4: 11.379 | G4: 0
A5: 14100721 | B5: GUTIERREZ VELEZ FRANCISCO | C5: 2021-07-08 | D5: LIPU | E5: 4.3532522 | F5: 3.9910251 | G5: 0
A6: 14100724 | B6: ORTIZ GARCIA LUIS ALBERTO | C6: 2017-05-01 | D6: LIPU | E6: 4.5080442 | F6: 5.3252909 | G6: 355.58
A7: 14100725 | B7: NAJAR LOPEZ JOSE SERGIO | C7: 2017-05-01 | D7: LIPU | E7: 4.436782 | F7: 4.749576 | G7: 355.58
A8: 14100726 | B8: GUZMAN MUNGUIA LUIS JAVIER | C8: 2017-05-01 | D8: LIPU | E8: 3.96182 | F8: 4.7084276 | G8: 355.58
A9: 14100727 | B9: ALONZO PEREZ JOSE REYES | C9: 2017-05-01 | D9: LIPU | E9: 4.9834409 | F9: 6.7414353 | G9: 355.58
A10: 14100729 | B10: LARIOS ALCARAZ EDUARDO | C10: 2017-05-01 | D10: LIPU | E10: Descansero | F10: Descansero | G10: 355.58
A11: 14100731 | B11: TABARES FLORES OSCAR ALEJANDRO | C11: 2022-09-02 | D11: LIPU | E11: 4.4326521 | F11: 4.9581321 | G11: 355.58
A12: 14100732 | B12: ROBLES DEADEL LAZARO | C12: 2017-05-01 | D12: LIPU | E12: 3.7835575 | F12: 5.1784205 | G12: 355.58
A13: 14100733 | B13: LINARES CISNEROS JOSE ANTONIO | C13: 2017-05-01 | D13: LIPU | E13: Descansero | F13: Descansero | G13: 355.58
A14: 14100740 | B14: OLIVARES HERNANDEZ GABRIEL | C14: 2021-11-17 | D14: LIPU | E14: 4.4923786 | F14: 5.4948638 | G14: 355.58
A15: 14100751 | B15: FLORES GARCIA PEDRO | C15: 2025-10-10 | D15: LIPU | E15: 3.96 | F15: 4.07 | G15: 355.58
A16: 14100777 | B16: GONZALEZ MANZO JAVIER OSWALDO | C16: 2017-05-01 | D16: LIPU | E16: Descansero | F16: Descansero | G16: 355.58
A17: 14100787 | B17: YEPEZ VAZQUEZ JOAN | C17: 2017-05-01 | D17: LIPU | E17: 3.7922536 | F17: 5.1406174 | G17: 355.58
A18: 14100795 | B18: BALTAZAR MENDOZA HORACIO | C18: 2017-05-01 | D18: LIPU | E18: 4.662251 | F18: 4.018721 | G18: 0
A19: 14100798 | B19: CARRILLO REYNOSO JESUS ALEJANDRO | C19: 2017-05-01 | D19: LIPU | E19: 4.0644462 | F19: 5.0306612 | G19: 355.58
A20: 14100807 | B20: OSORIO HERNANDEZ DOMINGO | C20: 2023-05-12 | D20: LIPU | E20: 4.7317431 | F20: 6.2797497 | G20: 355.58
A21: 14100823 | B21: FLORES ENRIQUEZ JUAN PABLO | C21: 2024-08-05 | D21: LIPU | E21: Descansero | F21: Descansero | G21: 355.58
A22: 14100842 | B22: BECERRA LUNA GUILLERMO | C22: 2017-05-01 | D22: LIPU | E22: Descansero | F22: Descansero | G22: 355.58
A23: 14100843 | B23: LOPEZ RAYMUNDO ROBERTO | C23: 2025-03-07 | D23: LIPU | E23: 3.5970917 | F23: 4.1459307 | G23: 355.58
A24: 14100858 | B24: REYNAGA SANCHEZ MARIO | C24: 2025-06-06 | D24: LIPU | E24: 3.7292467 | F24: 4.774209 | G24: 355.58
A25: 14100863 | B25: MARTINEZ ZAVALA FRANCISCO ESPIRIDION | C25: 2017-05-01 | D25: LIPU | E25: 4.23 | F25: 4.24 | G25: 355.58
A26: 14100897 | B26: CRUZ GUTIERREZ ALFREDO | C26: 2025-05-09 | D26: LIPU | E26: 4.0121683 | F26: 3.6816731 | G26: 0
A27: 14100902 | B27: SANCHEZ PONCE JOSE ALBERTO | C27: 2025-12-31 | D27: LIPU | E27: 4.0414963 | F27: 5.200803 | G27: 355.58
A28: 14101881 | B28: MORALES AGUILAR ALBERTO | C28: 2017-05-24 | D28: LIPU | E28: 3.9 | F28: 4.898404 | G28: 355.58
A29: 14101984 | B29: TABARES VAZQUEZ MARTIN | C29: 2018-11-29 | D29: LIPU | E29: 4.1883124 | F29: 5.032933 | G29: 355.58
A30: 14102081 | B30: OLEA SANCHEZ JOSE LUIS | C30: 2017-07-07 | D30: LIPU | E30: 7.0119567 | F30: 7.0810594 | G30: 355.58
A31: 14102288 | B31: RAMOS ANGUIANO SERGIO DAVID | C31: 2017-08-15 | D31: LIPU | E31: Descansero | F31: Descansero | G31: 355.58
A32: 14102701 | B32: ORTIZ HERNANDEZ JESUS GUADALUPE | C32: 2017-11-06 | D32: LIPU | E32: Descansero | F32: Descansero | G32: 355.58
A33: 14102730 | B33: ESTRADA ALVAREZ FERNANDO | C33: 2017-11-13 | D33: LIPU | E33: 3.98 | F33: 4.18 | G33: 355.58
A34: 14102875 | B34: LARIOS SANCHEZ HECTOR ALEXANDER | C34: 2017-12-20 | D34: LIPU | E34: 2.8043955 | F34: 3.9897073 | G34: 355.58
A35: 14102890 | B35: GONZALEZ VALENCIA BARTOLO | C35: 2017-12-21 | D35: LIPU | E35: 4.5700688 | F35: 5.5428299 | G35: 355.58
A36: 14103061 | B36: SANCHEZ PEREZ CARLOS FORTINO | C36: 2023-06-01 | D36: LIPU | E36: 3.6322725 | F36: 4.3610519 | G36: 355.58
A37: 14103106 | B37: CORTES ARMENTA HERNAN | C37: 2018-02-02 | D37: LIPU | E37: 4.0644255 | F37: 5.164819 | G37: 355.58
A38: 14103183 | B38: HERNANDEZ RON BLANCA HERLINDA | C38: 2018-02-27 | D38: LIPU | E38: 3.7173108 | F38: 4.233 | G38: 355.58
A39: 14103335 | B39: RIVERA MARTINEZ GUSTAVO | C39: 2018-04-09 | D39: LIPU | E39: 3.6673041 | F39: 4.3362235 | G39: 355.58
A40: 14103470 | B40: DEL TORO MARTINEZ HECTOR JOSE | C40: 2026-06-13 | D40: LIPU | E40: 4.4612301 | F40: 4.8965182 | G40: 355.58
A41: 14103679 | B41: BAUTISTA SOLORIO JAIME | C41: 2018-06-29 | D41: LIPU | E41: 10.744593 | F41: 13.602047 | G41: 355.58
...

Sheet BONOS
F1: 2002 AL 2015 4.30 | K1: SINIESTROS | L1: QUEJAS | M1: PUNTUALIDAD | N1: SCORE | O1: LOGUEO
A2: SEMANA 34 | F2: camion | K2: 134.18 | L2: 134.18 | N2: 200 | O2: 177.44
K4: 69371.06 | L4: 68834.34 | M4: 0 | N4: 49400 | O4: 48796 | P4: 0 | Q4: 0 | R4: 0 | S4: 236401.4
E5: CON/SIN | F5: CON/SIN | G5: TOTAL | H5: OK/NO | I5: OK/NO | J5: LOGUEO/NO LOGUEO | K5: TOTAL FORMULADO OBTENIDO | S5: TOTAL FORMULADO
A6: CLAVE | B6: NOMBRE | C6: F.INGRESO | D6: UNIDAD | E6: SINIESTROS | F6: QUEJAS | G6: SCORE OBTENIDO | H6: BONO SCORE | I6: PUNTUALIDAD | J6: BONO LOGUEO | K6: BONO SINIESTROS | L6: BONO QUEJAS | M6: BONO PUNTUALIDAD | N6: BONO SCORE1 | O6: BONO LOGUEO1 | P6: TOTAL BONO | Q6: DETALLE(FECHA DE SINIESTRO) | R6: OBSERVACIONES | S6: TOTAL B.DESEMPEÑO | U6: CONFIRMACIÓN DE VIAJE | V6: GUARDIA
A7: 14100714 | B7: RAMIREZ RODRIGUEZ JESUS | C7: 2019-01-11 | D7: LIPU | E7: SIN SINIESTRO | F7: SIN QUEJA | G7: 95 | H7: OK | I7: OK | J7: LOGUEO | K7: 134.18 | L7: 134.18 | N7: 200 | O7: 177.44 | S7: 645.8 | U7: BONO | V7: NO
A8: 14100718 | B8: MARTINEZ OCHOA PAULO | C8: 2017-05-01 | D8: LIPU | E8: SIN SINIESTRO | F8: SIN QUEJA | G8: 92 | H8: OK | I8: OK | J8: LOGUEO | K8: 134.18 | L8: 134.18 | N8: 200 | O8: 177.44 | S8: 645.8 | U8: BONO | V8: NO
A9: 14100721 | B9: GUTIERREZ VELEZ FRANCISCO | C9: 2021-07-08 | D9: LIPU | E9: SIN SINIESTRO | F9: SIN QUEJA | G9: 84 | H9: NO | I9: OK | J9: LOGUEO | K9: 134.18 | L9: 134.18 | N9: 0 | O9: 177.44 | S9: 445.8 | U9: BONO | V9: NO
A10: 14100724 | B10: ORTIZ GARCIA LUIS ALBERTO | C10: 2017-05-01 | D10: LIPU | E10: SIN SINIESTRO | F10: SIN QUEJA | G10: 95 | H10: OK | I10: NO | J10: LOGUEO | K10: 134.18 | L10: 134.18 | N10: 0 | O10: 0 | S10: 268.36 | U10: BONO | V10: NO
A11: 14100725 | B11: NAJAR LOPEZ JOSE SERGIO | C11: 2017-05-01 | D11: LIPU | E11: SIN SINIESTRO | F11: SIN QUEJA | G11: 93 | H11: OK | I11: OK | J11: NO LOGUEO | K11: 134.18 | L11: 134.18 | N11: 200 | O11: 0 | S11: 468.36 | U11: BONO | V11: NO
A12: 14100726 | B12: GUZMAN MUNGUIA LUIS JAVIER | C12: 2017-05-01 | D12: LIPU | E12: SIN SINIESTRO | F12: SIN QUEJA | G12: 95 | H12: OK | I12: OK | J12: LOGUEO | K12: 134.18 | L12: 134.18 | N12: 200 | O12: 177.44 | S12: 645.8 | U12: BONO | V12: NO
A13: 14100727 | B13: ALONZO PEREZ JOSE REYES | C13: 2017-05-01 | D13: LIPU | E13: SIN SINIESTRO | F13: SIN QUEJA | G13: 92 | H13: OK | I13: NO | J13: LOGUEO | K13: 134.18 | L13: 134.18 | N13: 0 | O13: 0 | S13: 268.36 | U13: BONO | V13: NO
A14: 14100729 | B14: LARIOS ALCARAZ EDUARDO | C14: 2017-05-01 | D14: LIPU | E14: SIN SINIESTRO | F14: SIN QUEJA | G14: 90 | H14: OK | I14: NO | J14: LOGUEO | K14: 134.18 | L14: 134.18 | N14: 0 | O14: 0 | S14: 268.36 | U14: BONO | V14: NO
A15: 14100731 | B15: TABARES FLORES OSCAR ALEJANDRO | C15: 2022-09-02 | D15: LIPU | E15: SIN SINIESTRO | F15: SIN QUEJA | G15: 92 | H15: OK | I15: NO | J15: LOGUEO | K15: 134.18 | L15: 134.18 | N15: 0 | O15: 0 | S15: 268.36 | U15: BONO | V15: NO
A16: 14100732 | B16: ROBLES DEADEL LAZARO | C16: 2017-05-01 | D16: LIPU | E16: SIN SINIESTRO | F16: SIN QUEJA | G16: 90 | H16: OK | I16: OK | J16: LOGUEO | K16: 134.18 | L16: 134.18 | N16: 200 | O16: 177.44 | S16: 645.8 | U16: BONO | V16: NO
A17: 14100733 | B17: LINARES CISNEROS JOSE ANTONIO | C17: 2017-05-01 | D17: LIPU | E17: SIN SINIESTRO | F17: SIN QUEJA | G17: 95 | H17: OK | I17: NO | J17: LOGUEO | K17: 134.18 | L17: 134.18 | N17: 0 | O17: 0 | S17: 268.36 | U17: BONO | V17: NO
A18: 14100740 | B18: OLIVARES HERNANDEZ GABRIEL | C18: 2021-11-17 | D18: LIPU | E18: SIN SINIESTRO | F18: SIN QUEJA | G18: 93 | H18: OK | I18: NO | J18: LOGUEO | K18: 134.18 | L18: 134.18 | N18: 0 | O18: 0 | S18: 268.36 | U18: BONO | V18: NO
A19: 14100751 | B19: FLORES GARCIA PEDRO | C19: 2025-10-10 | D19: LIPU | E19: SIN SINIESTRO | F19: SIN QUEJA | G19: 92 | H19: OK | I19: NO | J19: LOGUEO | K19: 134.18 | L19: 134.18 | N19: 0 | O19: 0 | S19: 268.36 | U19: BONO | V19: NO
A20: 14100777 | B20: GONZALEZ MANZO JAVIER OSWALDO | C20: 2017-05-01 | D20: LIPU | E20: SIN SINIESTRO | F20: SIN QUEJA | H20: NO | I20: OK | J20: NO LOGUEO | K20: 0 | L20: 0 | N20: 0 | O20: 0 | S20: 0 | U20: NO | V20: NO
A21: 14100787 | B21: YEPEZ VAZQUEZ JOAN | C21: 2017-05-01 | D21: LIPU | E21: SIN SINIESTRO | F21: SIN QUEJA | G21: 93 | H21: OK | I21: NO | J21: LOGUEO | K21: 134.18 | L21: 134.18 | N21: 0 | O21: 0 | S21: 268.36 | U21: BONO | V21: NO
A22: 14100795 | B22: BALTAZAR MENDOZA HORACIO | C22: 2017-05-01 | D22: LIPU | E22: SIN SINIESTRO | F22: SIN QUEJA | G22: 95 | H22: OK | I22: OK | J22: LOGUEO | K22: 134.18 | L22: 134.18 | N22: 200 | O22: 177.44 | S22: 645.8 | U22: BONO | V22: NO
A23: 14100798 | B23: CARRILLO REYNOSO JESUS ALEJANDRO | C23: 2017-05-01 | D23: LIPU | E23: SIN SINIESTRO | F23: SIN QUEJA | G23: 95 | H23: OK | I23: NO | J23: LOGUEO | K23: 134.18 | L23: 134.18 | N23: 0 | O23: 0 | S23: 268.36 | U23: BONO | V23: NO
A24: 14100807 | B24: OSORIO HERNANDEZ DOMINGO | C24: 2023-05-12 | D24: LIPU | E24: SIN SINIESTRO | F24: SIN QUEJA | G24: 93 | H24: OK | I24: OK | J24: LOGUEO | K24: 134.18 | L24: 134.18 | N24: 200 | O24: 177.44 | S24: 645.8 | U24: BONO | V24: NO
A25: 14100823 | B25: FLORES ENRIQUEZ JUAN PABLO | C25: 2024-08-05 | D25: LIPU | E25: SIN SINIESTRO | F25: SIN QUEJA | G25: 94 | H25: OK | I25: OK | J25: LOGUEO | K25: 134.18 | L25: 134.18 | N25: 200 | O25: 177.44 | S25: 645.8 | U25: BONO | V25: GUARDIA
A26: 14100842 | B26: BECERRA LUNA GUILLERMO | C26: 2017-05-01 | D26: LIPU | E26: SIN SINIESTRO | F26: SIN QUEJA | H26: NO | I26: OK | J26: NO LOGUEO | K26: 0 | L26: 0 | N26: 0 | O26: 0 | S26: 0 | U26: NO | V26: NO
A27: 14100843 | B27: LOPEZ RAYMUNDO ROBERTO | C27: 2025-03-07 | D27: LIPU | E27: SIN SINIESTRO | F27: SIN QUEJA | G27: 91 | H27: OK | I27: OK | J27: LOGUEO | K27: 134.18 | L27: 134.18 | N27: 200 | O27: 177.44 | S27: 645.8 | U27: BONO | V27: GUARDIA
A28: 14100858 | B28: REYNAGA SANCHEZ MARIO | C28: 2025-06-06 | D28: LIPU | E28: SIN SINIESTRO | F28: SIN QUEJA | G28: 92 | H28: OK | I28: OK | J28: LOGUEO | K28: 134.18 | L28: 134.18 | N28: 200 | O28: 177.44 | S28: 645.8 | U28: BONO | V28: NO
A29: 14100863 | B29: MARTINEZ ZAVALA FRANCISCO ESPIRIDION | C29: 2017-05-01 | D29: LIPU | E29: SIN SINIESTRO | F29: SIN QUEJA | G29: 94 | H29: OK | I29: OK | J29: LOGUEO | K29: 134.18 | L29: 134.18 | N29: 200 | O29: 177.44 | S29: 645.8 | U29: BONO | V29: NO
A30: 14100897 | B30: CRUZ GUTIERREZ ALFREDO | C30: 2025-05-09 | D30: LIPU | E30: SIN SINIESTRO | F30: SIN QUEJA | G30: 94 | H30: OK | I30: OK | J30: LOGUEO | K30: 134.18 | L30: 134.18 | N30: 200 | O30: 177.44 | S30: 645.8 | U30: BONO | V30: NO
A31: 14100902 | B31: SANCHEZ PONCE JOSE ALBERTO | C31: 2025-12-31 | D31: LIPU | E31: SIN SINIESTRO | F31: SIN QUEJA | G31: 74 | H31: NO | I31: NO | J31: LOGUEO | K31: 134.18 | L31: 134.18 | N31: 0 | O31: 0 | S31: 268.36 | U31: BONO | V31: NO
A32: 14101881 | B32: MORALES AGUILAR ALBERTO | C32: 2017-05-24 | D32: LIPU | E32: SIN SINIESTRO | F32: SIN QUEJA | G32: 93 | H32: OK | I32: OK | J32: LOGUEO | K32: 134.18 | L32: 134.18 | N32: 200 | O32: 177.44 | S32: 645.8 | U32: BONO | V32: NO
A33: 14101984 | B33: TABARES VAZQUEZ MARTIN | C33: 2018-11-29 | D33: LIPU | E33: SIN SINIESTRO | F33: SIN QUEJA | G33: 80 | H33: NO | I33: OK | J33: LOGUEO | K33: 134.18 | L33: 134.18 | N33: 0 | O33: 177.44 | S33: 445.8 | U33: BONO | V33: NO
A34: 14102081 | B34: OLEA SANCHEZ JOSE LUIS | C34: 2017-07-07 | D34: LIPU | E34: SIN SINIESTRO | F34: SIN QUEJA | G34: 92 | H34: OK | I34: OK | J34: LOGUEO | K34: 134.18 | L34: 134.18 | N34: 200 | O34: 177.44 | S34: 645.8 | U34: BONO | V34: GUARDIA
A35: 14102288 | B35: RAMOS ANGUIANO SERGIO DAVID | C35: 2017-08-15 | D35: LIPU | E35: SIN SINIESTRO | F35: SIN QUEJA | G35: 93 | H35: OK | I35: NO | J35: LOGUEO | K35: 134.18 | L35: 134.18 | N35: 0 | O35: 0 | S35: 268.36 | U35: BONO | V35: NO
A36: 14102701 | B36: ORTIZ HERNANDEZ JESUS GUADALUPE | C36: 2017-11-06 | D36: LIPU | E36: SIN SINIESTRO | F36: SIN QUEJA | G36: 89 | H36: NO | I36: OK | J36: LOGUEO | K36: 134.18 | L36: 134.18 | N36: 0 | O36: 177.44 | S36: 445.8 | U36: BONO | V36: NO
A37: 14102730 | B37: ESTRADA ALVAREZ FERNANDO | C37: 2017-11-13 | D37: LIPU | E37: SIN SINIESTRO | F37: SIN QUEJA | G37: 95 | H37: OK | I37: OK | J37: LOGUEO | K37: 134.18 | L37: 134.18 | N37: 200 | O37: 177.44 | S37: 645.8 | U37: BONO | V37: NO
A38: 14102875 | B38: LARIOS SANCHEZ HECTOR ALEXANDER | C38: 2017-12-20 | D38: LIPU | E38: SIN SINIESTRO | F38: SIN QUEJA | G38: 94 | H38: OK | I38: NO | J38: LOGUEO | K38: 134.18 | L38: 134.18 | N38: 0 | O38: 0 | S38: 268.36 | U38: BONO | V38: GUARDIA
A39: 14102890 | B39: GONZALEZ VALENCIA BARTOLO | C39: 2017-12-21 | D39: LIPU | E39: SIN SINIESTRO | F39: SIN QUEJA | H39: NO | I39: OK | J39: NO LOGUEO | K39: 0 | L39: 0 | N39: 0 | O39: 0 | S39: 0 | U39: NO | V39: NO
A40: 14103061 | B40: SANCHEZ PEREZ CARLOS FORTINO | C40: 2023-06-01 | D40: LIPU | E40: SIN SINIESTRO | F40: SIN QUEJA | G40: 95 | H40: OK | I40: OK | J40: LOGUEO | K40: 134.18 | L40: 134.18 | N40: 200 | O40: 177.44 | S40: 645.8 | U40: BONO | V40: NO
A41: 14103106 | B41: CORTES ARMENTA HERNAN | C41: 2018-02-02 | D41: LIPU | E41: SIN SINIESTRO | F41: SIN QUEJA | G41: 94 | H41: OK | I41: NO | J41: LOGUEO | K41: 134.18 | L41: 134.18 | N41: 0 | O41: 0 | S41: 268.36 | U41: BONO | V41: NO
...

Sheet CONSULTA
B1: NÓMINA
B2: 14100714
B3: NOMBRE | C3: =IFERROR(VLOOKUP(CONSULTA!$B$2,BONOS!$A$6:$BM$650,$H3,FALSE),"") -> RAMIREZ RODRIGUEZ JESUS | H3: =IFERROR(MATCH("NOMBRE ",BONOS!$A$6:$BM$6,0),"") -> 2
B4: SINIESTROS | C4: =IFERROR(VLOOKUP(CONSULTA!$B$2,BONOS!$A$6:$BM$650,$D4,FALSE),"") -> SIN SINIESTRO | D4: =IFERROR(MATCH("SINIESTROS",BONOS!$A$6:$BM$6,0),"") -> 5 | E4: BONO DE SCORE | G4: =IFERROR(VLOOKUP(CONSULTA!$B$2,BONOS!$A$6:$BM$650,$H4,FALSE),"") -> OK | H4: =IFERROR(MATCH("BONO SCORE",BONOS!$A$6:$BM$6,0),"") -> 8
B5: QUEJAS | C5: =IFERROR(VLOOKUP(CONSULTA!$B$2,BONOS!$A$6:$BM$650,$D5,FALSE),"") -> SIN QUEJA | D5: =IFERROR(MATCH("QUEJAS",BONOS!$A$6:$BM$6,0),"") -> 6 | E5: PUNTUALIDAD | G5: =IFERROR(VLOOKUP(CONSULTA!$B$2,BONOS!$A$6:$BM$650,$H5,FALSE),"") -> OK | H5: =IFERROR(MATCH("PUNTUALIDAD",BONOS!$A$6:$BM$6,0),"") -> 9
B6: SCORE OBTENIDO | C6: =IFERROR(VLOOKUP(CONSULTA!$B$2,BONOS!$A$6:$BM$650,$D6,FALSE),"") -> 95 | D6: =IFERROR(MATCH("SCORE OBTENIDO",BONOS!$A$6:$BM$6,0),"") -> 7 | E6: BONO LOGUEO | G6: =IFERROR(VLOOKUP(CONSULTA!$B$2,BONOS!$A$6:$BM$650,$H6,FALSE),"") -> LOGUEO | H6: =IFERROR(MATCH("BONO LOGUEO",BONOS!$A$6:$BM$6,0),"") -> 10
B8: RENDIMEINTO META | C8: =IFERROR(VLOOKUP(CONSULTA!$B$2,RENDIMIENTO!$A$2:$BM$650,$D8,FALSE),"") -> 3.5126734 | D8: =IFERROR(MATCH("META",RENDIMIENTO!$A$2:$BM$2,0),"") -> 5 | E8: BONO 0 SINIESTROS | G8: =IFERROR(VLOOKUP(CONSULTA!$B$2,BONOS!$A$6:$BM$650,$H8,FALSE),"") -> 134.18 | H8: =IFERROR(MATCH("BONO SINIESTROS",BONOS!$A$6:$BM$6,0),"") -> 11
B9: REDIMIENTO OBTENIDO | C9: =IFERROR(VLOOKUP(CONSULTA!$B$2,RENDIMIENTO!$A$2:$BM$650,$D9,FALSE),"") -> 3.5967005 | D9: =IFERROR(MATCH("REDIMIENTO OBTENIDO ",RENDIMIENTO!$A$2:$BM$2,0),"") -> 6 | E9: BONO 0 QUEJAS | G9: =IFERROR(VLOOKUP(CONSULTA!$B$2,BONOS!$A$6:$BM$650,$H9,FALSE),"") -> 134.18 | H9: =IFERROR(MATCH("BONO QUEJAS",BONOS!$A$6:$BM$6,0),"") -> 12
B10: SEMANA 34 | E10: BONO SCORE | G10: =IFERROR(VLOOKUP(CONSULTA!$B$2,BONOS!$A$6:$BM$650,$H10,FALSE),"") -> 200 | H10: =IFERROR(MATCH("BONO SCORE1",BONOS!$A$6:$BM$6,0),"") -> 14
E11: BONO LOGUEO | G11: =IFERROR(VLOOKUP(CONSULTA!$B$2,BONOS!$A$6:$BM$650,$H11,FALSE),"") -> 177.44 | H11: =IFERROR(MATCH("BONO LOGUEO1",BONOS!$A$6:$BM$6,0),"") -> 15
E12: BONO RENDIMIENTO | G12: =IFERROR(VLOOKUP(CONSULTA!$B$2,RENDIMIENTO!$A$2:$BM$650,$H12,FALSE),"") -> 355.58 | H12: =IFERROR(MATCH("TOTAL A PAGAR ",RENDIMIENTO!$A$2:$BM$2,0),"") -> 7
E14: TOTAL BONO DESEMPEÑO | G14: =IFERROR(VLOOKUP(CONSULTA!$B$2,BONOS!$A$6:$BM$650,$H14,FALSE),"") -> 645.8 | H14: =IFERROR(MATCH("TOTAL B.DESEMPEÑO ",BONOS!$A$6:$BM$6,0),"") -> 19
B17: Este documento es de carácter informativo. Su contenido carece de valor oficial, por lo que de requerir su “recibo de nómina”, favor de solicitarlo en oficinas de Transportes LIPU.
