Workbook

Sheet PUNTUALIDAD
A1: no. de nomina | B1: id | C1: id_servicio | D1: des | E1: Tipo de Viaje | F1: ID Ruta | G1: car | H1: shift | I1: group | J1: start_date | K1: start_time | L1: start_eta | M1: start_status | N1: end_date | O1: end_time | P1: end_eta | Q1: end_status | R1: operador | S1: Sem Via | T1: SALIDA | U1: LLEGADA | V1: Estatus Salida | W1: Estatus Llegada | X1: Estatus | Y1: Semana | Z1: Puntualidad | AA1: concat | AB1: supervisor2 | AC1: gte | AD1: CONCAT2 | AE1: ID Ruta | AF1: Turno | AG1: Dashtrax
A2: 14118625 | B2: 175447629 | C2: E-MOL-T1-R0010 | D2: Tlaquepaque 1 | E2: N | F2: 10 | G2: 13294 | H2: IN | I2: MOLEX | J2: 46236 | K2: 0.19097222 | L2: 0.19513889 | M2: done | N2: 46236 | O2: 0.26041667 | P2: 0.26052083 | Q2: done | R2: GUTIERREZ ROSALES ABNER ABRAHAM | S2: 32 | T2: 0.0041666667 | U2: 0.00010416667 | V2: Inicia tarde | W2: Llega a Tiempo | X2: Inicia tarde-Llega a Tiempo | Y2: 32 | Z2: No | AA2: Tlaquepaque 1MOLEX | AB2: VICTOR C. | AC2: Leopoldo V. | AD2: MOLEXTlaquepaque 1 | AE2: E-MOL-R0010 | AF2: T1 | AG2: Tlaquepaque 1-R0010-04:35
A3: 14122992 | B3: 175447907 | C3: E-HER-T1-R0039 | D3: Tonala-Tateposco Dominical | E3: N | F3: 39 | G3: 15693 | H3: IN | I3: HERSHEYS | J3: 46236 | K3: 0.19097222 | L3: 0.22222222 | M3: done | N3: 46236 | O3: 0.25 | P3: 0.25949074 | Q3: done | R3: OROPEZA GARCIA FRANCISCO JAVIER | S3: 32 | T3: 0.03125 | U3: 0.0094907407 | V3: Inicia tarde | W3: Llega tarde | X3: Inicia tarde-Llega tarde | Y3: 32 | Z3: No | AA3: Tonala-Tateposco DominicalHERSHEYS | AB3: CARLOS C. | AC3: Ilse M. | AD3: HERSHEYSTonala-Tateposco Dominical | AE3: E-HER-R0039 | AF3: T1 | AG3: Tonala-Tateposco Dominical-R0039-04:35
A4: 14117400 | B4: 175446306 | C4: E-SAN-T1-R0427 | D4: Dominical Tesistan Miramar | E4: N | F4: 427 | G4: 5474 | H4: IN | I4: SANMINA GDL | J4: 46236 | K4: 0.19444444 | L4: 0.20138889 | M4: done | N4: 46236 | O4: 0.26736111 | P4: 0.27462963 | Q4: done | R4: JEUDY X WANDY | S4: 32 | T4: 0.0069444444 | U4: 0.0072685185 | V4: Inicia tarde | W4: Llega tarde | X4: Inicia tarde-Llega tarde | Y4: 32 | Z4: No | AA4: Dominical Tesistan MiramarSANMINA GDL | AB4: PABLO F. | AC4: Felipe M. | AD4: SANMINA GDLDominical Tesistan Miramar | AE4: E-SAN-R0427 | AF4: T1 | AG4: Dominical Tesistan Miramar-R0427-04:40
A5: 14118773 | B5: 175446802 | C5: E-HER-T1-R0017 | D5: Arenales | E5: N | F5: 17 | G5: 14867 | H5: IN | I5: HERSHEYS | J5: 46236 | K5: 0.19444444 | L5: 0.22152778 | M5: done | N5: 46236 | O5: 0.25 | P5: 0.26109954 | Q5: done | R5: MARTINEZ ACOSTA MARIO EDUARDO | S5: 32 | T5: 0.027083333 | U5: 0.011099537 | V5: Inicia tarde | W5: Llega tarde | X5: Inicia tarde-Llega tarde | Y5: 32 | Z5: No | AA5: ArenalesHERSHEYS | AB5: CARLOS C. | AC5: Ilse M. | AD5: HERSHEYSArenales | AE5: E-HER-R0017 | AF5: T1 | AG5: Arenales-R0017-04:40
A6: 14123920 | B6: 175449768 | C6: E-PIS-T1-R0027 | D6: Las Juntas | E6: N | F6: 27 | G6: 4432 | H6: IN | I6: PIS-PISA | J6: 46236 | K6: 0.19444444 | L6: 0.20138889 | M6: done | N6: 46236 | O6: 0.26736111 | P6: 0.25394676 | Q6: done | R6: RIQUER HERNANDEZ ERWIN ALEXI | S6: 32 | T6: 0.0069444444 | U6: -0.013414352 | V6: Inicia tarde | W6: Llega a Tiempo | X6: Inicia tarde-Llega a Tiempo | Y6: 32 | Z6: No | AA6: Las JuntasPIS-PISA | AB6: DAVID C. | AC6: Felipe M. | AD6: PIS-PISALas Juntas | AE6: E-PIS-R0027 | AF6: T1 | AG6: Las Juntas-R0027-04:40
A7: 14113803 | B7: 175449820 | C7: E-PIS-T1-R0053 | D7: Colón-Patria | E7: N | F7: 53 | G7: 4340 | H7: IN | I7: PIS-PISA | J7: 46236 | K7: 0.19791667 | L7: 0.20347222 | M7: done | N7: 46236 | O7: 0.26736111 | P7: 0.24703704 | Q7: done | R7: CASTAÑEDA GOMEZ ALEJANDRO | S7: 32 | T7: 0.0055555556 | U7: -0.020324074 | V7: Inicia tarde | W7: Llega a Tiempo | X7: Inicia tarde-Llega a Tiempo | Y7: 32 | Z7: No | AA7: Colón-PatriaPIS-PISA | AB7: DAVID C. | AC7: Felipe M. | AD7: PIS-PISAColón-Patria | AE7: E-PIS-R0053 | AF7: T1 | AG7: Colón-Patria-R0053-04:45
A8: 14119324 | B8: 175446004 | C8: E-SM4-T1-R0129 | D8: Dominical San Sebastian 2 T1 | E8: N | F8: 129 | G8: 7915 | H8: IN | I8: SANMINA TLAJOMULCO | J8: 46236 | K8: 0.20208333 | L8: 0.20763889 | M8: done | N8: 46236 | O8: 0.26736111 | P8: 0.24672454 | Q8: done | R8: GONZALEZ VACA EDGAR ARTURO | S8: 32 | T8: 0.0055555556 | U8: -0.020636574 | V8: Inicia tarde | W8: Llega a Tiempo | X8: Inicia tarde-Llega a Tiempo | Y8: 32 | Z8: No | AA8: Dominical San Sebastian 2 T1SANMINA TLAJOMULCO | AB8: CUAUHTEMOC M. | AC8: Felipe M. | AD8: SANMINA TLAJOMULCODominical San Sebastian 2 T1 | AE8: E-SM4-R0129 | AF8: T1 | AG8: Dominical San Sebastian 2 T1-R0129-04:51
A9: 14123473 | B9: 175449752 | C9: E-PIS-T1-R0019 | D9: Fuelle | E9: N | F9: 19 | G9: 6906 | H9: IN | I9: PIS-PISA | J9: 46236 | K9: 0.20486111 | L9: 0.20972222 | M9: done | N9: 46236 | O9: 0.26736111 | P9: 0.24726852 | Q9: done | R9: FREGOSO EVANGELISTA MOISES | S9: 32 | T9: 0.0048611111 | U9: -0.020092593 | V9: Inicia tarde | W9: Llega a Tiempo | X9: Inicia tarde-Llega a Tiempo | Y9: 32 | Z9: No | AA9: FuellePIS-PISA | AB9: DAVID C. | AC9: Felipe M. | AD9: PIS-PISAFuelle | AE9: E-PIS-R0019 | AF9: T1 | AG9: Fuelle-R0019-04:55
A10: 14103106 | B10: 175444891 | C10: E-SK1-T1-R0028 | D10: Juanacatlan | E10: N | F10: 28 | G10: 16733 | H10: IN | I10: SANMINA KAMPUS 16 | J10: 46236 | K10: 0.20833333 | L10: 0.21180556 | M10: done | N10: 46236 | O10: 0.26736111 | P10: 0.25478009 | Q10: done | R10: CORTES ARMENTA HERNAN | S10: 32 | T10: 0.0034722222 | U10: -0.012581019 | V10: Inicia tarde | W10: Llega a Tiempo | X10: Inicia tarde-Llega a Tiempo | Y10: 32 | Z10: No | AA10: JuanacatlanSANMINA KAMPUS 16 | AB10: BRIAN A. | AC10: Felipe M. | AD10: SANMINA KAMPUS 16Juanacatlan | AE10: E-SK1-R0028 | AF10: T1 | AG10: Juanacatlan-R0028-05:00
A11: 14123004 | B11: 175449804 | C11: E-PIS-T1-R0045 | D11: Santa Anita | E11: N | F11: 45 | G11: 4875 | H11: IN | I11: PIS-PISA | J11: 46236 | K11: 0.20833333 | L11: 0.2125 | M11: done | N11: 46236 | O11: 0.26736111 | P11: 0.25284722 | Q11: done | R11: JUAREZ FAVELA JULIO CESAR | S11: 32 | T11: 0.0041666667 | U11: -0.014513889 | V11: Inicia tarde | W11: Llega a Tiempo | X11: Inicia tarde-Llega a Tiempo | Y11: 32 | Z11: No | AA11: Santa AnitaPIS-PISA | AB11: DAVID C. | AC11: Felipe M. | AD11: PIS-PISASanta Anita | AE11: E-PIS-R0045 | AF11: T1 | AG11: Santa Anita-R0045-05:00
A12: 14116431 | B12: 175444864 | C12: E-SK1-T1-R0015 | D12: Chulavista 2 T1 | E12: N | F12: 15 | G12: 16734 | H12: IN | I12: SANMINA KAMPUS 16 | J12: 46236 | K12: 0.21180556 | L12: 0.21597222 | M12: done | N12: 46236 | O12: 0.26736111 | P12: 0.25327546 | Q12: done | R12: JARAMILLO SANCHEZ MARCO ESTEBA | S12: 32 | T12: 0.0041666667 | U12: -0.014085648 | V12: Inicia tarde | W12: Llega a Tiempo | X12: Inicia tarde-Llega a Tiempo | Y12: 32 | Z12: No | AA12: Chulavista 2 T1SANMINA KAMPUS 16 | AB12: BRIAN A. | AC12: Felipe M. | AD12: SANMINA KAMPUS 16Chulavista 2 T1 | AE12: E-SK1-R0015 | AF12: T1 | AG12: Chulavista 2 T1-R0015-05:05
A13: 14120807 | B13: 175449756 | C13: E-PIS-T1-R0021 | D13: La Fortuna | E13: N | F13: 21 | G13: 4163 | H13: IN | I13: PIS-PISA | J13: 46236 | K13: 0.21180556 | L13: 0.21875 | M13: done | N13: 46236 | O13: 0.26736111 | P13: 0.24600694 | Q13: done | R13: MARTINEZ AGUIRRE BRAYAN ALEJAN | S13: 32 | T13: 0.0069444444 | U13: -0.021354167 | V13: Inicia tarde | W13: Llega a Tiempo | X13: Inicia tarde-Llega a Tiempo | Y13: 32 | Z13: No | AA13: La FortunaPIS-PISA | AB13: DAVID C. | AC13: Felipe M. | AD13: PIS-PISALa Fortuna | AE13: E-PIS-R0021 | AF13: T1 | AG13: La Fortuna-R0021-05:05
... A21: 14122904 | B21: 175443911 | C21: E-PEP-T1-R0049 | D21: Moctezuma Santa Rita | E21: N | F21: 49 | G21: 4487 | H21: IN | I21: PEPSICO GDL | J21: 46236 | K21: 0.23958333 | L21: 0.24652778 | M21: done | N21: 46236 | O21: 0.27083333 | P21: 0.26416667 | Q21: done | R21: TEJEDA MARTINEZ JOSE MANUEL | S21: 32 | T21: 0.0069444444 | U21: -0.0066666667 | V21: Inicia tarde | W21: Llega a Tiempo | X21: Inicia tarde-Llega a Tiempo | Y21: 32 | Z21: No | AA21: Moctezuma Santa RitaPEPSICO GDL | AB21: DANIEL | AC21: Leopoldo V. | AD21: PEPSICO GDLMoctezuma Santa Rita | AE21: E-PEP-R0049 | AF21: T1 | AG21: Moctezuma Santa Rita-R0049-05:45
B22: 175444825 | C22: E-PAQ-T1-R0003 | D22: Lopez Mateos Fin de semana | E22: N | F22: 3 | G22: 4392 | H22: IN | I22: PAQUETEXPRESS GDL | J22: 46236 | K22: 0.24513889 | L22: 0.25486111 | M22: done | N22: 46236 | O22: 0.29166667 | P22: 0.28525463 | Q22: done | R22: P.CURIEL HERNANDEZ EMMANUEL | S22: 32 | T22: 0.0097222222 | U22: -0.006412037 | V22: Inicia tarde | W22: Llega a Tiempo | X22: Inicia tarde-Llega a Tiempo | Y22: 32 | Z22: No | AA22: Lopez Mateos Fin de semanaPAQUETEXPRESS GDL | AB22: DAVID D. | AC22: Leopoldo V. | AD22: PAQUETEXPRESS GDLLopez Mateos Fin de semana | AE22: E-PAQ-R0003 | AF22: T1 | AG22: Lopez Mateos Fin de semana-R0003-05:53
A23: 14120196 | B23: 175449506 | C23: E-FOX-T1-R0102 | D23: El Zapote | E23: N | F23: 102 | G23: 14680 | H23: IN | I23: FOXCONN | J23: 46236 | K23: 0.24652778 | L23: 0.25416667 | M23: done | N23: 46236 | O23: 0.28125 | P23: 0.27806713 | Q23: done | R23: ALENCASTRO GARCIA FELIPE | S23: 32 | T23: 0.0076388889 | U23: -0.0031828704 | V23: Inicia tarde | W23: Llega a Tiempo | X23: Inicia tarde-Llega a Tiempo | Y23: 32 | Z23: No | AA23: El ZapoteFOXCONN | AB23: DIEGOVO. | AC23: Leopoldo V. | AD23: FOXCONNEl Zapote | AE23: E-FOX-R0102 | AF23: T1 | AG23: El Zapote-R0102-05:55
A24: 14123471 | B24: 175450024 | C24: E-FOX-T1-R0129 | D24: Las Huertas | E24: N | F24: 129 | G24: 5674 | H24: IN | I24: FOXCONN | J24: 46236 | K24: 0.24722222 | L24: 0.25069444 | M24: done | N24: 46236 | O24: 0.28125 | P24: 0.27291667 | Q24: done | R24: NUÑEZ ROSALES REYNALDO | S24: 32 | T24: 0.0034722222 | U24: -0.0083333333 | V24: Inicia tarde | W24: Llega a Tiempo | X24: Inicia tarde-Llega a Tiempo | Y24: 32 | Z24: No | AA24: Las HuertasFOXCONN | AB24: CANDELAS | AC24: Leopoldo V. | AD24: FOXCONNLas Huertas | AE24: E-FOX-R0129 | AF24: T1 | AG24: Las Huertas-R0129-05:56
A25: 14122136 | B25: 175448953 | C25: E-FOX-T1-R0086 | D25: Las Villas | E25: N | F25: 86 | G25: 16740 | H25: IN | I25: FOXCONN | J25: 46236 | K25: 0.25 | L25: 0.25972222 | M25: done | N25: 46236 | O25: 0.28125 | P25: 0.28174769 | Q25: done | R25: SEGOVIA AVILA RAUL | S25: 32 | T25: 0.0097222222 | U25: 0.00049768519 | V25: Inicia tarde | W25: Llega a Tiempo | X25: Inicia tarde-Llega a Tiempo | Y25: 32 | Z25: No | AA25: Las VillasFOXCONN | AB25: DIEGOVO. | AC25: Leopoldo V. | AD25: FOXCONNLas Villas | AE25: E-FOX-R0086 | AF25: T1 | AG25: Las Villas-R0086-06:00
A26: 14121152 | B26: 175447897 | C26: E-PAQ-T1-R0031 | D26: Villa Corona. | E26: N | F26: 31 | G26: 13011 | H26: IN | I26: PAQUETEXPRESS GDL | J26: 46236 | K26: 0.26388889 | L26: 0.29027778 | M26: done | N26: 46236 | O26: 0.29166667 | P26: 0.31319444 | Q26: done | R26: CONTRERAS CRUZ LUCINO | S26: 32 | T26: 0.026388889 | U26: 0.021527778 | V26: Inicia tarde | W26: Llega tarde | X26: Inicia tarde-Llega tarde | Y26: 32 | Z26: No | AA26: Villa Corona.PAQUETEXPRESS GDL | AB26: DAVID D. | AC26: Leopoldo V. | AD26: PAQUETEXPRESS GDLVilla Corona. | AE26: E-PAQ-R0031 | AF26: T1 | AG26: Villa Corona.-R0031-06:20
A27: 14119018 | B27: 175441266 | C27: E-PEP-T2-R0001 | D27: Moctezuma Santa Fe | E27: N | F27: 1 | G27: 10363 | H27: IN | I27: PEPSICO GDL | J27: 46236 | K27: 0.52083333 | L27: 0.52708333 | M27: done | N27: 46236 | O27: 0.60416667 | P27: 0.57659722 | Q27: done | R27: NUNGARAY BUENROSTRO SALVADOR | S27: 32 | T27: 0.00625 | U27: -0.027569444 | V27: Inicia tarde | W27: Llega a Tiempo | X27: Inicia tarde-Llega a Tiempo | Y27: 32 | Z27: No | AA27: Moctezuma Santa FePEPSICO GDL | AB27: DANIEL | AC27: Leopoldo V. | AD27: PEPSICO GDLMoctezuma Santa Fe | AE27: E-PEP-R0001 | AF27: T2 | AG27: Moctezuma Santa Fe-R0001-12:30
A28: 14118773 | B28: 175446803 | C28: E-HER-T2-R0017 | D28: Arenales | E28: N | F28: 17 | G28: 14867 | H28: IN | I28: HERSHEYS | J28: 46236 | K28: 0.52083333 | L28: 0.53472222 | M28: done | N28: 46236 | O28: 0.60416667 | P28: 0.5859375 | Q28: done | R28: MARTINEZ ACOSTA MARIO EDUARDO | S28: 32 | T28: 0.013888889 | U28: -0.018229167 | V28: Inicia tarde | W28: Llega a Tiempo | X28: Inicia tarde-Llega a Tiempo | Y28: 32 | Z28: No | AA28: ArenalesHERSHEYS | AB28: CARLOS C. | AC28: Ilse M. | AD28: HERSHEYSArenales | AE28: E-HER-R0017 | AF28: T2 | AG28: Arenales-R0017-12:30
A29: 14108222 | B29: 175444883 | C29: E-SK1-T2-R0025 | D29: Juan Pablo II | E29: N | F29: 25 | G29: 13844 | H29: IN | I29: SANMINA KAMPUS 16 | J29: 46236 | K29: 0.53125 | L29: 0.5375 | M29: done | N29: 46236 | O29: 0.60069444 | P29: 0.576875 | Q29: done | R29: TELLES PADILLA JOSE MANUEL | S29: 32 | T29: 0.00625 | U29: -0.023819444 | V29: Inicia tarde | W29: Llega a Tiempo | X29: Inicia tarde-Llega a Tiempo | Y29: 32 | Z29: No | AA29: Juan Pablo IISANMINA KAMPUS 16 | AB29: BRIAN A. | AC29: Felipe M. | AD29: SANMINA KAMPUS 16Juan Pablo II | AE29: E-SK1-R0025 | AF29: T2 | AG29: Juan Pablo II-R0025-12:45
A30: 14115536 | B30: 175450862 | C30: E-SAN-T2-R0504 | D30: Dominical Zapopan | E30: N | F30: 504 | G30: 5719 | H30: IN | I30: SANMINA GDL | J30: 46236 | K30: 0.53125 | L30: 0.5375 | M30: done | N30: 46236 | O30: 0.60069444 | P30: 0.59648148 | Q30: done | R30: VILLAGRAN PEREZ ARMANDO | S30: 32 | T30: 0.00625 | U30: -0.004212963 | V30: Inicia tarde | W30: Llega a Tiempo | X30: Inicia tarde-Llega a Tiempo | Y30: 32 | Z30: No | AA30: Dominical ZapopanSANMINA GDL | AB30: PABLO F. | AC30: Felipe M. | AD30: SANMINA GDLDominical Zapopan | AE30: E-SAN-R0504 | AF30: T2 | AG30: Dominical Zapopan-R0504-12:45
A31: 14115244 | B31: 175447438 | C31: E-AXL-T2-R0008 | D31: Centro Sur Fin de Semana | E31: N | F31: 8 | G31: 13044 | H31: IN | I31: AXIONLOG GDL | J31: 46236 | K31: 0.53472222 | L31: 0.54930556 | M31: done | N31: 46236 | O31: 0.59027778 | P31: 0.57986111 | Q31: done | R31: ANDALON ALVAREZ JOSE EUGENIO | S31: 32 | T31: 0.014583333 | U31: -0.010416667 | V31: Inicia tarde | W31: Llega a Tiempo | X31: Inicia tarde-Llega a Tiempo | Y31: 32 | Z31: No | AA31: Centro Sur Fin de SemanaAXIONLOG GDL | AB31: DAVID M | AC31: Ilse M. | AD31: AXIONLOG GDLCentro Sur Fin de Semana | AE31: E-AXL-R0008 | AF31: T2 | AG31: Centro Sur Fin de Semana-R0008-12:50
A32: 14103106 | B32: 175444892 | C32: E-SK1-T2-R0028 | D32: Juanacatlan | E32: N | F32: 28 | G32: 16733 | H32: IN | I32: SANMINA KAMPUS 16 | J32: 46236 | K32: 0.53958333 | L32: 0.54305556 | M32: done | N32: 46236 | O32: 0.60069444 | P32: 0.58434028 | Q32: done | R32: CORTES ARMENTA HERNAN | S32: 32 | T32: 0.0034722222 | U32: -0.016354167 | V32: Inicia tarde | W32: Llega a Tiempo | X32: Inicia tarde-Llega a Tiempo | Y32: 32 | Z32: No | AA32: JuanacatlanSANMINA KAMPUS 16 | AB32: BRIAN A. | AC32: Felipe M. | AD32: SANMINA KAMPUS 16Juanacatlan | AE32: E-SK1-R0028 | AF32: T2 | AG32: Juanacatlan-R0028-12:57
A33: 14106438 | B33: 175445479 | C33: E-PAQ-T2-R0018 | D33: 8 de Julio Fin de Semana | E33: N | F33: 18 | G33: 7005 | H33: IN | I33: PAQUETEXPRESS GDL | J33: 46236 | K33: 0.54166667 | L33: 0.54861111 | M33: done | N33: 46236 | O33: 0.58333333 | P33: 0.58267361 | Q33: done | R33: GAYTAN PINEDO CARLOS ENRIQUE | S33: 32 | T33: 0.0069444444 | U33: -0.00065972222 | V33: Inicia tarde | W33: Llega a Tiempo | X33: Inicia tarde-Llega a Tiempo | Y33: 32 | Z33: No | AA33: 8 de Julio Fin de SemanaPAQUETEXPRESS GDL | AB33: DAVID D. | AC33: Leopoldo V. | AD33: PAQUETEXPRESS GDL8 de Julio Fin de Semana | AE33: E-PAQ-R0018 | AF33: T2 | AG33: 8 de Julio Fin de Semana-R0018-13:00
A34: 14100731 | B34: 175446304 | C34: E-SAN-T2-R0425 | D34: Dominical Jauja-San pedrito T1 y T2 | E34: N | F34: 425 | G34: 16743 | H34: IN | I34: SANMINA GDL | J34: 46236 | K34: 0.54166667 | L34: 0.54791667 | M34: done | N34: 46236 | O34: 0.60069444 | P34: 0.58821759 | Q34: done | R34: TABARES FLORES OSCAR ALEJAND | S34: 32 | T34: 0.00625 | U34: -0.012476852 | V34: Inicia tarde | W34: Llega a Tiempo | X34: Inicia tarde-Llega a Tiempo | Y34: 32 | Z34: No | AA34: Dominical Jauja-San pedrito T1 y T2SANMINA GDL | AB34: PABLO F. | AC34: Felipe M. | AD34: SANMINA GDLDominical Jauja-San pedrito T1 y T2 | AE34: E-SAN-R0425 | AF34: T2 | AG34: Dominical Jauja-San pedrito T1 y T2-R0425-13:00
... A36: 14116431 | B36: 175495154 | C36: E-SK1-T2-R0091 | D36: San Sebastian | E36: N | F36: 91 | G36: 6352 | H36: IN | I36: SANMINA KAMPUS 16 | J36: 46236 | K36: 0.54166667 | L36: 0.55 | M36: done | N36: 46236 | O36: 0.60069444 | P36: 0.58888889 | Q36: done | R36: JARAMILLO SANCHEZ MARCO ESTEBA | S36: 32 | T36: 0.0083333333 | U36: -0.011805556 | V36: Inicia tarde | W36: Llega a Tiempo | X36: Inicia tarde-Llega a Tiempo | Y36: 32 | Z36: No | AA36: San SebastianSANMINA KAMPUS 16 | AB36: BRIAN A. | AC36: Felipe M. | AD36: SANMINA KAMPUS 16San Sebastian | AE36: E-SK1-R0091 | AF36: T2 | AG36: San Sebastian-R0091-13:00
A37: 14100718 | B37: 175446027 | C37: E-SM4-T2-R0140 | D37: Dominical Lomas de San Agustin | E37: N | F37: 140 | G37: 6782 | H37: IN | I37: SANMINA TLAJOMULCO | J37: 46236 | K37: 0.54513889 | L37: 0.66597222 | M37: done | N37: 46236 | O37: 0.60069444 | Q37: start | R37: MARTINEZ OCHOA PAULO | S37: 32 | T37: 0.12083333 | U37: -0.60069444 | V37: Inicia tarde | W37: Llega a Tiempo | X37: Inicia tarde-Llega a Tiempo | Y37: 32 | Z37: No | AA37: Dominical Lomas de San AgustinSANMINA TLAJOMULCO | AB37: CUAUHTEMOC M. | AC37: Felipe M. | AD37: SANMINA TLAJOMULCODominical Lomas de San Agustin | AE37: E-SM4-R0140 | AF37: T2 | AG37: Dominical Lomas de San Agustin-R0140-13:05
A38: 14120925 | B38: 175446016 | C38: E-SM4-T2-R0134 | D38: Dominical Parques de Santa Cruz | E38: N | F38: 134 | G38: 5530 | H38: IN | I38: SANMINA TLAJOMULCO | J38: 46236 | K38: 0.55208333 | L38: 0.5625 | M38: done | N38: 46236 | O38: 0.60069444 | P38: 0.60166667 | Q38: done | R38: RODRIGUEZ LOPEZ ANGEL ALBERTO | S38: 32 | T38: 0.010416667 | U38: 0.00097222222 | V38: Inicia tarde | W38: Llega a Tiempo | X38: Inicia tarde-Llega a Tiempo | Y38: 32 | Z38: No | AA38: Dominical Parques de Santa CruzSANMINA TLAJOMULCO | AB38: CUAUHTEMOC M. | AC38: Felipe M. | AD38: SANMINA TLAJOMULCODominical Parques de Santa Cruz | AE38: E-SM4-R0134 | AF38: T2 | AG38: Dominical Parques de Santa Cruz-R0134-13:15
A39: 14123312 | B39: 175449441 | C39: E-FOX-T2-R0096 | D39: Patria | E39: N | F39: 96 | G39: 6901 | H39: IN | I39: FOXCONN | J39: 46236 | K39: 0.5625 | L39: 0.58125 | M39: done | N39: 46236 | O39: 0.61458333 | P39: 0.59929398 | Q39: done | R39: MENDOZA OLIVA JESUS DE LOS REYES | S39: 32 | T39: 0.01875 | U39: -0.015289352 | V39: Inicia tarde | W39: Llega a Tiempo | X39: Inicia tarde-Llega a Tiempo | Y39: 32 | Z39: No | AA39: PatriaFOXCONN | AB39: CANDELAS | AC39: Leopoldo V. | AD39: FOXCONNPatria | AE39: E-FOX-R0096 | AF39: T2 | AG39: Patria-R0096-13:30
A40: 14118625 | B40: 175447630 | C40: E-MOL-T2-R0010 | D40: Tlaquepaque 1 | E40: N | F40: 10 | G40: 13294 | H40: IN | I40: MOLEX | J40: 46236 | K40: 0.66319444 | L40: 0.66736111 | M40: done | N40: 46236 | O40: 0.76041667 | P40: 0.73696759 | Q40: done | R40: GUTIERREZ ROSALES ABNER ABRAHAM | S40: 32 | T40: 0.0041666667 | U40: -0.023449074 | V40: Inicia tarde | W40: Llega a Tiempo | X40: Inicia tarde-Llega a Tiempo | Y40: 32 | Z40: No | AA40: Tlaquepaque 1MOLEX | AB40: VICTOR C. | AC40: Leopoldo V. | AD40: MOLEXTlaquepaque 1 | AE40: E-MOL-R0010 | AF40: T2 | AG40: Tlaquepaque 1-R0010-15:55
A41: 14123473 | B41: 175449753 | C41: E-PIS-T2-R0019 | D41: Fuelle | E41: N | F41: 19 | G41: 6906 | H41: IN | I41: PIS-PISA | J41: 46236 | K41: 0.68402778 | L41: 0.6875 | M41: done | N41: 46236 | O41: 0.76736111 | P41: 0.73140046 | Q41: done | R41: FREGOSO EVANGELISTA MOISES | S41: 32 | T41: 0.0034722222 | U41: -0.035960648 | V41: Inicia tarde | W41: Llega a Tiempo | X41: Inicia tarde-Llega a Tiempo | Y41: 32 | Z41: No | AA41: FuellePIS-PISA | AB41: DAVID C. | AC41: Felipe M. | AD41: PIS-PISAFuelle | AE41: E-PIS-R0019 | AF41: T2 | AG41: Fuelle-R0019-16:25
A42: 14123462 | B42: 175449797 | C42: E-PIS-T2-R0041 | D42: Parques del Palmar | E42: N | F42: 41 | G42: 4778 | H42: IN | I42: PIS-PISA | J42: 46236 | K42: 0.68402778 | L42: 0.6875 | M42: done | N42: 46236 | O42: 0.76736111 | P42: 0.73680556 | Q42: done | R42: CID CANCHOLA MARIO ALBERTO | S42: 32 | T42: 0.0034722222 | U42: -0.030555556 | V42: Inicia tarde | W42: Llega a Tiempo | X42: Inicia tarde-Llega a Tiempo | Y42: 32 | Z42: No | AA42: Parques del PalmarPIS-PISA | AB42: DAVID C. | AC42: Felipe M. | AD42: PIS-PISAParques del Palmar | AE42: E-PIS-R0041 | AF42: T2 | AG42: Parques del Palmar-R0041-16:25
A43: 14123004 | B43: 175449805 | C43: E-PIS-T2-R0045 | D43: Santa Anita | E43: N | F43: 45 | G43: 4875 | H43: IN | I43: PIS-PISA | J43: 46236 | K43: 0.70833333 | L43: 0.7125 | M43: done | N43: 46236 | O43: 0.76736111 | P43: 0.75369213 | Q43: done | R43: JUAREZ FAVELA JULIO CESAR | S43: 32 | T43: 0.0041666667 | U43: -0.013668981 | V43: Inicia tarde | W43: Llega a Tiempo | X43: Inicia tarde-Llega a Tiempo | Y43: 32 | Z43: No | AA43: Santa AnitaPIS-PISA | AB43: DAVID C. | AC43: Felipe M. | AD43: PIS-PISASanta Anita | AE43: E-PIS-R0045 | AF43: T2 | AG43: Santa Anita-R0045-17:00
A44: 14107217 | B44: 175449869 | C44: E-PIS-T2-R0079 | D44: Villas de la Hacienda | E44: N | F44: 79 | G44: 6885 | H44: IN | I44: PIS-PISA | J44: 46236 | K44: 0.70833333 | L44: 0.71180556 | M44: done | N44: 46236 | O44: 0.76736111 | P44: 0.74537037 | Q44: done | R44: GARCIA PEREZ ALFONSO | S44: 32 | T44: 0.0034722222 | U44: -0.021990741 | V44: Inicia tarde | W44: Llega a Tiempo | X44: Inicia tarde-Llega a Tiempo | Y44: 32 | Z44: No | AA44: Villas de la HaciendaPIS-PISA | AB44: DAVID C. | AC44: Felipe M. | AD44: PIS-PISAVillas de la Hacienda | AE44: E-PIS-R0079 | AF44: T2 | AG44: Villas de la Hacienda-R0079-17:00
A45: 14102875 | B45: 175449801 | C45: E-PIS-T2-R0043 | D45: Periferico Sur | E45: N | F45: 43 | G45: 4431 | H45: IN | I45: PIS-PISA | J45: 46236 | K45: 0.71180556 | L45: 0.71597222 | M45: done | N45: 46236 | O45: 0.76736111 | P45: 0.75511574 | Q45: done | R45: LARIOS SANCHEZ HECTOR ALEXANDE | S45: 32 | T45: 0.0041666667 | U45: -0.01224537 | V45: Inicia tarde | W45: Llega a Tiempo | X45: Inicia tarde-Llega a Tiempo | Y45: 32 | Z45: No | AA45: Periferico SurPIS-PISA | AB45: DAVID C. | AC45: Felipe M. | AD45: PIS-PISAPeriferico Sur | AE45: E-PIS-R0043 | AF45: T2 | AG45: Periferico Sur-R0043-17:05
A46: 14122113 | B46: 175450174 | C46: E-PIS-T2-R0095 | D46: Las Vias | E46: N | F46: 95 | G46: 4534 | H46: IN | I46: PIS-PISA | J46: 46236 | K46: 0.72222222 | L46: 0.72847222 | M46: done | N46: 46236 | O46: 0.76736111 | P46: 0.74930556 | Q46: done | R46: DELGADILLO SANCHEZ EDSON FABIA | S46: 32 | T46: 0.00625 | U46: -0.018055556 | V46: Inicia tarde | W46: Llega a Tiempo | X46: Inicia tarde-Llega a Tiempo | Y46: 32 | Z46: No | AA46: Las ViasPIS-PISA | AB46: DAVID C. | AC46: Felipe M. | AD46: PIS-PISALas Vias | AE46: E-PIS-R0095 | AF46: T2 | AG46: Las Vias-R0095-17:20
A47: 14100718 | B47: 175446028 | C47: E-SM4-T3-R0140 | D47: Dominical Lomas de San Agustin | E47: N | F47: 140 | G47: 6782 | H47: IN | I47: SANMINA TLAJOMULCO | J47: 46236 | K47: 0.86111111 | L47: 0.86458333 | M47: done | N47: 46236 | O47: 0.93402778 | P47: 0.92083333 | Q47: done | R47: MARTINEZ OCHOA PAULO | S47: 32 | T47: 0.0034722222 | U47: -0.013194444 | V47: Inicia tarde | W47: Llega a Tiempo | X47: Inicia tarde-Llega a Tiempo | Y47: 32 | Z47: No | AA47: Dominical Lomas de San AgustinSANMINA TLAJOMULCO | AB47: CUAUHTEMOC M. | AC47: Felipe M. | AD47: SANMINA TLAJOMULCODominical Lomas de San Agustin | AE47: E-SM4-R0140 | AF47: T3 | AG47: Dominical Lomas de San Agustin-R0140-20:40
A48: 14103183 | B48: 175443414 | C48: E-DIA-T3-R0001 | D48: Atotonilco-Nueva Destileria | E48: N | F48: 1 | G48: 15313 | H48: IN | I48: DIAGEO GDL | J48: 46236 | K48: 0.86805556 | L48: 0.87152778 | M48: done | N48: 46236 | O48: 0.88888889 | P48: 0.88263889 | Q48: done | R48: HERNANDEZ RON BLANCA HERLINDA | S48: 32 | T48: 0.0034722222 | U48: -0.00625 | V48: Inicia tarde | W48: Llega a Tiempo | X48: Inicia tarde-Llega a Tiempo | Y48: 32 | Z48: No | AA48: Atotonilco-Nueva DestileriaDIAGEO GDL | AB48: VIRIDIANA G | AC48: Ilse M. | AD48: DIAGEO GDLAtotonilco-Nueva Destileria | AE48: E-DIA-R0001 | AF48: T3 | AG48: Atotonilco-Nueva Destileria-R0001-20:50
...

Sheet ACUMULADO
A1: agrupador | B1: concepto | C1: clave | D1: nombre_completo | E1: importe | F1: periodo
A2: PRESTACIONES | B2: BONO DE RENDIMI | C2: 14100716 | D2: AMBRIZ MERCADO MARTIN | E2: 355.8 | F2: S33
A3: PRESTACIONES | B3: BONO DE RENDIMI | C3: 14106035 | D3: TAMAYO GONZALEZ CHRISTIAN JESUS | E3: 355.58 | F3: S33
A4: PRESTACIONES | B4: BONO DE RENDIMI | C4: 14118625 | D4: GUTIERREZ ROSALES ABNER ABRAHAM | E4: 355.58 | F4: S33
A5: PRESTACIONES | B5: BONO DE RENDIMI | C5: 14122681 | D5: FLORES RUIZ CLEMENTE | E5: 355.58 | F5: S33
A6: PRESTACIONES | B6: BONO DE RENDIMI | C6: 14122682 | D6: PONCE REYNOSO GILBERTO | E6: 355.58 | F6: S33
A7: PRESTACIONES | B7: BONO DE RENDIMI | C7: 14122994 | D7: TEPOSTE JIMENEZ MARCOS GUADALUPE | E7: 355.58 | F7: S33
A8: PRESTACIONES | B8: BONO DE RENDIMI | C8: 14123082 | D8: NAVARRO LEMUS LUIS ANGEL | E8: 355.58 | F8: S33
A9: PRESTACIONES | B9: BONO DE RENDIMI | C9: 14123145 | D9: ALVAREZ AGUILAR DIEGO ARTURO | E9: 355.58 | F9: S33
A10: PRESTACIONES | B10: BONO DE RENDIMI | C10: 14123332 | D10: LARA SANDOVAL JOSE MIGUEL | E10: 1422.32 | F10: S33
A11: PRESTACIONES | B11: BONO DE RENDIMI | C11: 14103470 | D11: DEL TORO MARTINEZ HECTOR JOSE | E11: 355.58 | F11: S33
A12: PRESTACIONES | B12: BONO DE RENDIMI | C12: 14110506 | D12: SALAZAR LOPEZ JOVANNY | E12: 355.58 | F12: S33
A13: PRESTACIONES | B13: BONO DE RENDIMI | C13: 14110604 | D13: DIAZ BLANQUET ROSA JANNET | E13: 355.58 | F13: S33
... A3713: PRESTACIONES | B3713: VIAJES ADICIONA2 | C3713: 14121571 | D3713: VILLALOBOS CURIEL ANDRES ALEJANDRO | E3713: 800 | F3713: S33

Sheet RENDIMIENTO
A2: CLAVE | B2: NOMBRE | C2: F.INGRESO | D2: UNIDAD | E2: META | F2: REDIMIENTO OBTENIDO | G2: TOTAL A PAGAR | H2: SEMANA DE RETROACTIVO
A3: 14100714 | B3: RAMIREZ RODRIGUEZ JESUS | C3: 2019-01-11 | D3: LIPU | E3: 3.5126734 | F3: 3.5967005 | G3: 355.58
A4: 14100718 | B4: MARTINEZ OCHOA PAULO | C4: 2017-05-01 | D4: LIPU | E4: 11.418646 | F4: 11.379 | G4: 0
A5: 14100721 | B5: GUTIERREZ VELEZ FRANCISCO | C5: 2021-07-08 | D5: LIPU | E5: 4.3532522 | F5: 3.9910251 | G5: 0
A6: 14100724 | B6: ORTIZ GARCIA LUIS ALBERTO | C6: 2017-05-01 | D6: LIPU | E6: 4.5080442 | F6: 5.3252909 | G6: 355.58
A7: 14100725 | B7: NAJAR LOPEZ JOSE SERGIO | C7: 2017-05-01 | D7: LIPU | E7: 4.436782 | F7: 4.749576 | G7: 355.58
A8: 14100726 | B8: GUZMAN MUNGUIA LUIS JAVIER | C8: 2017-05-01 | D8: LIPU | E8: 3.96182 | F8: 4.7084276 | G8: 355.58
A9: 14100727 | B9: ALONZO PEREZ JOSE REYES | C9: 2017-05-01 | D9: LIPU | E9: 4.9834409 | F9: 6.7414353 | G9: 355.58
A10: 14100729 | B10: LARIOS ALCARAZ EDUARDO | C10: 2017-05-01 | D10: LIPU | E10: Descansero | F10: Descansero | G10: 355.58
A11: 14100731 | B11: TABARES FLORES OSCAR ALEJANDRO | C11: 2022-09-02 | D11: LIPU | E11: 4.4326521 | F11: 4.9581321 | G11: 355.58
A12: 14100732 | B12: ROBLES DEADEL LAZARO | C12: 2017-05-01 | D12: LIPU | E12: 3.7835575 | F12: 5.1784205 | G12: 355.58
A13: 14100733 | B13: LINARES CISNEROS JOSE ANTONIO | C13: 2017-05-01 | D13: LIPU | E13: Descansero | F13: Descansero | G13: 355.58
A14: 14100740 | B14: OLIVARES HERNANDEZ GABRIEL | C14: 2021-11-17 | D14: LIPU | E14: 4.4923786 | F14: 5.4948638 | G14: 355.58
A15: 14100751 | B15: FLORES GARCIA PEDRO | C15: 2025-10-10 | D15: LIPU | E15: 3.96 | F15: 4.07 | G15: 355.58
A16: 14100777 | B16: GONZALEZ MANZO JAVIER OSWALDO | C16: 2017-05-01 | D16: LIPU | E16: Descansero | F16: Descansero | G16: 355.58
A17: 14100787 | B17: YEPEZ VAZQUEZ JOAN | C17: 2017-05-01 | D17: LIPU | E17: 3.7922536 | F17: 5.1406174 | G17: 355.58
A18: 14100795 | B18: BALTAZAR MENDOZA HORACIO | C18: 2017-05-01 | D18: LIPU | E18: 4.662251 | F18: 4.018721 | G18: 0
A19: 14100798 | B19: CARRILLO REYNOSO JESUS ALEJANDRO | C19: 2017-05-01 | D19: LIPU | E19: 4.0644462 | F19: 5.0306612 | G19: 355.58
A20: 14100807 | B20: OSORIO HERNANDEZ DOMINGO | C20: 2023-05-12 | D20: LIPU | E20: 4.7317431 | F20: 6.2797497 | G20: 355.58
A21: 14100823 | B21: FLORES ENRIQUEZ JUAN PABLO | C21: 2024-08-05 | D21: LIPU | E21: Descansero | F21: Descansero | G21: 355.58
A22: 14100842 | B22: BECERRA LUNA GUILLERMO | C22: 2017-05-01 | D22: LIPU | E22: Descansero | F22: Descansero | G22: 355.58
A23: 14100843 | B23: LOPEZ RAYMUNDO ROBERTO | C23: 2025-03-07 | D23: LIPU | E23: 3.5970917 | F23: 4.1459307 | G23: 355.58
A24: 14100858 | B24: REYNAGA SANCHEZ MARIO | C24: 2025-06-06 | D24: LIPU | E24: 3.7292467 | F24: 4.774209 | G24: 355.58
A25: 14100863 | B25: MARTINEZ ZAVALA FRANCISCO ESPIRIDION | C25: 2017-05-01 | D25: LIPU | E25: Retroactivo | F25: Retroactivo | G25: 711.16
A26: 14100897 | B26: CRUZ GUTIERREZ ALFREDO | C26: 2025-05-09 | D26: LIPU | E26: 4.0121683 | F26: 3.6816731 | G26: 0
A27: 14100902 | B27: SANCHEZ PONCE JOSE ALBERTO | C27: 2025-12-31 | D27: LIPU | E27: 4.0414963 | F27: 5.200803 | G27: 355.58
A28: 14101881 | B28: MORALES AGUILAR ALBERTO | C28: 2017-05-24 | D28: LIPU | E28: 3.9 | F28: 4.898404 | G28: 355.58
A29: 14101984 | B29: TABARES VAZQUEZ MARTIN | C29: 2018-11-29 | D29: LIPU | E29: 4.1883124 | F29: 5.032933 | G29: 355.58
A30: 14102081 | B30: OLEA SANCHEZ JOSE LUIS | C30: 2017-07-07 | D30: LIPU | E30: 7.0119567 | F30: 7.0810594 | G30: 355.58
A31: 14102288 | B31: RAMOS ANGUIANO SERGIO DAVID | C31: 2017-08-15 | D31: LIPU | E31: Descansero | F31: Descansero | G31: 355.58
A32: 14102701 | B32: ORTIZ HERNANDEZ JESUS GUADALUPE | C32: 2017-11-06 | D32: LIPU | E32: Descansero | F32: Descansero | G32: 355.58
A33: 14102730 | B33: ESTRADA ALVAREZ FERNANDO | C33: 2017-11-13 | D33: LIPU | E33: Retroactivo | F33: Retroactivo | G33: 355.58
A34: 14102875 | B34: LARIOS SANCHEZ HECTOR ALEXANDER | C34: 2017-12-20 | D34: LIPU | E34: 2.8043955 | F34: 3.9897073 | G34: 355.58
A35: 14102890 | B35: GONZALEZ VALENCIA BARTOLO | C35: 2017-12-21 | D35: LIPU | E35: 4.5700688 | F35: 5.5428299 | G35: 355.58
A36: 14103061 | B36: SANCHEZ PEREZ CARLOS FORTINO | C36: 2023-06-01 | D36: LIPU | E36: 3.6322725 | F36: 4.3610519 | G36: 355.58
A37: 14103106 | B37: CORTES ARMENTA HERNAN | C37: 2018-02-02 | D37: LIPU | E37: 4.0644255 | F37: 5.164819 | G37: 355.58
A38: 14103183 | B38: HERNANDEZ RON BLANCA HERLINDA | C38: 2018-02-27 | D38: LIPU | E38: 3.7173108 | F38: 4.233 | G38: 355.58
A39: 14103335 | B39: RIVERA MARTINEZ GUSTAVO | C39: 2018-04-09 | D39: LIPU | E39: 3.6673041 | F39: 4.3362235 | G39: 355.58
A40: 14103470 | B40: DEL TORO MARTINEZ HECTOR JOSE | C40: 2026-06-13 | D40: LIPU | E40: 4.4612301 | F40: 4.8965182 | G40: 355.58
A41: 14103679 | B41: BAUTISTA SOLORIO JAIME | C41: 2018-06-29 | D41: LIPU | E41: 10.744593 | F41: 13.602047 | G41: 355.58
...

Sheet BONOS
F1: 2002 AL 2015 4.30 | K1: SINIESTROS | L1: QUEJAS | M1: PUNTUALIDAD | N1: SCORE | O1: LOGUEO
A2: SEMANA 33 | F2: camion | K2: 134.18 | L2: 134.18 | N2: 200 | O2: 177.44
K4: 69639.42 | L4: 67895.08 | M4: 0 | N4: 48200 | O4: 50215.52 | P4: 0 | Q4: 0 | R4: 0 | S4: 235950.02
E5: CON/SIN | F5: CON/SIN | G5: TOTAL | H5: OK/NO | I5: OK/NO | J5: LOGUEO/NO LOGUEO | K5: TOTAL FORMULADO OBTENIDO | S5: TOTAL FORMULADO
A6: CLAVE | B6: NOMBRE | C6: F.INGRESO | D6: UNIDAD | E6: SINIESTROS | F6: QUEJAS | G6: SCORE OBTENIDO | H6: BONO SCORE | I6: PUNTUALIDAD | J6: BONO LOGUEO | K6: BONO SINIESTROS | L6: BONO QUEJAS | M6: BONO PUNTUALIDAD | N6: BONO SCORE1 | O6: BONO LOGUEO1 | P6: TOTAL BONO | Q6: DETALLE(FECHA DE SINIESTRO) | R6: OBSERVACIONES | S6: TOTAL B.DESEMPEÑO | U6: CONFIRMACIÓN DE VIAJE | V6: GUARDIA
A7: 14100714 | B7: RAMIREZ RODRIGUEZ JESUS | C7: 2019-01-11 | D7: LIPU | E7: SIN SINIESTRO | F7: SIN QUEJA | G7: 95 | H7: OK | I7: OK | J7: LOGUEO | K7: 134.18 | L7: 134.18 | N7: 200 | O7: 177.44 | S7: 645.8 | U7: BONO | V7: NO
A8: 14100718 | B8: MARTINEZ OCHOA PAULO | C8: 2017-05-01 | D8: LIPU | E8: SIN SINIESTRO | F8: SIN QUEJA | G8: 91 | H8: OK | I8: NO | J8: LOGUEO | K8: 134.18 | L8: 134.18 | N8: 0 | O8: 0 | S8: 268.36 | U8: BONO | V8: NO
A9: 14100721 | B9: GUTIERREZ VELEZ FRANCISCO | C9: 2021-07-08 | D9: LIPU | E9: SIN SINIESTRO | F9: SIN QUEJA | G9: 84 | H9: NO | I9: NO | J9: LOGUEO | K9: 134.18 | L9: 134.18 | N9: 0 | O9: 0 | S9: 268.36 | U9: BONO | V9: NO
A10: 14100724 | B10: ORTIZ GARCIA LUIS ALBERTO | C10: 2017-05-01 | D10: LIPU | E10: SIN SINIESTRO | F10: SIN QUEJA | G10: 95 | H10: OK | I10: OK | J10: LOGUEO | K10: 134.18 | L10: 134.18 | N10: 200 | O10: 177.44 | S10: 645.8 | U10: BONO | V10: NO
A11: 14100725 | B11: NAJAR LOPEZ JOSE SERGIO | C11: 2017-05-01 | D11: LIPU | E11: SIN SINIESTRO | F11: SIN QUEJA | G11: 93 | H11: OK | I11: NO | J11: LOGUEO | K11: 134.18 | L11: 134.18 | N11: 0 | O11: 0 | S11: 268.36 | U11: BONO | V11: NO
A12: 14100726 | B12: GUZMAN MUNGUIA LUIS JAVIER | C12: 2017-05-01 | D12: LIPU | E12: SIN SINIESTRO | F12: SIN QUEJA | G12: 95 | H12: OK | I12: OK | J12: LOGUEO | K12: 134.18 | L12: 134.18 | N12: 200 | O12: 177.44 | S12: 645.8 | U12: BONO | V12: NO
A13: 14100727 | B13: ALONZO PEREZ JOSE REYES | C13: 2017-05-01 | D13: LIPU | E13: SIN SINIESTRO | F13: SIN QUEJA | G13: 92 | H13: OK | I13: NO | J13: LOGUEO | K13: 134.18 | L13: 134.18 | N13: 0 | O13: 0 | S13: 268.36 | U13: BONO | V13: NO
A14: 14100729 | B14: LARIOS ALCARAZ EDUARDO | C14: 2017-05-01 | D14: LIPU | E14: SIN SINIESTRO | F14: SIN QUEJA | G14: 88 | H14: NO | I14: NO | J14: LOGUEO | K14: 134.18 | L14: 134.18 | N14: 0 | O14: 0 | S14: 268.36 | U14: BONO | V14: NO
A15: 14100731 | B15: TABARES FLORES OSCAR ALEJANDRO | C15: 2022-09-02 | D15: LIPU | E15: SIN SINIESTRO | F15: SIN QUEJA | G15: 91 | H15: OK | I15: NO | J15: LOGUEO | K15: 134.18 | L15: 134.18 | N15: 0 | O15: 0 | S15: 268.36 | U15: BONO | V15: NO
A16: 14100732 | B16: ROBLES DEADEL LAZARO | C16: 2017-05-01 | D16: LIPU | E16: SIN SINIESTRO | F16: SIN QUEJA | G16: 92 | H16: OK | I16: OK | J16: LOGUEO | K16: 134.18 | L16: 134.18 | N16: 200 | O16: 177.44 | S16: 645.8 | U16: BONO | V16: NO
A17: 14100733 | B17: LINARES CISNEROS JOSE ANTONIO | C17: 2017-05-01 | D17: LIPU | E17: SIN SINIESTRO | F17: SIN QUEJA | G17: 94 | H17: OK | I17: NO | J17: LOGUEO | K17: 134.18 | L17: 134.18 | N17: 0 | O17: 0 | S17: 268.36 | U17: BONO | V17: NO
A18: 14100740 | B18: OLIVARES HERNANDEZ GABRIEL | C18: 2021-11-17 | D18: LIPU | E18: SIN SINIESTRO | F18: SIN QUEJA | G18: 93 | H18: OK | I18: NO | J18: LOGUEO | K18: 134.18 | L18: 134.18 | N18: 0 | O18: 0 | S18: 268.36 | U18: BONO | V18: NO
A19: 14100751 | B19: FLORES GARCIA PEDRO | C19: 2025-10-10 | D19: LIPU | E19: SIN SINIESTRO | F19: SIN QUEJA | G19: 90 | H19: OK | I19: OK | J19: LOGUEO | K19: 134.18 | L19: 134.18 | N19: 200 | O19: 177.44 | S19: 645.8 | U19: BONO | V19: NO
A20: 14100777 | B20: GONZALEZ MANZO JAVIER OSWALDO | C20: 2017-05-01 | D20: LIPU | E20: SIN SINIESTRO | F20: SIN QUEJA | H20: NO | I20: OK | J20: NO LOGUEO | K20: 0 | L20: 0 | N20: 0 | O20: 0 | S20: 0 | U20: NO | V20: NO
A21: 14100787 | B21: YEPEZ VAZQUEZ JOAN | C21: 2017-05-01 | D21: LIPU | E21: SIN SINIESTRO | F21: SIN QUEJA | G21: 92 | H21: OK | I21: NO | J21: LOGUEO | K21: 134.18 | L21: 134.18 | N21: 0 | O21: 0 | S21: 268.36 | U21: BONO | V21: NO
A22: 14100795 | B22: BALTAZAR MENDOZA HORACIO | C22: 2017-05-01 | D22: LIPU | E22: SIN SINIESTRO | F22: SIN QUEJA | G22: 92 | H22: OK | I22: OK | J22: NO LOGUEO | K22: 134.18 | L22: 134.18 | N22: 200 | O22: 0 | S22: 468.36 | U22: BONO | V22: NO
A23: 14100798 | B23: CARRILLO REYNOSO JESUS ALEJANDRO | C23: 2017-05-01 | D23: LIPU | E23: SIN SINIESTRO | F23: SIN QUEJA | G23: 95 | H23: OK | I23: OK | J23: LOGUEO | K23: 134.18 | L23: 134.18 | N23: 200 | O23: 177.44 | S23: 645.8 | U23: BONO | V23: NO
A24: 14100807 | B24: OSORIO HERNANDEZ DOMINGO | C24: 2023-05-12 | D24: LIPU | E24: SIN SINIESTRO | F24: SIN QUEJA | G24: 92 | H24: OK | I24: OK | J24: LOGUEO | K24: 134.18 | L24: 134.18 | N24: 200 | O24: 177.44 | S24: 645.8 | U24: BONO | V24: NO
A25: 14100823 | B25: FLORES ENRIQUEZ JUAN PABLO | C25: 2024-08-05 | D25: LIPU | E25: SIN SINIESTRO | F25: SIN QUEJA | G25: 94 | H25: OK | I25: OK | J25: LOGUEO | K25: 134.18 | L25: 134.18 | N25: 200 | O25: 177.44 | S25: 645.8 | U25: BONO | V25: GUARDIA
A26: 14100842 | B26: BECERRA LUNA GUILLERMO | C26: 2017-05-01 | D26: LIPU | E26: SIN SINIESTRO | F26: SIN QUEJA | H26: NO | I26: OK | J26: NO LOGUEO | K26: 0 | L26: 0 | N26: 0 | O26: 0 | S26: 0 | U26: NO | V26: NO
A27: 14100843 | B27: LOPEZ RAYMUNDO ROBERTO | C27: 2025-03-07 | D27: LIPU | E27: SIN SINIESTRO | F27: SIN QUEJA | G27: 92 | H27: OK | I27: NO | J27: LOGUEO | K27: 134.18 | L27: 134.18 | N27: 0 | O27: 0 | S27: 268.36 | U27: BONO | V27: NO
A28: 14100858 | B28: REYNAGA SANCHEZ MARIO | C28: 2025-06-06 | D28: LIPU | E28: SIN SINIESTRO | F28: SIN QUEJA | G28: 93 | H28: OK | I28: OK | J28: LOGUEO | K28: 134.18 | L28: 134.18 | N28: 200 | O28: 177.44 | S28: 645.8 | U28: BONO | V28: NO
A29: 14100863 | B29: MARTINEZ ZAVALA FRANCISCO ESPIRIDION | C29: 2017-05-01 | D29: LIPU | E29: SIN SINIESTRO | F29: SIN QUEJA | G29: 95 | H29: OK | I29: OK | J29: LOGUEO | K29: 134.18 | L29: 134.18 | N29: 200 | O29: 177.44 | S29: 645.8 | U29: BONO | V29: NO
A30: 14100897 | B30: CRUZ GUTIERREZ ALFREDO | C30: 2025-05-09 | D30: LIPU | E30: SIN SINIESTRO | F30: SIN QUEJA | G30: 93 | H30: OK | I30: OK | J30: LOGUEO | K30: 134.18 | L30: 134.18 | N30: 200 | O30: 177.44 | S30: 645.8 | U30: BONO | V30: NO
A31: 14100902 | B31: SANCHEZ PONCE JOSE ALBERTO | C31: 2025-12-31 | D31: LIPU | E31: SIN SINIESTRO | F31: SIN QUEJA | G31: 89 | H31: NO | I31: OK | J31: LOGUEO | K31: 134.18 | L31: 134.18 | N31: 0 | O31: 177.44 | S31: 445.8 | U31: BONO | V31: NO
A32: 14101881 | B32: MORALES AGUILAR ALBERTO | C32: 2017-05-24 | D32: LIPU | E32: SIN SINIESTRO | F32: SIN QUEJA | G32: 89 | H32: NO | I32: NO | J32: LOGUEO | K32: 134.18 | L32: 134.18 | N32: 0 | O32: 0 | S32: 268.36 | U32: BONO | V32: NO
A33: 14101984 | B33: TABARES VAZQUEZ MARTIN | C33: 2018-11-29 | D33: LIPU | E33: SIN SINIESTRO | F33: SIN QUEJA | G33: 87 | H33: NO | I33: OK | J33: NO LOGUEO | K33: 134.18 | L33: 134.18 | N33: 0 | O33: 0 | S33: 268.36 | U33: BONO | V33: NO
A34: 14102081 | B34: OLEA SANCHEZ JOSE LUIS | C34: 2017-07-07 | D34: LIPU | E34: SIN SINIESTRO | F34: SIN QUEJA | G34: 89 | H34: NO | I34: OK | J34: NO LOGUEO | K34: 0 | L34: 0 | N34: 0 | O34: 0 | S34: 0 | U34: NO | V34: NO
A35: 14102288 | B35: RAMOS ANGUIANO SERGIO DAVID | C35: 2017-08-15 | D35: LIPU | E35: SIN SINIESTRO | F35: SIN QUEJA | G35: 94 | H35: OK | I35: OK | J35: LOGUEO | K35: 134.18 | L35: 134.18 | N35: 200 | O35: 177.44 | S35: 645.8 | U35: BONO | V35: NO
A36: 14102701 | B36: ORTIZ HERNANDEZ JESUS GUADALUPE | C36: 2017-11-06 | D36: LIPU | E36: SIN SINIESTRO | F36: SIN QUEJA | G36: 87 | H36: NO | I36: NO | J36: LOGUEO | K36: 134.18 | L36: 134.18 | N36: 0 | O36: 0 | S36: 268.36 | U36: BONO | V36: NO
A37: 14102730 | B37: ESTRADA ALVAREZ FERNANDO | C37: 2017-11-13 | D37: LIPU | E37: SIN SINIESTRO | F37: SIN QUEJA | G37: 95 | H37: OK | I37: OK | J37: LOGUEO | K37: 134.18 | L37: 134.18 | N37: 200 | O37: 177.44 | S37: 645.8 | U37: BONO | V37: NO
A38: 14102875 | B38: LARIOS SANCHEZ HECTOR ALEXANDER | C38: 2017-12-20 | D38: LIPU | E38: SIN SINIESTRO | F38: SIN QUEJA | G38: 93 | H38: OK | I38: NO | J38: LOGUEO | K38: 134.18 | L38: 134.18 | N38: 0 | O38: 0 | S38: 268.36 | U38: BONO | V38: GUARDIA
... A65: 14106438 | B65: GAYTAN PINEDO CARLOS ENRIQUE | C65: 2020-05-19 | D65: LIPU | E65: SIN SINIESTRO | F65: SIN QUEJA | G65: 95 | H65: OK | I65: NO | J65: LOGUEO | K65: 134.18 | L65: 134.18 | N65: 0 | O65: 0 | S65: 268.36 | U65: BONO | V65: NO
A66: 14106778 | B66: CABALLERO ANGUIANO SERGIO | C66: 2020-07-24 | D66: LIPU | E66: SIN SINIESTRO | F66: SIN QUEJA | H66: NO | I66: OK | J66: NO LOGUEO | K66: 0 | L66: 0 | N66: 0 | O66: 0 | S66: 0 | U66: NO | V66: NO
A67: 14106949 | B67: SOTELO AVIÑA MICHEL ALEJANDRO | C67: 2020-09-21 | D67: LIPU | E67: SIN SINIESTRO | F67: SIN QUEJA | G67: 95 | H67: OK | I67: OK | J67: LOGUEO | K67: 134.18 | L67: 134.18 | N67: 200 | O67: 177.44 | S67: 645.8 | U67: BONO | V67: NO
...

Sheet CONSULTA
B1: NÓMINA
B2: 14119958
B3: NOMBRE | C3: =IFERROR(VLOOKUP(CONSULTA!$B$2,BONOS!$A$6:$BM$650,$H3,FALSE),"") -> MARTINEZ PATRICIO ANGEL ULISES | H3: =IFERROR(MATCH("NOMBRE ",BONOS!$A$6:$BM$6,0),"") -> 2
B4: SINIESTROS | C4: =IFERROR(VLOOKUP(CONSULTA!$B$2,BONOS!$A$6:$BM$650,$D4,FALSE),"") -> SIN SINIESTRO | D4: =IFERROR(MATCH("SINIESTROS",BONOS!$A$6:$BM$6,0),"") -> 5 | E4: BONO DE SCORE | G4: =IFERROR(VLOOKUP(CONSULTA!$B$2,BONOS!$A$6:$BM$650,$H4,FALSE),"") -> OK | H4: =IFERROR(MATCH("BONO SCORE",BONOS!$A$6:$BM$6,0),"") -> 8
B5: QUEJAS | C5: =IFERROR(VLOOKUP(CONSULTA!$B$2,BONOS!$A$6:$BM$650,$D5,FALSE),"") -> SIN QUEJA | D5: =IFERROR(MATCH("QUEJAS",BONOS!$A$6:$BM$6,0),"") -> 6 | E5: PUNTUALIDAD | G5: =IFERROR(VLOOKUP(CONSULTA!$B$2,BONOS!$A$6:$BM$650,$H5,FALSE),"") -> OK | H5: =IFERROR(MATCH("PUNTUALIDAD",BONOS!$A$6:$BM$6,0),"") -> 9
B6: SCORE OBTENIDO | C6: =IFERROR(VLOOKUP(CONSULTA!$B$2,BONOS!$A$6:$BM$650,$D6,FALSE),"") -> 91 | D6: =IFERROR(MATCH("SCORE OBTENIDO",BONOS!$A$6:$BM$6,0),"") -> 7 | E6: BONO LOGUEO | G6: =IFERROR(VLOOKUP(CONSULTA!$B$2,BONOS!$A$6:$BM$650,$H6,FALSE),"") -> LOGUEO | H6: =IFERROR(MATCH("BONO LOGUEO",BONOS!$A$6:$BM$6,0),"") -> 10
B8: RENDIMEINTO META | C8: =IFERROR(VLOOKUP(CONSULTA!$B$2,RENDIMIENTO!$A$2:$BM$650,$D8,FALSE),"") -> 8.1038809 | D8: =IFERROR(MATCH("META",RENDIMIENTO!$A$2:$BM$2,0),"") -> 5 | E8: BONO 0 SINIESTROS | G8: =IFERROR(VLOOKUP(CONSULTA!$B$2,BONOS!$A$6:$BM$650,$H8,FALSE),"") -> 134.18 | H8: =IFERROR(MATCH("BONO SINIESTROS",BONOS!$A$6:$BM$6,0),"") -> 11
B9: REDIMIENTO OBTENIDO | C9: =IFERROR(VLOOKUP(CONSULTA!$B$2,RENDIMIENTO!$A$2:$BM$650,$D9,FALSE),"") -> 8.2357284 | D9: =IFERROR(MATCH("REDIMIENTO OBTENIDO ",RENDIMIENTO!$A$2:$BM$2,0),"") -> 6 | E9: BONO 0 QUEJAS | G9: =IFERROR(VLOOKUP(CONSULTA!$B$2,BONOS!$A$6:$BM$650,$H9,FALSE),"") -> 134.18 | H9: =IFERROR(MATCH("BONO QUEJAS",BONOS!$A$6:$BM$6,0),"") -> 12
B10: SEMANA 33 | E10: BONO SCORE | G10: =IFERROR(VLOOKUP(CONSULTA!$B$2,BONOS!$A$6:$BM$650,$H10,FALSE),"") -> 200 | H10: =IFERROR(MATCH("BONO SCORE1",BONOS!$A$6:$BM$6,0),"") -> 14
E11: BONO LOGUEO | G11: =IFERROR(VLOOKUP(CONSULTA!$B$2,BONOS!$A$6:$BM$650,$H11,FALSE),"") -> 177.44 | H11: =IFERROR(MATCH("BONO LOGUEO1",BONOS!$A$6:$BM$6,0),"") -> 15
E12: BONO RENDIMIENTO | G12: =IFERROR(VLOOKUP(CONSULTA!$B$2,RENDIMIENTO!$A$2:$BM$650,$H12,FALSE),"") -> 355.58 | H12: =IFERROR(MATCH("TOTAL A PAGAR ",RENDIMIENTO!$A$2:$BM$2,0),"") -> 7
E14: TOTAL BONO DESEMPEÑO | G14: =IFERROR(VLOOKUP(CONSULTA!$B$2,BONOS!$A$6:$BM$650,$H14,FALSE),"") -> 645.8 | H14: =IFERROR(MATCH("TOTAL B.DESEMPEÑO ",BONOS!$A$6:$BM$6,0),"") -> 19
E15: TOTAL BONO RENDIMIENTO | G15: =G12 -> 355.58
B17: Este documento es de carácter informativo. Su contenido carece de valor oficial, por lo que de requerir su “recibo de nómina”, favor de solicitarlo en oficinas de Transportes LIPU.
