Workbook

Sheet PUNTUALIDAD
A1: id | B1: id_servicio | C1: business_unit | D1: des | E1: Tipo de Viaje | F1: ID Ruta | G1: desc_adicional | H1: car | I1: status | J1: shift | K1: group | L1: start_date | M1: start_time | N1: start_eta | O1: start_status | P1: end_date | Q1: end_time | R1: end_eta | S1: end_status | T1: record_quality | U1: km cotizado | V1: km promedio | W1: km_calc | X1: km_calc + vac | Y1: km_vac_inicial | Z1: km_vac_final | AA1: driver | AB1: worker_id | AC1: operador | AD1: no. de nomina | AE1: usuario | AF1: Fecha de creación (Tiempo de Servidor) | AG1: momento | AH1: Sem Via | AI1: Sol Viaje | AJ1: Diagnostico Viaje | AK1: $ Viaje | AL1: $ Viaje Fijo | AM1: Tipo de Facturación | AN1: Periodo de Facturación | AO1: Fecha de creación (Tiempo de Unidad de Negocios) | AP1: Aforo | AQ1: SALIDA | AR1: LLEGADA | AS1: Estatus Salida | AT1: Estatus Llegada | AU1: Estatus | AV1: Semana | AW1: Puntualidad | AX1: concat | AY1: supervisor2 | AZ1: gte | BA1: CONCAT2 | BB1: ID Ruta | BC1: Turno | BD1: Dashtrax
A2: 176541809 | B2: E-HER-T1-R0017 | C2: LIPU Guadalajara | D2: Arenales | E2: N | F2: 17 | H2: 15192 | I2: 6 | J2: IN | K2: HERSHEYS | L2: 46265 | M2: 0.19444444 | N2: 0.19791667 | O2: done | P2: 46265 | Q2: 0.25 | R2: 0.24675926 | S2: done | T2: 1 | U2: 37 | V2: 33.03 | W2: 34.41 | X2: - | Y2: - | Z2: - | AA2: ZUÑIGA CARRILLO CHRISTIAN ALEJ | AB2: 14122103 | AC2: ZUÑIGA CARRILLO CHRISTIAN ALEJ | AD2: 14122103 | AE2: SISTEMA | AF2: AUTOMÁTICO | AG2: AUTOMÁTICO | AH2: 36 | AI2: Ok | AJ2: Retrasado,A tiempo | AK2: 815 | AL2: N/A | AM2: Variable por Ruta | AN2: Sin asignar | AO2: AUTOMÁTICO | AP2: - | AQ2: 0.0034722222 | AR2: -0.0032407407 | AS2: Inicia tarde | AT2: Llega a Tiempo | AU2: Inicia tarde-Llega a Tiempo | AV2: 36 | AW2: No | AX2: ArenalesHERSHEYS | AY2: CARLOS C. | AZ2: Ilse M. | BA2: HERSHEYSArenales | BB2: E-HER-R0017 | BC2: T1 | BD2: Arenales-R0017-04:40
A3: 176536422 | B3: E-SAN-T1-R0317 | C3: LIPU Guadalajara | D3: Angel Leaño T1 | E3: N | F3: 317 | H3: 13900 | I3: 6 | J3: IN | K3: SANMINA GDL | L3: 46265 | M3: 0.20138889 | N3: 0.20555556 | O3: done | P3: 46265 | Q3: 0.26736111 | R3: 0.24967593 | S3: done | T3: 1 | U3: 47 | V3: 41.37 | W3: 43.66 | X3: - | Y3: - | Z3: - | AA3: PEREZ CORREA LUIS CARLOS | AB3: 14123635 | AC3: PEREZ CORREA LUIS CARLOS | AD3: 14123635 | AE3: SISTEMA | AF3: AUTOMÁTICO | AG3: AUTOMÁTICO | AH3: 36 | AI3: Ok | AJ3: Retrasado,A tiempo | AK3: 530.63 | AL3: N/A | AM3: Variable por Ruta | AN3: Sin asignar | AO3: AUTOMÁTICO | AP3: 24 | AQ3: 0.0041666667 | AR3: -0.017685185 | AS3: Inicia tarde | AT3: Llega a Tiempo | AU3: Inicia tarde-Llega a Tiempo | AV3: 36 | AW3: No | AX3: Angel Leaño T1SANMINA GDL | AY3: PABLO F. | AZ3: Felipe M. | BA3: SANMINA GDLAngel Leaño T1 | BB3: E-SAN-R0317 | BC3: T1 | BD3: Angel Leaño T1-R0317-04:50
A4: 176543622 | B4: E-MOL-T1-R0024 | C4: LIPU Guadalajara | D4: Tetlán | E4: N | F4: 24 | H4: 15786 | I4: 6 | J4: IN | K4: MOLEX | L4: 46265 | M4: 0.20138889 | N4: 0.20694444 | O4: done | P4: 46265 | Q4: 0.26041667 | R4: 0.25042824 | S4: done | T4: 1 | U4: 67 | V4: 59.86 | W4: 59.45 | X4: - | Y4: - | Z4: - | AA4: RUVALCABA CORTEZ NOE | AB4: 14118501 | AC4: RUVALCABA CORTEZ NOE | AD4: 14118501 | AE4: SISTEMA | AF4: AUTOMÁTICO | AG4: AUTOMÁTICO | AH4: 36 | AI4: Ok | AJ4: Retrasado,A tiempo | AK4: 0 | AL4: N/A | AM4: Variable por Ruta | AN4: Sin asignar | AO4: AUTOMÁTICO | AP4: - | AQ4: 0.0055555556 | AR4: -0.0099884259 | AS4: Inicia tarde | AT4: Llega a Tiempo | AU4: Inicia tarde-Llega a Tiempo | AV4: 36 | AW4: No | AX4: TetlánMOLEX | AY4: VICTOR C. | AZ4: Leopoldo V. | BA4: MOLEXTetlán | BB4: E-MOL-R0024 | BC4: T1 | BD4: Tetlán-R0024-04:50
A5: 176549835 | B5: E-SAN-T1-R0503 | C5: LIPU Guadalajara | D5: Tabachines T1 | E5: N | F5: 503 | H5: 13416 | I5: 6 | J5: IN | K5: SANMINA GDL | L5: 46265 | M5: 0.20138889 | N5: 0.24097222 | O5: done | P5: 46265 | Q5: 0.26736111 | R5: 0.30763889 | S5: done | T5: 1 | U5: 42 | V5: 35.33 | W5: 34.07 | X5: 56.23 | Y5: 16.91 | Z5: 5.25 | AA5: SANTANA ARAIZA SANTIAGO | AB5: 14106368 | AC5: SANTANA ARAIZA SANTIAGO | AD5: 14106368 | AE5: SISTEMA | AF5: AUTOMÁTICO | AG5: AUTOMÁTICO | AH5: 36 | AI5: Ok | AJ5: Retrasado | AK5: 0 | AL5: N/A | AM5: Variable por Ruta | AN5: Sin asignar | AO5: AUTOMÁTICO | AP5: - | AQ5: 0.039583333 | AR5: 0.040277778 | AS5: Inicia tarde | AT5: Llega tarde | AU5: Inicia tarde-Llega tarde | AV5: 36 | AW5: No | AX5: Tabachines T1SANMINA GDL | AY5: PABLO F. | AZ5: Felipe M. | BA5: SANMINA GDLTabachines T1 | BB5: E-SAN-R0503 | BC5: T1 | BD5: Tabachines T1-R0503-04:50
A6: 176531117 | B6: E-SAN-T1-R0061 | C6: LIPU Guadalajara | D6: Bethel | E6: N | F6: 61 | H6: 16744 | I6: 6 | J6: IN | K6: SANMINA GDL | L6: 46265 | M6: 0.20833333 | N6: 0.21319444 | O6: done | P6: 46265 | Q6: 0.26736111 | R6: 0.25465278 | S6: done | T6: 1 | U6: 46 | V6: 42.96 | W6: 40.45 | X6: - | Y6: - | Z6: - | AA6: CASTAÑEDA AGUILAR LUIS ANTONIO | AB6: 14119956 | AC6: CASTAÑEDA AGUILAR LUIS ANTONIO | AD6: 14119956 | AE6: SISTEMA | AF6: AUTOMÁTICO | AG6: AUTOMÁTICO | AH6: 36 | AI6: Ok | AJ6: Retrasado,A tiempo | AK6: 530.63 | AL6: N/A | AM6: Variable por Ruta | AN6: Sin asignar | AO6: AUTOMÁTICO | AP6: - | AQ6: 0.0048611111 | AR6: -0.012708333 | AS6: Inicia tarde | AT6: Llega a Tiempo | AU6: Inicia tarde-Llega a Tiempo | AV6: 36 | AW6: No | AX6: BethelSANMINA GDL | AY6: PABLO F. | AZ6: Felipe M. | BA6: SANMINA GDLBethel | BB6: E-SAN-R0061 | BC6: T1 | BD6: Bethel-R0061-05:00
A7: 176538845 | B7: E-SM4-T1-R0108 | C7: LIPU Guadalajara | D7: San Sebastian 1 Turno 1 | E7: N | F7: 108 | H7: 5672 | I7: 6 | J7: IN | K7: SANMINA TLAJOMULCO | L7: 46265 | M7: 0.20833333 | N7: 0.21180556 | O7: done | P7: 46265 | Q7: 0.26736111 | R7: 0.25574074 | S7: done | T7: 1 | U7: 42 | V7: 27.41 | W7: 28.63 | X7: - | Y7: - | Z7: - | AA7: GARCIA RAMIREZ EZEQUIEL | AB7: 14124002 | AC7: GARCIA RAMIREZ EZEQUIEL | AD7: 14124002 | AE7: SISTEMA | AF7: AUTOMÁTICO | AG7: AUTOMÁTICO | AH7: 36 | AI7: Ok | AJ7: Retrasado,A tiempo | AK7: 0 | AL7: N/A | AM7: Variable por Ruta | AN7: Sin asignar | AO7: AUTOMÁTICO | AP7: 36 | AQ7: 0.0034722222 | AR7: -0.01162037 | AS7: Inicia tarde | AT7: Llega a Tiempo | AU7: Inicia tarde-Llega a Tiempo | AV7: 36 | AW7: No | AX7: San Sebastian 1 Turno 1SANMINA TLAJOMULCO | AY7: CUAUHTEMOC M. | AZ7: Felipe M. | BA7: SANMINA TLAJOMULCOSan Sebastian 1 Turno 1 | BB7: E-SM4-R0108 | BC7: T1 | BD7: San Sebastian 1 Turno 1-R0108-05:00
A8: 176545517 | B8: E-SM4-T1-R0204 | C8: LIPU Guadalajara | D8: San Sebastian 2 | E8: N | F8: 204 | H8: 7915 | I8: 6 | J8: IN | K8: SANMINA TLAJOMULCO | L8: 46265 | M8: 0.20833333 | N8: 0.21458333 | O8: done | P8: 46265 | Q8: 0.26736111 | R8: 0.24138889 | S8: done | T8: 1 | U8: 37 | V8: 32.02 | W8: 28.59 | X8: - | Y8: - | Z8: - | AA8: TORRES SANCHEZ JOSE MARTIN | AB8: 14123894 | AC8: TORRES SANCHEZ JOSE MARTIN | AD8: 14123894 | AE8: SISTEMA | AF8: AUTOMÁTICO | AG8: AUTOMÁTICO | AH8: 36 | AI8: Ok | AJ8: Retrasado,A tiempo | AK8: 0 | AL8: N/A | AM8: Variable por Ruta | AN8: Sin asignar | AO8: AUTOMÁTICO | AP8: - | AQ8: 0.00625 | AR8: -0.025972222 | AS8: Inicia tarde | AT8: Llega a Tiempo | AU8: Inicia tarde-Llega a Tiempo | AV8: 36 | AW8: No | AX8: San Sebastian 2SANMINA TLAJOMULCO | AY8: CUAUHTEMOC M. | AZ8: Felipe M. | BA8: SANMINA TLAJOMULCOSan Sebastian 2 | BB8: E-SM4-R0204 | BC8: T1 | BD8: San Sebastian 2-R0204-05:00
A9: 176551668 | B9: E-BIM-T1-R0009 | C9: LIPU Guadalajara | D9: Oblatos | E9: N | F9: 9 | H9: 4533 | I9: 6 | J9: IN | K9: BIMBO | L9: 46265 | M9: 0.20833333 | N9: 0.21319444 | O9: done | P9: 46265 | Q9: 0.23958333 | R9: 0.23645833 | S9: done | T9: 1 | U9: 21 | V9: 18.63 | W9: 18.69 | X9: - | Y9: - | Z9: - | AA9: REOS GONZALEZ ROBERTO | AB9: 14123572 | AC9: REOS GONZALEZ ROBERTO | AD9: 14123572 | AE9: SISTEMA | AF9: AUTOMÁTICO | AG9: AUTOMÁTICO | AH9: 36 | AI9: Ok | AJ9: Retrasado,A tiempo | AK9: - | AL9: N/A | AM9: Sin asignar | AN9: Sin asignar | AO9: AUTOMÁTICO | AP9: - | AQ9: 0.0048611111 | AR9: -0.003125 | AS9: Inicia tarde | AT9: Llega a Tiempo | AU9: Inicia tarde-Llega a Tiempo | AV9: 36 | AW9: No | AX9: OblatosBIMBO | AY9: DANIEL | AZ9: Leopoldo V. | BA9: BIMBOOblatos | BB9: #N/A | BC9: T1 | BD9: Oblatos-R0009-05:00
A10: 176548304 | B10: E-PIS-T1-R0051 | C10: LIPU Guadalajara | D10: El Refugio | E10: N | F10: 51 | H10: 4431 | I10: 6 | J10: IN | K10: PIS-PISA | L10: 46265 | M10: 0.21041667 | N10: 0.21458333 | O10: done | P10: 46265 | Q10: 0.26736111 | R10: 0.2569213 | S10: done | T10: 1 | U10: 41 | V10: 36.56 | W10: 35.66 | X10: - | Y10: - | Z10: - | AA10: LARIOS SANCHEZ HECTOR ALEXANDE | AB10: 14102875 | AC10: LARIOS SANCHEZ HECTOR ALEXANDE | AD10: 14102875 | AE10: SISTEMA | AF10: AUTOMÁTICO | AG10: AUTOMÁTICO | AH10: 36 | AI10: Ok | AJ10: Retrasado,A tiempo | AK10: 0 | AL10: N/A | AM10: Variable por Ruta | AN10: Sin asignar | AO10: AUTOMÁTICO | AP10: - | AQ10: 0.0041666667 | AR10: -0.010439815 | AS10: Inicia tarde | AT10: Llega a Tiempo | AU10: Inicia tarde-Llega a Tiempo | AV10: 36 | AW10: No | AX10: El RefugioPIS-PISA | AY10: DAVID C. | AZ10: Felipe M. | BA10: PIS-PISAEl Refugio | BB10: E-PIS-R0051 | BC10: T1 | BD10: El Refugio-R0051-05:03
A11: 176540220 | B11: E-CUP-T1-R0012 | C11: LIPU Guadalajara | D11: Huertas | E11: N | F11: 12 | H11: 9700 | I11: 6 | J11: IN | K11: CUPRUM GDL | L11: 46265 | M11: 0.2125 | N11: 0.21597222 | O11: done | P11: 46265 | Q11: 0.24652778 | R11: 0.23888889 | S11: done | T11: 1 | U11: 18 | V11: 13.62 | W11: 14.08 | X11: 26.52 | Y11: 12.08 | Z11: 0.36 | AA11: RAMIREZ GONZALEZ CYNTHIA PATRICIA | AB11: 14123107 | AC11: RAMIREZ GONZALEZ CYNTHIA PATRICIA | AD11: 14123107 | AE11: SISTEMA | AF11: AUTOMÁTICO | AG11: AUTOMÁTICO | AH11: 36 | AI11: Ok | AJ11: Retrasado,A tiempo | AK11: 408.1 | AL11: N/A | AM11: Variable por Ruta | AN11: Sin asignar | AO11: AUTOMÁTICO | AP11: - | AQ11: 0.0034722222 | AR11: -0.0076388889 | AS11: Inicia tarde | AT11: Llega a Tiempo | AU11: Inicia tarde-Llega a Tiempo | AV11: 36 | AW11: No | AX11: HuertasCUPRUM GDL | AY11: DAVID M | AZ11: Ilse M. | BA11: CUPRUM GDLHuertas | BB11: E-CUP-R0012 | BC11: T1 | BD11: Huertas-R0012-05:06
A12: 176538871 | B12: E-SM4-T1-R0119 | C12: LIPU Guadalajara | D12: Tlajomulco 1 | E12: N | F12: 119 | H12: 5771 | I12: 6 | J12: IN | K12: SANMINA TLAJOMULCO | L12: 46265 | M12: 0.21527778 | N12: 0.22083333 | O12: done | P12: 46265 | Q12: 0.26736111 | R12: 0.25721065 | S12: done | T12: 1 | U12: 38 | V12: 35.15 | W12: 33.93 | X12: - | Y12: - | Z12: - | AA12: HERNANDEZ FLORES OSCAR | AB12: 14116853 | AC12: HERNANDEZ FLORES OSCAR | AD12: 14116853 | AE12: SISTEMA | AF12: AUTOMÁTICO | AG12: AUTOMÁTICO | AH12: 36 | AI12: Ok | AJ12: Retrasado,A tiempo | AK12: 0 | AL12: N/A | AM12: Variable por Ruta | AN12: Sin asignar | AO12: AUTOMÁTICO | AP12: - | AQ12: 0.0055555556 | AR12: -0.010150463 | AS12: Inicia tarde | AT12: Llega a Tiempo | AU12: Inicia tarde-Llega a Tiempo | AV12: 36 | AW12: No | AX12: Tlajomulco 1SANMINA TLAJOMULCO | AY12: CUAUHTEMOC M. | AZ12: Felipe M. | BA12: SANMINA TLAJOMULCOTlajomulco 1 | BB12: E-SM4-R0119 | BC12: T1 | BD12: Tlajomulco 1-R0119-05:10
A13: 176551758 | B13: E-BIM-T1-R0012 | C13: LIPU Guadalajara | D13: Adolf Horn | E13: N | F13: 12 | H13: 7345 | I13: 6 | J13: IN | K13: BIMBO | L13: 46265 | M13: 0.21527778 | N13: 0.22430556 | O13: done | P13: 46265 | Q13: 0.23958333 | R13: 0.23768519 | S13: done | T13: 1 | U13: 17 | V13: 14.46 | W13: 14 | X13: - | Y13: - | Z13: - | AA13: PELAYO PELAYO JOSE MARIA | AB13: 14117542 | AC13: PELAYO PELAYO JOSE MARIA | AD13: 14117542 | AE13: SISTEMA | AF13: AUTOMÁTICO | AG13: AUTOMÁTICO | AH13: 36 | AI13: Ok | AJ13: Retrasado,A tiempo | AK13: - | AL13: N/A | AM13: Sin asignar | AN13: Sin asignar | AO13: AUTOMÁTICO | AP13: - | AQ13: 0.0090277778 | AR13: -0.0018981481 | AS13: Inicia tarde | AT13: Llega a Tiempo | AU13: Inicia tarde-Llega a Tiempo | AV13: 36 | AW13: No | AX13: Adolf HornBIMBO | AY13: DANIEL | AZ13: Leopoldo V. | BA13: BIMBOAdolf Horn | BB13: #N/A | BC13: T1 | BD13: Adolf Horn-R0012-05:10
A14: 176538767 | B14: E-SM4-T1-R0080 | C14: LIPU Guadalajara | D14: Villas Santa Cruz | E14: N | F14: 80 | H14: 13375 | I14: 6 | J14: IN | K14: SANMINA TLAJOMULCO | L14: 46265 | M14: 0.21875 | N14: 0.23263889 | O14: done | P14: 46265 | Q14: 0.26736111 | R14: 0.25234954 | S14: done | T14: 1 | U14: 36 | V14: 22.36 | W14: 12.93 | X14: - | Y14: - | Z14: - | AA14: VALLE SANCHEZ RAFAEL | AB14: 14117509 | AC14: VALLE SANCHEZ RAFAEL | AD14: 14117509 | AE14: SISTEMA | AF14: AUTOMÁTICO | AG14: AUTOMÁTICO | AH14: 36 | AI14: Ok | AJ14: Retrasado,A tiempo | AK14: 0 | AL14: N/A | AM14: Variable por Ruta | AN14: Sin asignar | AO14: AUTOMÁTICO | AP14: - | AQ14: 0.013888889 | AR14: -0.015011574 | AS14: Inicia tarde | AT14: Llega a Tiempo | AU14: Inicia tarde-Llega a Tiempo | AV14: 36 | AW14: No | AX14: Villas Santa CruzSANMINA TLAJOMULCO | AY14: CUAUHTEMOC M. | AZ14: Felipe M. | BA14: SANMINA TLAJOMULCOVillas Santa Cruz | BB14: E-SM4-R0080 | BC14: T1 | BD14: Villas Santa Cruz-R0080-05:15
A15: 176538838 | B15: E-SM4-T1-R0105 | C15: LIPU Guadalajara | D15: Prepa 13 T1 | E15: N | F15: 105 | H15: 15993 | I15: 6 | J15: IN | K15: SANMINA TLAJOMULCO | L15: 46265 | M15: 0.21875 | N15: 0.22291667 | O15: done | P15: 46265 | Q15: 0.26736111 | R15: 0.260625 | S15: done | T15: 1 | U15: 38 | V15: 32.09 | W15: 34.45 | X15: - | Y15: - | Z15: - | AA15: CHAVEZ PALOMARES MARIANO | AB15: 14123925 | AC15: CHAVEZ PALOMARES MARIANO | AD15: 14123925 | AE15: SISTEMA | AF15: AUTOMÁTICO | AG15: AUTOMÁTICO | AH15: 36 | AI15: Ok | AJ15: Retrasado,A tiempo | AK15: 0 | AL15: N/A | AM15: Variable por Ruta | AN15: Sin asignar | AO15: AUTOMÁTICO | AP15: - | AQ15: 0.0041666667 | AR15: -0.0067361111 | AS15: Inicia tarde | AT15: Llega a Tiempo | AU15: Inicia tarde-Llega a Tiempo | AV15: 36 | AW15: No | AX15: Prepa 13 T1SANMINA TLAJOMULCO | AY15: CUAUHTEMOC M. | AZ15: Felipe M. | BA15: SANMINA TLAJOMULCOPrepa 13 T1 | BB15: E-SM4-R0105 | BC15: T1 | BD15: Prepa 13 T1-R0105-05:15
A16: 176548507 | B16: E-SM4-T1-R0227 | C16: LIPU Guadalajara | D16: Lomas del Sur | E16: N | F16: 227 | H16: 4980 | I16: 6 | J16: IN | K16: SANMINA TLAJOMULCO | L16: 46265 | M16: 0.21875 | N16: 0.22430556 | O16: done | P16: 46265 | Q16: 0.26736111 | R16: 0.25645833 | S16: done | T16: 1 | U16: 30 | V16: 24.54 | W16: 23.76 | X16: - | Y16: - | Z16: - | AA16: LOPEZ GODINEZ MIGUEL DE JESUS | AB16: 14119154 | AC16: LOPEZ GODINEZ MIGUEL DE JESUS | AD16: 14119154 | AE16: SISTEMA | AF16: AUTOMÁTICO | AG16: AUTOMÁTICO | AH16: 36 | AI16: Ok | AJ16: Retrasado,A tiempo | AK16: 0 | AL16: N/A | AM16: Variable por Ruta | AN16: Sin asignar | AO16: AUTOMÁTICO | AP16: - | AQ16: 0.0055555556 | AR16: -0.010902778 | AS16: Inicia tarde | AT16: Llega a Tiempo | AU16: Inicia tarde-Llega a Tiempo | AV16: 36 | AW16: No | AX16: Lomas del SurSANMINA TLAJOMULCO | AY16: CUAUHTEMOC M. | AZ16: Felipe M. | BA16: SANMINA TLAJOMULCOLomas del Sur | BB16: E-SM4-R0227 | BC16: T1 | BD16: Lomas del Sur-R0227-05:15
A17: 176538621 | B17: E-SK1-T1-R0033 | C17: LIPU Guadalajara | D17: Polanco T1 | E17: N | F17: 33 | H17: 16734 | I17: 6 | J17: IN | K17: SANMINA KAMPUS 16 | L17: 46265 | M17: 0.22222222 | N17: 0.2375 | O17: done | P17: 46265 | Q17: 0.26736111 | R17: 0.27815972 | S17: done | T17: 1 | U17: 26 | V17: 22.25 | W17: 23.85 | X17: - | Y17: - | Z17: - | AA17: VAZQUEZ FLORES FABIAN | AB17: 14107967 | AC17: VAZQUEZ FLORES FABIAN | AD17: 14107967 | AE17: SISTEMA | AF17: AUTOMÁTICO | AG17: AUTOMÁTICO | AH17: 36 | AI17: Ok | AJ17: Retrasado | AK17: 0 | AL17: N/A | AM17: Variable por Ruta | AN17: Sin asignar | AO17: AUTOMÁTICO | AP17: - | AQ17: 0.015277778 | AR17: 0.010798611 | AS17: Inicia tarde | AT17: Llega tarde | AU17: Inicia tarde-Llega tarde | AV17: 36 | AW17: No | AX17: Polanco T1SANMINA KAMPUS 16 | AY17: BRIAN A. | AZ17: Felipe M. | BA17: SANMINA KAMPUS 16Polanco T1 | BB17: E-SK1-R0033 | BC17: T1 | BD17: Polanco T1-R0033-05:20
A18: 176545733 | B18: E-FOX-T1-R0077 | C18: LIPU Guadalajara | D18: Tonala 1 | E18: N | F18: 77 | G18: NORTE | H18: 5527 | I18: 6 | J18: IN | K18: FOXCONN | L18: 46265 | M18: 0.22222222 | N18: 0.22569444 | O18: done | P18: 46265 | Q18: 0.28125 | R18: 0.25989583 | S18: done | T18: 1 | U18: 27 | V18: 23.23 | W18: 22.66 | X18: - | Y18: - | Z18: - | AA18: MONCADA CALDERON FRANCISCO | AB18: 14123254 | AC18: MONCADA CALDERON FRANCISCO | AD18: 14123254 | AE18: SISTEMA | AF18: AUTOMÁTICO | AG18: AUTOMÁTICO | AH18: 36 | AI18: Ok | AJ18: Retrasado,A tiempo | AK18: 0 | AL18: N/A | AM18: Variable por Ruta | AN18: Sin asignar | AO18: AUTOMÁTICO | AP18: - | AQ18: 0.0034722222 | AR18: -0.021354167 | AS18: Inicia tarde | AT18: Llega a Tiempo | AU18: Inicia tarde-Llega a Tiempo | AV18: 36 | AW18: No | AX18: Tonala 1FOXCONN | AY18: CANDELAS | AZ18: Leopoldo V. | BA18: FOXCONNTonala 1 | BB18: E-FOX-R0077 | BC18: T1 | BD18: Tonala 1-R0077-05:20
A19: 176546909 | B19: E-SM3-T1-R0221 | C19: LIPU Guadalajara | D19: El Mirador | E19: N | F19: 221 | H19: 5423 | I19: 6 | J19: IN | K19: SANMINA FORANE | L19: 46265 | M19: 0.22222222 | N19: 0.22708333 | O19: done | P19: 46265 | Q19: 0.26736111 | R19: 0.26046296 | S19: done | T19: 1 | U19: 12 | V19: 17.67 | W19: 17.91 | X19: - | Y19: - | Z19: - | AA19: LUEVANO LOPEZ JUAN EZEQUIEL | AB19: 14123926 | AC19: LUEVANO LOPEZ JUAN EZEQUIEL | AD19: 14123926 | AE19: SISTEMA | AF19: AUTOMÁTICO | AG19: AUTOMÁTICO | AH19: 36 | AI19: Ok | AJ19: Retrasado,A tiempo | AK19: 0 | AL19: N/A | AM19: Variable por Ruta | AN19: Sin asignar | AO19: AUTOMÁTICO | AP19: 49 | AQ19: 0.0048611111 | AR19: -0.0068981481 | AS19: Inicia tarde | AT19: Llega a Tiempo | AU19: Inicia tarde-Llega a Tiempo | AV19: 36 | AW19: No | AX19: El MiradorSANMINA FORANE | AY19: HEROS M. | AZ19: Felipe M. | BA19: SANMINA FORANEEl Mirador | BB19: E-SM3-R0221 | BC19: T1 | BD19: El Mirador-R0221-05:20
A20: 176549079 | B20: E-MAS-T1-R0007 | C20: LIPU Guadalajara | D20: Chulavista | E20: N | F20: 7 | H20: 4984 | I20: 6 | J20: IN | K20: MASECA GDL | L20: 46265 | M20: 0.22222222 | N20: 0.22638889 | O20: done | P20: 46265 | Q20: 0.26041667 | R20: 0.26502315 | S20: done | T20: 1 | U20: 21 | V20: 17.4 | W20: 17.69 | X20: - | Y20: - | Z20: - | AA20: AVILAN RIVERA MIGUEL UBALDO | AB20: 14123652 | AC20: AVILAN RIVERA MIGUEL UBALDO | AD20: 14123652 | AE20: SISTEMA | AF20: AUTOMÁTICO | AG20: AUTOMÁTICO | AH20: 36 | AI20: Ok | AJ20: Retrasado | AK20: 0 | AL20: N/A | AM20: Variable por Ruta | AN20: Sin asignar | AO20: AUTOMÁTICO | AP20: - | AQ20: 0.0041666667 | AR20: 0.0046064815 | AS20: Inicia tarde | AT20: Llega tarde | AU20: Inicia tarde-Llega tarde | AV20: 36 | AW20: No | AX20: ChulavistaMASECA GDL | AY20: DAVID M | AZ20: Ilse M. | BA20: MASECA GDLChulavista | BB20: E-MAS-R0007 | BC20: T1 | BD20: Chulavista-R0007-05:20
A21: 176541791 | B21: E-HER-T1-R0011 | C21: LIPU Guadalajara | D21: El Salto Azucena | E21: N | F21: 11 | H21: 15185 | I21: 6 | J21: IN | K21: HERSHEYS | L21: 46265 | M21: 0.22638889 | N21: 0.23194444 | O21: done | P21: 46265 | Q21: 0.25 | R21: 0.24733796 | S21: done | T21: 1 | U21: 14 | V21: 9.91 | W21: 8.43 | X21: - | Y21: - | Z21: - | AA21: RODRIGUEZ MARTINEZ OMAR ROGELIO | AB21: 14122925 | AC21: RODRIGUEZ MARTINEZ OMAR ROGELIO | AD21: 14122925 | AE21: SISTEMA | AF21: AUTOMÁTICO | AG21: AUTOMÁTICO | AH21: 36 | AI21: Ok | AJ21: Retrasado,A tiempo | AK21: 730 | AL21: N/A | AM21: Variable por Ruta | AN21: Sin asignar | AO21: AUTOMÁTICO | AP21: - | AQ21: 0.0055555556 | AR21: -0.002662037 | AS21: Inicia tarde | AT21: Llega a Tiempo | AU21: Inicia tarde-Llega a Tiempo | AV21: 36 | AW21: No | AX21: El Salto AzucenaHERSHEYS | AY21: CARLOS C. | AZ21: Ilse M. | BA21: HERSHEYSEl Salto Azucena | BB21: E-HER-R0011 | BC21: T1 | BD21: El Salto Azucena-R0011-05:26
A22: 176530495 | B22: E-PEP-T1-R0009 | C22: LIPU Guadalajara | D22: Moctezuma San Agustin | E22: N | F22: 9 | H22: 5923 | I22: 6 | J22: IN | K22: PEPSICO GDL | L22: 46265 | M22: 0.22916667 | N22: 0.23333333 | O22: done | P22: 46265 | Q22: 0.27083333 | R22: 0.26597222 | S22: done | T22: 1 | U22: 22 | V22: 12.46 | W22: 20.08 | X22: 39.91 | Y22: 17.01 | Z22: 2.82 | AA22: HERNANDEZ GALLEGOS HECTOR ABRA | AB22: 14122133 | AC22: HERNANDEZ GALLEGOS HECTOR ABRA | AD22: 14122133 | AE22: SISTEMA | AF22: AUTOMÁTICO | AG22: AUTOMÁTICO | AH22: 36 | AI22: Ok | AJ22: Retrasado,A tiempo | AK22: 544.9 | AL22: N/A | AM22: Variable por Ruta | AN22: Sin asignar | AO22: AUTOMÁTICO | AP22: - | AQ22: 0.0041666667 | AR22: -0.0048611111 | AS22: Inicia tarde | AT22: Llega a Tiempo | AU22: Inicia tarde-Llega a Tiempo | AV22: 36 | AW22: No | AX22: Moctezuma San AgustinPEPSICO GDL | AY22: DANIEL | AZ22: Leopoldo V. | BA22: PEPSICO GDLMoctezuma San Agustin | BB22: E-PEP-R0009 | BC22: T1 | BD22: Moctezuma San Agustin-R0009-05:30
A23: 176543738 | B23: E-FOX-T1-R0050 | C23: LIPU Guadalajara | D23: Villas Terranova | E23: N | F23: 50 | G23: SUR | H23: 12898 | I23: 6 | J23: IN | K23: FOXCONN | L23: 46265 | M23: 0.22916667 | N23: 0.23263889 | O23: done | P23: 46265 | Q23: 0.28125 | R23: 0.26857639 | S23: done | T23: 1 | U23: 25 | V23: 27.27 | W23: 26.78 | X23: - | Y23: - | Z23: - | AA23: DURAN DIAZ MARIO ALBERTO | AB23: 14124143 | AC23: DURAN DIAZ MARIO ALBERTO | AD23: 14124143 | AE23: SISTEMA | AF23: AUTOMÁTICO | AG23: AUTOMÁTICO | AH23: 36 | AI23: Ok | AJ23: Retrasado,A tiempo | AK23: 0 | AL23: N/A | AM23: Variable por Ruta | AN23: Sin asignar | AO23: AUTOMÁTICO | AP23: - | AQ23: 0.0034722222 | AR23: -0.012673611 | AS23: Inicia tarde | AT23: Llega a Tiempo | AU23: Inicia tarde-Llega a Tiempo | AV23: 36 | AW23: No | AX23: Villas TerranovaFOXCONN | AY23: DIEGOVO. | AZ23: Leopoldo V. | BA23: FOXCONNVillas Terranova | BB23: E-FOX-R0050 | BC23: T1 | BD23: Villas Terranova-R0050-05:30
A24: 176547616 | B24: E-FOX-T1-R0098 | C24: LIPU Guadalajara | D24: El Colli | E24: N | F24: 98 | G24: NORTE | H24: 14692 | I24: 6 | J24: IN | K24: FOXCONN | L24: 46265 | M24: 0.22916667 | N24: 0.23611111 | O24: done | P24: 46265 | Q24: 0.28125 | R24: 0.27304398 | S24: done | T24: 1 | U24: 31 | V24: 26.76 | W24: 26.7 | X24: - | Y24: - | Z24: - | AA24: REA PINEDO SALVADOR MANUEL | AB24: 14123725 | AC24: REA PINEDO SALVADOR MANUEL | AD24: 14123725 | AE24: SISTEMA | AF24: AUTOMÁTICO | AG24: AUTOMÁTICO | AH24: 36 | AI24: Ok | AJ24: Retrasado,A tiempo | AK24: 0 | AL24: N/A | AM24: Variable por Ruta | AN24: Sin asignar | AO24: AUTOMÁTICO | AP24: 40 | AQ24: 0.0069444444 | AR24: -0.0082060185 | AS24: Inicia tarde | AT24: Llega a Tiempo | AU24: Inicia tarde-Llega a Tiempo | AV24: 36 | AW24: No | AX24: El ColliFOXCONN | AY24: CANDELAS | AZ24: Leopoldo V. | BA24: FOXCONNEl Colli | BB24: E-FOX-R0098 | BC24: T1 | BD24: El Colli-R0098-05:30
A25: 176549218 | B25: E-SM4-T1-R0237 | C25: LIPU Guadalajara | D25: Apoyo Adolf Horn T1 | E25: N | F25: 237 | H25: 5530 | I25: 6 | J25: IN | K25: SANMINA TLAJOMULCO | L25: 46265 | M25: 0.22916667 | N25: 0.23888889 | O25: done | P25: 46265 | Q25: 0.26736111 | R25: 0.26252315 | S25: done | T25: 1 | U25: 19 | V25: 17.27 | W25: 17.42 | X25: - | Y25: - | Z25: - | AA25: RODRIGUEZ LOPEZ ANGEL ALBERTO | AB25: 14120925 | AC25: RODRIGUEZ LOPEZ ANGEL ALBERTO | AD25: 14120925 | AE25: SISTEMA | AF25: AUTOMÁTICO | AG25: AUTOMÁTICO | AH25: 36 | AI25: Ok | AJ25: Retrasado,A tiempo | AK25: 0 | AL25: N/A | AM25: Variable por Ruta | AN25: Sin asignar | AO25: AUTOMÁTICO | AP25: - | AQ25: 0.0097222222 | AR25: -0.004837963 | AS25: Inicia tarde | AT25: Llega a Tiempo | AU25: Inicia tarde-Llega a Tiempo | AV25: 36 | AW25: No | AX25: Apoyo Adolf Horn T1SANMINA TLAJOMULCO | AY25: CUAUHTEMOC M. | AZ25: Felipe M. | BA25: SANMINA TLAJOMULCOApoyo Adolf Horn T1 | BB25: E-SM4-R0237 | BC25: T1 | BD25: Apoyo Adolf Horn T1-R0237-05:30
A26: 176545723 | B26: E-FOX-T1-R0073 | C26: LIPU Guadalajara | D26: Valle De Tejeda | E26: N | F26: 73 | G26: SUR | H26: 2528 | I26: 6 | J26: IN | K26: FOXCONN | L26: 46265 | M26: 0.23263889 | N26: 0.26111111 | O26: done | P26: 46265 | Q26: 0.28125 | R26: 0.32222222 | S26: done | T26: 1 | U26: 29 | V26: 22.09 | W26: 5.24 | X26: - | Y26: - | Z26: - | AA26: MENDOZA CARDONA JOSE ALEJANDRO | AB26: 14123634 | AC26: MENDOZA CARDONA JOSE ALEJANDRO | AD26: 14123634 | AE26: SISTEMA | AF26: AUTOMÁTICO | AG26: AUTOMÁTICO | AH26: 36 | AI26: Ok | AJ26: Retrasado | AK26: 0 | AL26: N/A | AM26: Variable por Ruta | AN26: Sin asignar | AO26: AUTOMÁTICO | AP26: - | AQ26: 0.028472222 | AR26: 0.040972222 | AS26: Inicia tarde | AT26: Llega tarde | AU26: Inicia tarde-Llega tarde | AV26: 36 | AW26: No | AX26: Valle De TejedaFOXCONN | AY26: CANDELAS | AZ26: Leopoldo V. | BA26: FOXCONNValle De Tejeda | BB26: E-FOX-R0073 | BC26: T1 | BD26: Valle De Tejeda-R0073-05:35
A27: 176538978 | B27: E-DJT-T1-R0001 | C27: LIPU Guadalajara | D27: Puga | E27: N | F27: 1 | H27: 7943 | I27: 6 | J27: IN | K27: DON JULIO TEPIC | L27: 46265 | M27: 0.23611111 | N27: 0.30486111 | O27: done | P27: 46265 | Q27: 0.33333333 | R27: 0.31736111 | S27: done | T27: 1 | U27: 29 | V27: 3.05 | W27: 1.75 | X27: 32.78 | Y27: 18.16 | Z27: 12.87 | AA27: VILLEGAS HUIZAR RAMIRO | AB27: 14122708 | AC27: VILLEGAS HUIZAR RAMIRO | AD27: 14122708 | AE27: SISTEMA | AF27: AUTOMÁTICO | AG27: AUTOMÁTICO | AH27: 36 | AI27: Ok | AJ27: Retrasado,A tiempo | AK27: - | AL27: 0 | AM27: Fijo más Variable por KM | AN27: Sin asignar | AO27: AUTOMÁTICO | AP27: - | AQ27: 0.06875 | AR27: -0.015972222 | AS27: Inicia tarde | AT27: Llega a Tiempo | AU27: Inicia tarde-Llega a Tiempo | AV27: 36 | AW27: No | AX27: PugaDON JULIO TEPIC | AY27: VIRIDIANA G | AZ27: Ilse M. | BA27: DON JULIO TEPIC Puga | BB27: E-DJT-R0001 | BC27: T1 | BD27: Puga-R0001-05:40
A28: 176544211 | B28: E-FOX-T1-R0069 | C28: LIPU Guadalajara | D28: Lomas del Mirador | E28: N | F28: 69 | G28: SUR | H28: 4982 | I28: 6 | J28: IN | K28: FOXCONN | L28: 46265 | M28: 0.23611111 | N28: 0.24097222 | O28: done | P28: 46265 | Q28: 0.28125 | R28: 0.28010417 | S28: done | T28: 1 | U28: 28 | V28: 22.72 | W28: 15.34 | X28: - | Y28: - | Z28: - | AA28: TORRES CAMPOS VICTOR MANUEL | AB28: 14111678 | AC28: TORRES CAMPOS VICTOR MANUEL | AD28: 14111678 | AE28: SISTEMA | AF28: AUTOMÁTICO | AG28: AUTOMÁTICO | AH28: 36 | AI28: Ok | AJ28: Retrasado,A tiempo | AK28: 0 | AL28: N/A | AM28: Variable por Ruta | AN28: Sin asignar | AO28: AUTOMÁTICO | AP28: - | AQ28: 0.0048611111 | AR28: -0.0011458333 | AS28: Inicia tarde | AT28: Llega a Tiempo | AU28: Inicia tarde-Llega a Tiempo | AV28: 36 | AW28: No | AX28: Lomas del MiradorFOXCONN | AY28: DIEGOVO. | AZ28: Leopoldo V. | BA28: FOXCONNLomas del Mirador | BB28: E-FOX-R0069 | BC28: T1 | BD28: Lomas del Mirador-R0069-05:40
A29: 176548851 | B29: E-FOX-T1-R0139 | C29: LIPU Guadalajara | D29: Apoyo Chulavista | E29: N | F29: 139 | G29: SUR | H29: 10359 | I29: 6 | J29: IN | K29: FOXCONN | L29: 46265 | M29: 0.23611111 | N29: 0.24166667 | O29: done | P29: 46265 | Q29: 0.28125 | R29: 0.26740741 | S29: done | T29: 1 | U29: 23 | V29: 23.47 | W29: 26.22 | X29: - | Y29: - | Z29: - | AA29: AGRIPINO ROBLES MARIO ALFONS | AB29: 14112026 | AC29: AGRIPINO ROBLES MARIO ALFONS | AD29: 14112026 | AE29: SISTEMA | AF29: AUTOMÁTICO | AG29: AUTOMÁTICO | AH29: 36 | AI29: Ok | AJ29: Retrasado,A tiempo | AK29: 0 | AL29: N/A | AM29: Variable por Ruta | AN29: Sin asignar | AO29: AUTOMÁTICO | AP29: 25 | AQ29: 0.0055555556 | AR29: -0.013842593 | AS29: Inicia tarde | AT29: Llega a Tiempo | AU29: Inicia tarde-Llega a Tiempo | AV29: 36 | AW29: No | AX29: Apoyo ChulavistaFOXCONN | AY29: DIEGOVO. | AZ29: Leopoldo V. | BA29: FOXCONNApoyo Chulavista | BB29: E-FOX-R0139 | BC29: T1 | BD29: Apoyo Chulavista-R0139-05:40
A30: 176550710 | B30: E-FOX-T1-R0256 | C30: LIPU Guadalajara | D30: Apoyo Valle de la Misericordia | E30: N | F30: 256 | G30: SUR | H30: 5353 | I30: 6 | J30: IN | K30: FOXCONN | L30: 46265 | M30: 0.23611111 | N30: 0.25416667 | O30: done | P30: 46265 | Q30: 0.28125 | R30: 0.28346065 | S30: done | T30: 1 | U30: 16 | V30: 11.79 | W30: 10.79 | X30: - | Y30: - | Z30: - | AA30: ROLDAN RODRIGUEZ LUIS ANGEL | AB30: 14123988 | AC30: ROLDAN RODRIGUEZ LUIS ANGEL | AD30: 14123988 | AE30: SISTEMA | AF30: AUTOMÁTICO | AG30: AUTOMÁTICO | AH30: 36 | AI30: Ok | AJ30: Retrasado | AK30: 0 | AL30: N/A | AM30: Variable por Ruta | AN30: Sin asignar | AO30: AUTOMÁTICO | AP30: - | AQ30: 0.018055556 | AR30: 0.0022106481 | AS30: Inicia tarde | AT30: Llega a Tiempo | AU30: Inicia tarde-Llega a Tiempo | AV30: 36 | AW30: No | AX30: Apoyo Valle de la MisericordiaFOXCONN | AY30: DIEGOVO. | AZ30: Leopoldo V. | BA30: FOXCONNApoyo Valle de la Misericordia | BB30: E-FOX-R0256 | BC30: T1 | BD30: Apoyo Valle de la Misericordia-R0256-05:40
A31: 176552029 | B31: E-FOX-T1-R0269 | C31: LIPU Guadalajara | D31: Hacienda Real | E31: N | F31: 269 | G31: Norte | H31: 6782 | I31: 6 | J31: IN | K31: FOXCONN | L31: 46265 | M31: 0.23611111 | N31: 0.24444444 | O31: done | P31: 46265 | Q31: 0.28125 | R31: 0.28069444 | S31: done | T31: 1 | U31: 18 | V31: 13.57 | W31: 14.28 | X31: - | Y31: - | Z31: - | AA31: REA PINEDO JUAN JOSE | AB31: 14122160 | AC31: REA PINEDO JUAN JOSE | AD31: 14122160 | AE31: SISTEMA | AF31: AUTOMÁTICO | AG31: AUTOMÁTICO | AH31: 36 | AI31: Ok | AJ31: Retrasado,A tiempo | AK31: 0 | AL31: N/A | AM31: Variable por Ruta | AN31: Sin asignar | AO31: AUTOMÁTICO | AP31: - | AQ31: 0.0083333333 | AR31: -0.00055555556 | AS31: Inicia tarde | AT31: Llega a Tiempo | AU31: Inicia tarde-Llega a Tiempo | AV31: 36 | AW31: No | AX31: Hacienda RealFOXCONN | AY31: CANDELAS | AZ31: Leopoldo V. | BA31: FOXCONNHacienda Real | BB31: #N/A | BC31: T1 | BD31: Hacienda Real-R0269-05:40
A32: 176538533 | B32: E-PAQ-T1-R0009 | C32: LIPU Guadalajara | D32: 8 De Julio | E32: N | F32: 9 | H32: 10362 | I32: 6 | J32: IN | K32: PAQUETEXPRESS GDL | L32: 46265 | M32: 0.24305556 | N32: 0.24652778 | O32: done | P32: 46265 | Q32: 0.29166667 | R32: 0.27924769 | S32: done | T32: 1 | U32: 27 | V32: -4308.22 | W32: 24 | X32: - | Y32: - | Z32: - | AA32: MARTINEZ PEREZ OSCAR IVAN | AB32: 14110465 | AC32: MARTINEZ PEREZ OSCAR IVAN | AD32: 14110465 | AE32: SISTEMA | AF32: AUTOMÁTICO | AG32: AUTOMÁTICO | AH32: 36 | AI32: Ok | AJ32: Retrasado,A tiempo | AK32: 1242 | AL32: 0 | AM32: Fijo más Variable por KM | AN32: Mensual | AO32: AUTOMÁTICO | AP32: - | AQ32: 0.0034722222 | AR32: -0.012418981 | AS32: Inicia tarde | AT32: Llega a Tiempo | AU32: Inicia tarde-Llega a Tiempo | AV32: 36 | AW32: No | AX32: 8 De JulioPAQUETEXPRESS GDL | AY32: DAVID D. | AZ32: Leopoldo V. | BA32: PAQUETEXPRESS GDL8 De Julio | BB32: E-PAQ-R0009 | BC32: T1 | BD32: 8 De Julio-R0009-05:50
A33: 176538981 | B33: E-DJT-T1-R0004 | C33: LIPU Guadalajara | D33: Pochotitan Mujeres | E33: N | F33: 4 | H33: 13295 | I33: 7 | J33: IN | K33: DON JULIO TEPIC | L33: 46265 | M33: 0.24305556 | N33: 0.26597222 | O33: done | P33: 46265 | Q33: 0.33333333 | S33: start | T33: 0 | U33: 17 | V33: 1.86 | W33: 16.48 | X33: 33.78 | Y33: 17.3 | Z33: 0 | AA33: ROSALES AVILA MAXIMILIANO | AB33: 14122706 | AC33: ROSALES AVILA MAXIMILIANO | AD33: 14122706 | AE33: SISTEMA | AF33: AUTOMÁTICO | AG33: AUTOMÁTICO | AH33: 36 | AI33: Ok,Cabina | AJ33: Retrasado | AK33: - | AL33: 0 | AM33: Fijo más Variable por KM | AN33: Sin asignar | AO33: AUTOMÁTICO | AP33: - | AQ33: 0.022916667 | AR33: -0.33333333 | AS33: Inicia tarde | AT33: Llega a Tiempo | AU33: Inicia tarde-Llega a Tiempo | AV33: 36 | AW33: No | AX33: Pochotitan MujeresDON JULIO TEPIC | AY33: VIRIDIANA G | AZ33: Ilse M. | BA33: DON JULIO TEPIC Pochotitan Mujeres | BB33: E-DJT-R0004 | BC33: T1 | BD33: Pochotitan Mujeres-R0004-05:50
A34: 176541176 | B34: E-ZFF-T1-R0049 | C34: LIPU Guadalajara | D34: ADM Santa Mago | E34: N | F34: 49 | H34: 6802 | I34: 6 | J34: IN | K34: ZF FORANEO | L34: 46265 | M34: 0.25 | N34: 0.25902778 | O34: done | P34: 46265 | Q34: 0.33333333 | R34: 0.3087037 | S34: done | T34: 1 | U34: 48 | V34: 46.59 | W34: 46.22 | X34: - | Y34: - | Z34: - | AA34: GOMEZ DELGADILLO MARCO ANTONIO | AB34: 14114431 | AC34: GOMEZ DELGADILLO MARCO ANTONIO | AD34: 14114431 | AE34: SISTEMA | AF34: AUTOMÁTICO | AG34: AUTOMÁTICO | AH34: 36 | AI34: Ok | AJ34: Retrasado,A tiempo | AK34: 0 | AL34: N/A | AM34: Variable por Ruta | AN34: Sin asignar | AO34: AUTOMÁTICO | AP34: - | AQ34: 0.0090277778 | AR34: -0.02462963 | AS34: Inicia tarde | AT34: Llega a Tiempo | AU34: Inicia tarde-Llega a Tiempo | AV34: 36 | AW34: No | AX34: ADM Santa MagoZF FORANEO | AY34: AGEO C. | AZ34: Ilse M. | BA34: ZF FORANEOADM Santa Mago | BB34: E-ZFF-R0049 | BC34: T1 | BD34: ADM Santa Mago-R0049-06:00
A35: 176544391 | B35: E-DJT-T1-R0009 | C35: LIPU Guadalajara | D35: San Fernando | E35: N | F35: 9 | H35: 14866 | I35: 5 | J35: IN | K35: DON JULIO TEPIC | L35: 46265 | M35: 0.25 | N35: 0.25486111 | O35: done | P35: 46265 | Q35: 0.33333333 | S35: start | U35: 17 | V35: - | W35: 20.4 | X35: 22.1 | Y35: 1.7 | Z35: 0 | AA35: VILLEGAS HUIZAR FERNANDO | AB35: 14108361 | AC35: VILLEGAS HUIZAR FERNANDO | AD35: 14108361 | AE35: SISTEMA | AF35: AUTOMÁTICO | AG35: AUTOMÁTICO | AH35: 36 | AI35: Ok,Cabina | AJ35: Retrasado | AK35: - | AL35: 0 | AM35: Fijo más Variable por KM | AN35: Sin asignar | AO35: AUTOMÁTICO | AP35: - | AQ35: 0.0048611111 | AR35: -0.33333333 | AS35: Inicia tarde | AT35: Llega a Tiempo | AU35: Inicia tarde-Llega a Tiempo | AV35: 36 | AW35: No | AX35: San FernandoDON JULIO TEPIC | AY35: VIRIDIANA G | AZ35: Ilse M. | BA35: DON JULIO TEPIC San Fernando | BB35: E-DJT-R0009 | BC35: T1 | BD35: San Fernando-R0009-06:00
A36: 176543628 | B36: E-MOL-T1-R0028 | C36: LIPU Guadalajara | D36: ADM Arcos de Zapopan | E36: N | F36: 28 | H36: 15485 | I36: 6 | J36: IN | K36: MOLEX | L36: 46265 | M36: 0.26041667 | N36: 0.26458333 | O36: done | P36: 46265 | Q36: 0.3125 | R36: 0.30070602 | S36: done | T36: 1 | U36: 62 | V36: 58.79 | W36: 58.84 | X36: - | Y36: - | Z36: - | AA36: DIAZ BLANQUET ROSA JANNET | AB36: 14110604 | AC36: DIAZ BLANQUET ROSA JANNET | AD36: 14110604 | AE36: SISTEMA | AF36: AUTOMÁTICO | AG36: AUTOMÁTICO | AH36: 36 | AI36: Ok | AJ36: Retrasado,A tiempo | AK36: 0 | AL36: N/A | AM36: Variable por Ruta | AN36: Sin asignar | AO36: AUTOMÁTICO | AP36: - | AQ36: 0.0041666667 | AR36: -0.011793981 | AS36: Inicia tarde | AT36: Llega a Tiempo | AU36: Inicia tarde-Llega a Tiempo | AV36: 36 | AW36: No | AX36: ADM Arcos de ZapopanMOLEX | AY36: VICTOR C. | AZ36: Leopoldo V. | BA36: MOLEXADM Arcos de Zapopan | BB36: E-MOL-R0028 | BC36: T1 | BD36: ADM Arcos de Zapopan-R0028-06:15
A37: 176538551 | B37: E-SK1-T1-R0001 | C37: LIPU Guadalajara | D37: ADM Calzada | E37: N | F37: 1 | G37: ADM | H37: 16783 | I37: 6 | J37: IN | K37: SANMINA KAMPUS 16 | L37: 46265 | M37: 0.27430556 | N37: 0.27916667 | O37: done | P37: 46265 | Q37: 0.33333333 | R37: 0.31969907 | S37: done | T37: 1 | U37: 28 | V37: 25.16 | W37: 25.31 | X37: - | Y37: - | Z37: - | AA37: SALAMANCA SALAS JOSE VICTORIAN | AB37: 14122067 | AC37: SALAMANCA SALAS JOSE VICTORIAN | AD37: 14122067 | AE37: SISTEMA | AF37: AUTOMÁTICO | AG37: AUTOMÁTICO | AH37: 36 | AI37: Ok | AJ37: Retrasado,A tiempo | AK37: 0 | AL37: N/A | AM37: Variable por Ruta | AN37: Sin asignar | AO37: AUTOMÁTICO | AP37: - | AQ37: 0.0048611111 | AR37: -0.013634259 | AS37: Inicia tarde | AT37: Llega a Tiempo | AU37: Inicia tarde-Llega a Tiempo | AV37: 36 | AW37: No | AX37: ADM CalzadaSANMINA KAMPUS 16 | AY37: BRIAN A. | AZ37: Felipe M. | BA37: SANMINA KAMPUS 16ADM Calzada | BB37: E-SK1-R0001 | BC37: T1 | BD37: ADM Calzada-R0001-06:35
A38: 176545063 | B38: E-SA4-T1-R0099 | C38: LIPU Guadalajara | D38: Ocotlan 2 | E38: N | F38: 99 | G38: ADM HM | H38: 17343 | I38: 6 | J38: IN | K38: SANMINA ADM | L38: 46265 | M38: 0.27638889 | N38: 0.30486111 | O38: done | P38: 46265 | Q38: 0.34722222 | R38: 0.35658565 | S38: done | T38: 1 | U38: 64 | V38: 60.42 | W38: 60.78 | X38: - | Y38: - | Z38: - | AA38: MEDINA SALAZAR CARLOS ERNESTO | AB38: 14115136 | AC38: MEDINA SALAZAR CARLOS ERNESTO | AD38: 14115136 | AE38: SISTEMA | AF38: AUTOMÁTICO | AG38: AUTOMÁTICO | AH38: 36 | AI38: Ok | AJ38: Retrasado | AK38: 0 | AL38: N/A | AM38: Variable por Ruta | AN38: Sin asignar | AO38: AUTOMÁTICO | AP38: - | AQ38: 0.028472222 | AR38: 0.0093634259 | AS38: Inicia tarde | AT38: Llega tarde | AU38: Inicia tarde-Llega tarde | AV38: 36 | AW38: No | AX38: Ocotlan 2SANMINA ADM | AY38: FELIPE G. | AZ38: Felipe M. | BA38: SANMINA ADMOcotlan 2 | BB38: E-SA4-R0099 | BC38: T1 | BD38: Ocotlan 2-R0099-06:38
A39: 176545047 | B39: E-SA4-T1-R0083 | C39: LIPU Guadalajara | D39: Gran Fonda | E39: N | F39: 83 | G39: ADM HM | H39: 6353 | I39: 6 | J39: IN | K39: SANMINA ADM | L39: 46265 | M39: 0.27777778 | N39: 0.30416667 | O39: done | P39: 46265 | Q39: 0.34722222 | R39: 0.34556713 | S39: done | T39: 1 | U39: 35 | V39: 28.43 | W39: 28.67 | X39: - | Y39: - | Z39: - | AA39: MAGDALENO RAMIREZ EDGAR ANTONI | AB39: 14121860 | AC39: MAGDALENO RAMIREZ EDGAR ANTONI | AD39: 14121860 | AE39: SISTEMA | AF39: AUTOMÁTICO | AG39: AUTOMÁTICO | AH39: 36 | AI39: Ok | AJ39: Retrasado,A tiempo | AK39: 0 | AL39: N/A | AM39: Variable por Ruta | AN39: Sin asignar | AO39: AUTOMÁTICO | AP39: - | AQ39: 0.026388889 | AR39: -0.0016550926 | AS39: Inicia tarde | AT39: Llega a Tiempo | AU39: Inicia tarde-Llega a Tiempo | AV39: 36 | AW39: No | AX39: Gran FondaSANMINA ADM | AY39: FELIPE G. | AZ39: Felipe M. | BA39: SANMINA ADMGran Fonda | BB39: E-SA4-R0083 | BC39: T1 | BD39: Gran Fonda-R0083-06:40
A40: 176545069 | B40: E-SA4-T1-R0105 | C40: LIPU Guadalajara | D40: Ocotlan 3 | E40: N | F40: 105 | G40: ADM HM | H40: 17340 | I40: 6 | J40: IN | K40: SANMINA ADM | L40: 46265 | M40: 0.27777778 | N40: 0.30277778 | O40: done | P40: 46265 | Q40: 0.34722222 | R40: 0.34395833 | S40: done | T40: 1 | U40: 47 | V40: 19.35 | W40: 43.42 | X40: - | Y40: - | Z40: - | AA40: LUNA SANDOVAL DAVID | AB40: 14108111 | AC40: LUNA SANDOVAL DAVID | AD40: 14108111 | AE40: SISTEMA | AF40: AUTOMÁTICO | AG40: AUTOMÁTICO | AH40: 36 | AI40: Ok | AJ40: Retrasado,A tiempo | AK40: 0 | AL40: N/A | AM40: Variable por Ruta | AN40: Sin asignar | AO40: AUTOMÁTICO | AP40: - | AQ40: 0.025 | AR40: -0.0032638889 | AS40: Inicia tarde | AT40: Llega a Tiempo | AU40: Inicia tarde-Llega a Tiempo | AV40: 36 | AW40: No | AX40: Ocotlan 3SANMINA ADM | AY40: FELIPE G. | AZ40: Felipe M. | BA40: SANMINA ADMOcotlan 3 | BB40: E-SA4-R0105 | BC40: T1 | BD40: Ocotlan 3-R0105-06:40
...

Sheet ACUMULADO
A1: agrupador | B1: concepto | C1: clave | D1: nombre_completo | E1: periodo | F1: importe
A2: PERCEPCIONES | B2: AYUDA ESCOLAR | C2: 16124304 | D2: SERNA ALANIS EMMANUEL OQUITZI | E2: S38 | F2: 1950
A3: PERCEPCIONES | B3: AYUDA ESCOLAR | C3: 16123865 | D3: RUBIO REYES ROBERTO | E3: S38 | F3: 2350
A4: PERCEPCIONES | B4: BONO DESEMPEÑO | C4: 14124376 | D4: ORTIZ ROBLES LUIS RAMON | E4: S38 | F4: 268.36
A5: PERCEPCIONES | B5: BONO DESEMPEÑO | C5: 14124352 | D5: ROJAS LOZANO LUIS BENJAMIN | E5: S38 | F5: 268.36
A6: PERCEPCIONES | B6: BONO DESEMPEÑO | C6: 14124334 | D6: FRIAS TERRONES GILBERTO | E6: S38 | F6: 645.8
A7: PERCEPCIONES | B7: BONO DESEMPEÑO | C7: 14124320 | D7: JIMENEZ VALDES ERNESTO | E7: S38 | F7: 468.36
A8: PERCEPCIONES | B8: BONO DESEMPEÑO | C8: 14124303 | D8: DE LEON TORRES RAMON | E8: S38 | F8: 645.8
A9: PERCEPCIONES | B9: BONO DESEMPEÑO | C9: 14124286 | D9: SANCHEZ GOMEZ JUAN CARLOS | E9: S38 | F9: 645.8
A10: PERCEPCIONES | B10: BONO DESEMPEÑO | C10: 14124263 | D10: SOTO RAMOS FRANCISCO FERNANDO | E10: S38 | F10: 268.36
A11: PERCEPCIONES | B11: BONO DESEMPEÑO | C11: 14124260 | D11: MENDEZ MANZO JOSE MANUEL | E11: S38 | F11: 645.8
A12: PERCEPCIONES | B12: BONO DESEMPEÑO | C12: 14124254 | D12: RAMOS TENE JUAN CARLOS | E12: S38 | F12: 645.8
A13: PERCEPCIONES | B13: BONO DESEMPEÑO | C13: 14124244 | D13: OCEGUEDA GONZALEZ DAVID SALVADOR | E13: S38 | F13: 511.62
... A3326: PERCEPCIONES | B3326: SUELDO | C3326: 14100913 | D3326: SANCHEZ PICHARDO JUAN | E3326: S38 | F3326: 3052.84

Sheet DMAS
A1: driver_name | B1: 46285 | C1: 46284 | D1: 46283 | E1: 46282 | F1: 46281 | G1: 46280 | H1: 46279 | I1: 46278 | J1: 46277 | K1: 46276 | L1: 46275 | M1: 46274 | N1: 46273 | O1: 46272 | P1: 46271 | Q1: 46270 | R1: 46269 | S1: 46268 | T1: 46267 | U1: 46266 | V1: 46265 | W1: Nomina | X1: CEROS | Y1: LOGUEO
A2: GARCIA SALCEDO FRANCISCO JAVIE | B2: 3.93 | C2: 5.58 | D2: 5.98 | E2: 6.19 | F2: 1.25 | G2: 6.2699 | H2: 7 | I2: 3.88 | J2: 5.85 | K2: 6.98 | L2: 6.2699 | M2: 6.8399 | N2: 7.06 | O2: 1.47 | P2: 5.21 | Q2: 6.82 | R2: 6.82 | S2: 6.7699 | T2: 6.66 | U2: 7.93 | V2: 6.55 | W2: 14109436 | X2: =COUNTIF(P2:V2,0) -> 0 | Y2: =IF(X2>1,"NO LOGUEO","LOGUEO") -> LOGUEO
A3: GALLEGOS PEREZ BERNARDO CRUZ | B3: 0 | C3: 3.43 | D3: 3.35 | E3: 3.8 | F3: 0 | G3: 2.61 | H3: 3.62 | I3: 4.4799 | J3: 3.59 | K3: 3.56 | L3: 4.29 | M3: 3.29 | N3: 3.68 | O3: 3.65 | P3: 0 | Q3: 3.56 | R3: 3.55 | S3: 3.75 | T3: 3.47 | U3: 3.3 | V3: 3.58 | W3: 14117986 | X3: =COUNTIF(P3:V3,0) -> 1 | Y3: =IF(X3>1,"NO LOGUEO","LOGUEO") -> LOGUEO
A4: P.NUNO SUAREZ AMADO | B4: 0 | C4: 0 | D4: 0 | E4: 0 | F4: 0 | G4: 0 | H4: 0 | I4: 0 | J4: 0 | K4: 0 | L4: 1.93 | M4: 1.94 | N4: 0 | O4: 0 | P4: 0 | Q4: 0 | R4: 0 | S4: 0 | T4: 0 | U4: 0 | V4: 0 | X4: =COUNTIF(P4:V4,0) -> 7 | Y4: =IF(X4>1,"NO LOGUEO","LOGUEO") -> NO LOGUEO
A5: P.SANCHEZ CASTELLANOS ANTONIO DE JESUS | B5: 4.23 | C5: 0 | D5: 0.85 | E5: 0 | F5: 0 | G5: 6.67 | H5: 2.2799 | I5: 0 | J5: 0 | K5: 7.14 | L5: 1.97 | M5: 0 | N5: 0 | O5: 0 | P5: 0 | Q5: 0 | R5: 0 | S5: 0 | T5: 0 | U5: 0 | V5: 0 | X5: =COUNTIF(P5:V5,0) -> 7 | Y5: =IF(X5>1,"NO LOGUEO","LOGUEO") -> NO LOGUEO
A6: P.RAMIREZ RAMIREZ LINO | B6: 0 | C6: 0 | D6: 0 | E6: 0 | F6: 0 | G6: 0 | H6: 4.35 | I6: 0 | J6: 0 | K6: 0 | L6: 0 | M6: 0.63 | N6: 0 | O6: 0 | P6: 0 | Q6: 0 | R6: 0 | S6: 0 | T6: 0 | U6: 0 | V6: 0 | X6: =COUNTIF(P6:V6,0) -> 7 | Y6: =IF(X6>1,"NO LOGUEO","LOGUEO") -> NO LOGUEO
A7: SANCHEZ PONCE JOSE ALBERTO | B7: 0 | C7: 6.34 | D7: 7.42 | E7: 12.11 | F7: 8.65 | G7: 2.67 | H7: 0 | I7: 0 | J7: 4.22 | K7: 5.79 | L7: 9.7099 | M7: 7.31 | N7: 8.39 | O7: 2.47 | P7: 0 | Q7: 5.21 | R7: 11.28 | S7: 6.85 | T7: 9.49 | U7: 0 | V7: 0 | W7: 14100902 | X7: =COUNTIF(P7:V7,0) -> 3 | Y7: =IF(X7>1,"NO LOGUEO","LOGUEO") -> NO LOGUEO
A8: P.PARRA MAGANA JOSE ANDRES | B8: 0 | C8: 0 | D8: 0.73 | E8: 0 | F8: 0 | G8: 2.43 | H8: 0 | I8: 0 | J8: 2.48 | K8: 3.77 | L8: 0 | M8: 0.92 | N8: 0 | O8: 0 | P8: 0 | Q8: 0 | R8: 0 | S8: 0 | T8: 0 | U8: 0 | V8: 0 | X8: =COUNTIF(P8:V8,0) -> 7 | Y8: =IF(X8>1,"NO LOGUEO","LOGUEO") -> NO LOGUEO
A9: MARTINEZ LOPEZ PEDRO ALBERTO | B9: 0 | C9: 0 | D9: 10.15 | E9: 0 | F9: 4.38 | G9: 0 | H9: 6.75 | I9: 1.58 | J9: 10 | K9: 0 | L9: 12.02 | M9: 0 | N9: 11.4199 | O9: 1.35 | P9: 0 | Q9: 0 | R9: 10.93 | S9: 0 | T9: 0 | U9: 0 | V9: 1.53 | X9: =COUNTIF(P9:V9,0) -> 5 | Y9: =IF(X9>1,"NO LOGUEO","LOGUEO") -> NO LOGUEO
A10: P.MARTINEZ LOPEZ PEDRO ALBERTO | B10: 0 | C10: 0 | D10: 0 | E10: 0 | F10: 0 | G10: 0 | H10: 0 | I10: 0 | J10: 0 | K10: 0 | L10: 0 | M10: 0 | N10: 0 | O10: 0 | P10: 0 | Q10: 0 | R10: 0 | S10: 0 | T10: 0 | U10: 0 | V10: 0 | X10: =COUNTIF(P10:V10,0) -> 7 | Y10: =IF(X10>1,"NO LOGUEO","LOGUEO") -> NO LOGUEO
A11: P.CAMPOS RIOS JUAN CARLOS | B11: 5.13 | C11: 0 | D11: 0 | E11: 6.19 | F11: 0 | G11: 5.4 | H11: 3.67 | I11: 0 | J11: 0 | K11: 0 | L11: 5.55 | M11: 0 | N11: 0 | O11: 0 | P11: 0 | Q11: 0 | R11: 0 | S11: 0 | T11: 0 | U11: 0 | V11: 0 | X11: =COUNTIF(P11:V11,0) -> 7 | Y11: =IF(X11>1,"NO LOGUEO","LOGUEO") -> NO LOGUEO
A12: ESPARZA OCHOA ARMANDO | B12: 6.67 | C12: 4.2699 | D12: 5.38 | E12: 4.92 | F12: 1.92 | G12: 4.63 | H12: 5.5 | I12: 4.47 | J12: 4.35 | K12: 4.5299 | L12: 5.67 | M12: 3.68 | N12: 0 | O12: 3.89 | P12: 4.5599 | Q12: 7.51 | R12: 6.3 | S12: 4.72 | T12: 6.49 | U12: 4.87 | V12: 5.1 | W12: 14121543 | X12: =COUNTIF(P12:V12,0) -> 0 | Y12: =IF(X12>1,"NO LOGUEO","LOGUEO") -> LOGUEO
A13: GARCIA GARCIA RUBEN | B13: 0 | C13: 3.52 | D13: 3.34 | E13: 3.36 | F13: 2.85 | G13: 3.98 | H13: 3.88 | I13: 2.41 | J13: 2.83 | K13: 3.78 | L13: 3.67 | M13: 4.43 | N13: 5.3 | O13: 3.7 | P13: 0 | Q13: 4.63 | R13: 3.24 | S13: 3.67 | T13: 1.78 | U13: 5.1099 | V13: 3.7299 | W13: 14114709 | X13: =COUNTIF(P13:V13,0) -> 1 | Y13: =IF(X13>1,"NO LOGUEO","LOGUEO") -> LOGUEO
A14: TAVERA MORALES SATURNINO | B14: 0 | C14: 11.06 | D14: 10.86 | E14: 8.32 | F14: 0 | G14: 0 | H14: 3.08 | I14: 4.2 | J14: 4.75 | K14: 4.73 | L14: 8.11 | M14: 4.32 | N14: 10.1299 | O14: 3.33 | P14: 5.16 | Q14: 7.2899 | R14: 8.41 | S14: 4.04 | T14: 7.43 | U14: 4.2 | V14: 10.87 | X14: =COUNTIF(P14:V14,0) -> 0 | Y14: =IF(X14>1,"NO LOGUEO","LOGUEO") -> LOGUEO
A15: CHAVEZ RUIZ ARMANDO | B15: 0 | C15: 5.87 | D15: 7.49 | E15: 5.53 | F15: 2.59 | G15: 6.54 | H15: 6.15 | I15: 1.47 | J15: 6.1299 | K15: 6.02 | L15: 6.13 | M15: 6.38 | N15: 5.46 | O15: 5.2499 | P15: 0 | Q15: 5.66 | R15: 6.0199 | S15: 7.1699 | T15: 7.44 | U15: 6.91 | V15: 5.34 | W15: 14121784 | X15: =COUNTIF(P15:V15,0) -> 1 | Y15: =IF(X15>1,"NO LOGUEO","LOGUEO") -> LOGUEO
A16: GARCIA RAZO VICTOR MANUEL | B16: 1.9 | C16: 3.37 | D16: 2.4699 | E16: 6.16 | F16: 1.37 | G16: 5.59 | H16: 3.62 | I16: 1.2 | J16: 2.88 | K16: 4.3 | L16: 8.27 | M16: 6.47 | N16: 8.52 | O16: 6.34 | P16: 1.57 | Q16: 7.88 | R16: 4.99 | S16: 5.51 | T16: 6.3 | U16: 5.16 | V16: 2.75 | W16: 14121809 | X16: =COUNTIF(P16:V16,0) -> 0 | Y16: =IF(X16>1,"NO LOGUEO","LOGUEO") -> LOGUEO
A17: AGUINAGA GUERRERO JOSE DAMIA | B17: 1.98 | C17: 7.4 | D17: 0.62 | E17: 11.78 | F17: 0 | G17: 18.73 | H17: 6.4799 | I17: 32.03 | J17: 10.4299 | K17: 29.42 | L17: 7.63 | M17: 9.23 | N17: 5.2699 | O17: 9.8799 | P17: 2.0099 | Q17: 10.7299 | R17: 10.3599 | S17: 16.79 | T17: 6.21 | U17: 10.7 | V17: 5.51 | X17: =COUNTIF(P17:V17,0) -> 0 | Y17: =IF(X17>1,"NO LOGUEO","LOGUEO") -> LOGUEO
A18: DE LA ROSA PORTUGAL ALBERTO | B18: 5.44 | C18: 2.86 | D18: 6.81 | E18: 2.29 | F18: 4.8999 | G18: 5.3199 | H18: 2.25 | I18: 5.1499 | J18: 4.76 | K18: 3.67 | L18: 0 | M18: 4.72 | N18: 5.6 | O18: 6.17 | P18: 5.33 | Q18: 5.0699 | R18: 4.85 | S18: 4.9599 | T18: 4.47 | U18: 5.2399 | V18: 5.69 | W18: 14121672 | X18: =COUNTIF(P18:V18,0) -> 0 | Y18: =IF(X18>1,"NO LOGUEO","LOGUEO") -> LOGUEO
A19: DE LA CRUZ PLASCENCIA ARMANDO | B19: 9.18 | C19: 5.0299 | D19: 3.41 | E19: 4.7899 | F19: 1.23 | G19: 4.8999 | H19: 3.67 | I19: 5.27 | J19: 0 | K19: 1.99 | L19: 3.76 | M19: 3.34 | N19: 2.87 | O19: 5.11 | P19: 10.85 | Q19: 4.94 | R19: 3.07 | S19: 2.7199 | T19: 3.1399 | U19: 3.96 | V19: 2.96 | W19: 14121733 | X19: =COUNTIF(P19:V19,0) -> 0 | Y19: =IF(X19>1,"NO LOGUEO","LOGUEO") -> LOGUEO
A20: CAMPOS LOPEZ JOEL SALVADOR | B20: 0 | C20: 8.03 | D20: 7 | E20: 7.9 | F20: 1.35 | G20: 7.62 | H20: 7.2 | I20: 5.32 | J20: 8.55 | K20: 7.1599 | L20: 2.99 | M20: 8.09 | N20: 6.95 | O20: 8.3699 | P20: 6.15 | Q20: 8.1299 | R20: 9.6599 | S20: 10.81 | T20: 6.53 | U20: 9.7099 | V20: 7.09 | X20: =COUNTIF(P20:V20,0) -> 0 | Y20: =IF(X20>1,"NO LOGUEO","LOGUEO") -> LOGUEO
A21: P.CAMPOS LOPEZ JOEL SALVADOR | B21: 0 | C21: 0 | D21: 0 | E21: 0 | F21: 0 | G21: 0 | H21: 0 | I21: 0 | J21: 0 | K21: 0 | L21: 0 | M21: 0 | N21: 0 | O21: 0 | P21: 0 | Q21: 0 | R21: 0 | S21: 0 | T21: 0 | U21: 0 | V21: 0 | X21: =COUNTIF(P21:V21,0) -> 7 | Y21: =IF(X21>1,"NO LOGUEO","LOGUEO") -> NO LOGUEO
A22: A.HERNANDEZ BEDOLLA MIGUEL ANGEL | B22: 0 | C22: 0 | D22: 0 | E22: 0.22 | F22: 0 | G22: 0 | H22: 0.77 | I22: 0 | J22: 0 | K22: 0 | L22: 0 | M22: 0.8 | N22: 0 | O22: 0 | P22: 0 | Q22: 0 | R22: 1.18 | S22: 0 | T22: 0 | U22: 0.4 | V22: 0.33 | X22: =COUNTIF(P22:V22,0) -> 4 | Y22: =IF(X22>1,"NO LOGUEO","LOGUEO") -> NO LOGUEO
A23: P.VAZQUEZ LUCAS LUIS FERNANDO | B23: 0 | C23: 0 | D23: 0 | E23: 0 | F23: 0 | G23: 0 | H23: 0 | I23: 0 | J23: 0 | K23: 0 | L23: 0 | M23: 0 | N23: 0 | O23: 0 | P23: 0 | Q23: 0 | R23: 0 | S23: 0 | T23: 0 | U23: 0 | V23: 0 | X23: =COUNTIF(P23:V23,0) -> 7 | Y23: =IF(X23>1,"NO LOGUEO","LOGUEO") -> NO LOGUEO
A24: P.MENDEZ CAMPOS RUBEN | B24: 0 | C24: 0 | D24: 0 | E24: 0 | F24: 0 | G24: 0 | H24: 0 | I24: 0 | J24: 0 | K24: 0 | L24: 0 | M24: 0 | N24: 0 | O24: 0 | P24: 0 | Q24: 0 | R24: 0 | S24: 0 | T24: 0 | U24: 0 | V24: 0 | X24: =COUNTIF(P24:V24,0) -> 7 | Y24: =IF(X24>1,"NO LOGUEO","LOGUEO") -> NO LOGUEO
A25: DURAN DIAZ MARIO ALBERTO | B25: 0 | C25: 0 | D25: 12.52 | E25: 4.4 | F25: 0 | G25: 0 | H25: 0 | I25: 0 | J25: 0 | K25: 0 | L25: 0 | M25: 0 | N25: 0 | O25: 0 | P25: 0 | Q25: 4.82 | R25: 3.84 | S25: 0 | T25: 0 | U25: 0 | V25: 1.88 | X25: =COUNTIF(P25:V25,0) -> 4 | Y25: =IF(X25>1,"NO LOGUEO","LOGUEO") -> NO LOGUEO
A26: P.DURAN DIAZ MARIO ALBERTO | B26: 0 | C26: 0 | D26: 0 | E26: 0 | F26: 0 | G26: 0 | H26: 0 | I26: 0 | J26: 0 | K26: 0 | L26: 0 | M26: 0 | N26: 0 | O26: 0 | P26: 0 | Q26: 0 | R26: 0 | S26: 0 | T26: 0 | U26: 0 | V26: 0 | X26: =COUNTIF(P26:V26,0) -> 7 | Y26: =IF(X26>1,"NO LOGUEO","LOGUEO") -> NO LOGUEO
A27: P.VAZQUEZ HERNANDEZ RODOLFO | B27: 0 | C27: 0 | D27: 0 | E27: 0 | F27: 0 | G27: 0 | H27: 0 | I27: 0 | J27: 0 | K27: 0 | L27: 0 | M27: 0 | N27: 0 | O27: 0 | P27: 0 | Q27: 0 | R27: 0 | S27: 0 | T27: 0 | U27: 0 | V27: 0 | X27: =COUNTIF(P27:V27,0) -> 7 | Y27: =IF(X27>1,"NO LOGUEO","LOGUEO") -> NO LOGUEO
A28: SERRANO MACHUCA MARTIN DE JESU | B28: 2.8 | C28: 4.1 | D28: 4.68 | E28: 7.46 | F28: 0.32 | G28: 3.52 | H28: 6.15 | I28: 1.08 | J28: 3.78 | K28: 5.95 | L28: 8.07 | M28: 8.17 | N28: 2.4 | O28: 6.28 | P28: 1.7599 | Q28: 1.56 | R28: 3.2199 | S28: 0 | T28: 0 | U28: 0 | V28: 0 | W28: 14104315 | X28: =COUNTIF(P28:V28,0) -> 4 | Y28: =IF(X28>1,"NO LOGUEO","LOGUEO") -> NO LOGUEO
A29: MEZA RAMIREZ FEDERICO | B29: 2.27 | C29: 5.39 | D29: 4.93 | E29: 2.67 | F29: 3.17 | G29: 8.5899 | H29: 2.97 | I29: 2.4 | J29: 11 | K29: 4.95 | L29: 10.26 | M29: 5.1 | N29: 5.48 | O29: 6.64 | P29: 0 | Q29: 9.84 | R29: 7.77 | S29: 8.8899 | T29: 5.24 | U29: 8.47 | V29: 0 | X29: =COUNTIF(P29:V29,0) -> 2 | Y29: =IF(X29>1,"NO LOGUEO","LOGUEO") -> NO LOGUEO
A30: P.MEZA RAMIREZ FEDERICO | B30: 0 | C30: 0 | D30: 0 | E30: 0 | F30: 0 | G30: 0 | H30: 0 | I30: 0 | J30: 0 | K30: 0 | L30: 0 | M30: 0 | N30: 0 | O30: 0 | P30: 0 | Q30: 0 | R30: 0 | S30: 0 | T30: 0 | U30: 0 | V30: 0 | X30: =COUNTIF(P30:V30,0) -> 7 | Y30: =IF(X30>1,"NO LOGUEO","LOGUEO") -> NO LOGUEO
A31: P.CAMPOS CRUZ LUIS ALBERTO | B31: 0 | C31: 0 | D31: 0 | E31: 0 | F31: 0 | G31: 0 | H31: 0 | I31: 0 | J31: 0 | K31: 0 | L31: 0 | M31: 0 | N31: 0 | O31: 0 | P31: 0 | Q31: 0 | R31: 0 | S31: 0 | T31: 0 | U31: 0 | V31: 0 | X31: =COUNTIF(P31:V31,0) -> 7 | Y31: =IF(X31>1,"NO LOGUEO","LOGUEO") -> NO LOGUEO
A32: MARTINEZ MORENO JAVAN EMILIANO | B32: 7.12 | C32: 6.6 | D32: 7.75 | E32: 6.73 | F32: 7.69 | G32: 8.3199 | H32: 6.72 | I32: 0 | J32: 6.25 | K32: 7.18 | L32: 7.43 | M32: 6.8 | N32: 6.9 | O32: 7.35 | P32: 6.58 | Q32: 8.7899 | R32: 7.27 | S32: 7.17 | T32: 7.4 | U32: 0 | V32: 6.6 | X32: =COUNTIF(P32:V32,0) -> 1 | Y32: =IF(X32>1,"NO LOGUEO","LOGUEO") -> LOGUEO
A33: P.MARTINEZ MORENO JAVAN EMILIANO | B33: 0 | C33: 0 | D33: 0 | E33: 0 | F33: 0 | G33: 0 | H33: 0 | I33: 0 | J33: 0 | K33: 0 | L33: 0 | M33: 0 | N33: 0 | O33: 0 | P33: 0 | Q33: 0 | R33: 0 | S33: 0 | T33: 0 | U33: 0 | V33: 0 | X33: =COUNTIF(P33:V33,0) -> 7 | Y33: =IF(X33>1,"NO LOGUEO","LOGUEO") -> NO LOGUEO
A34: PROCOPIO MENDOZA JUAN FERNANDO | B34: 0.42 | C34: 10.12 | D34: 9.73 | E34: 12.6499 | F34: 8.8699 | G34: 13.82 | H34: 9.96 | I34: 0 | J34: 7.11 | K34: 13.18 | L34: 10.2899 | M34: 14.05 | N34: 9.95 | O34: 13.91 | P34: 0.4 | Q34: 10.51 | R34: 10.1599 | S34: 12.97 | T34: 10.23 | U34: 13.99 | V34: 10.06 | W34: 14121522 | X34: =COUNTIF(P34:V34,0) -> 0 | Y34: =IF(X34>1,"NO LOGUEO","LOGUEO") -> LOGUEO
A35: BARAJAS TOVAR JAVIER IGNACIO | B35: 0 | C35: 0 | D35: 0 | E35: 0 | F35: 0 | G35: 0 | H35: 0 | I35: 0 | J35: 0 | K35: 5.03 | L35: 9.1399 | M35: 0 | N35: 9.58 | O35: 7.03 | P35: 3.8 | Q35: 8.52 | R35: 9.5 | S35: 8.35 | T35: 7.73 | U35: 11.5399 | V35: 9.77 | X35: =COUNTIF(P35:V35,0) -> 0 | Y35: =IF(X35>1,"NO LOGUEO","LOGUEO") -> LOGUEO
A36: P.BARAJAS TOVAR JAVIER IGNACIO | B36: 0 | C36: 0 | D36: 0 | E36: 0 | F36: 0 | G36: 0 | H36: 0 | I36: 0 | J36: 0 | K36: 0 | L36: 0 | M36: 0 | N36: 0 | O36: 0 | P36: 0 | Q36: 0 | R36: 0 | S36: 0 | T36: 0 | U36: 0 | V36: 0 | X36: =COUNTIF(P36:V36,0) -> 7 | Y36: =IF(X36>1,"NO LOGUEO","LOGUEO") -> NO LOGUEO
A37: GONZALEZ GERARDO URIEL | B37: 0 | C37: 0 | D37: 2.3499 | E37: 5.19 | F37: 1.91 | G37: 7.17 | H37: 6.43 | I37: 0 | J37: 6.51 | K37: 6.74 | L37: 6.2 | M37: 5 | N37: 0 | O37: 4.19 | P37: 4.07 | Q37: 1.5 | R37: 2.87 | S37: 7.04 | T37: 6.5899 | U37: 6.5 | V37: 5.55 | W37: 14121398 | X37: =COUNTIF(P37:V37,0) -> 0 | Y37: =IF(X37>1,"NO LOGUEO","LOGUEO") -> LOGUEO
A38: GUTIERREZ SEGURA JUAN ARMANDO | B38: 0 | C38: 0 | D38: 4.1 | E38: 3.74 | F38: 2.2199 | G38: 8.05 | H38: 7.19 | I38: 8.22 | J38: 7.07 | K38: 7.98 | L38: 4.5599 | M38: 0 | N38: 0 | O38: 0 | P38: 0 | Q38: 0 | R38: 0 | S38: 0 | T38: 0 | U38: 0 | V38: 0 | W38: 14112962 | X38: =COUNTIF(P38:V38,0) -> 7 | Y38: =IF(X38>1,"NO LOGUEO","LOGUEO") -> NO LOGUEO
A39: PINEDA VELAZQUEZ PASCUAL | B39: 5.17 | C39: 6.22 | D39: 7.32 | E39: 5.57 | F39: 5.88 | G39: 7.02 | H39: 6.0199 | I39: 0 | J39: 5.93 | K39: 6.08 | L39: 5.95 | M39: 0 | N39: 7.1 | O39: 5.73 | P39: 7.6199 | Q39: 6.02 | R39: 5.92 | S39: 7.3 | T39: 6.68 | U39: 5.6499 | V39: 6.56 | W39: 14118892 | X39: =COUNTIF(P39:V39,0) -> 0 | Y39: =IF(X39>1,"NO LOGUEO","LOGUEO") -> LOGUEO
A40: GUILLEN VEGA GUILLERMO | B40: 0 | C40: 11.1199 | D40: 10.08 | E40: 4.45 | F40: 8.0399 | G40: 4.47 | H40: 10.7099 | I40: 0 | J40: 9.1199 | K40: 4.74 | L40: 10.2199 | M40: 6.81 | N40: 5.21 | O40: 13.67 | P40: 0 | Q40: 5.72 | R40: 7.12 | S40: 1.92 | T40: 9.48 | U40: 4.58 | V40: 9.85 | W40: 14121545 | X40: =COUNTIF(P40:V40,0) -> 1 | Y40: =IF(X40>1,"NO LOGUEO","LOGUEO") -> LOGUEO
...

Sheet RENDIMIENTO
A2: CLAVE | B2: NOMBRE | C2: F.INGRESO | D2: UNIDAD | E2: META | F2: REDIMIENTO OBTENIDO | G2: TOTAL A PAGAR | H2: SEMANA DE RETROACTIVO
A3: 14100716 | B3: AMBRIZ MERCADO MARTIN | C3: 2017-05-01 | D3: LIPU | F3: #N/A
A4: 14100718 | B4: MARTINEZ OCHOA PAULO | C4: 2017-05-01 | D4: LIPU | E4: 11.418646 | F4: 11.4715 | G4: 355.58
A5: 14100721 | B5: GUTIERREZ VELEZ FRANCISCO | C5: 2021-07-08 | D5: LIPU | E5: 4.3532522 | F5: 4.1853333 | G5: 0
A6: 14100724 | B6: ORTIZ GARCIA LUIS ALBERTO | C6: 2017-05-01 | D6: LIPU | E6: 3.55 | F6: 3.7375 | G6: 355.58
A7: 14100725 | B7: NAJAR LOPEZ JOSE SERGIO | C7: 2017-05-01 | D7: LIPU | F7: #N/A
A8: 14100726 | B8: GUZMAN MUNGUIA LUIS JAVIER | C8: 2017-05-01 | D8: LIPU | E8: 3.96182 | F8: 4.224 | G8: 355.58
A9: 14100727 | B9: ALONZO PEREZ JOSE REYES | C9: 2017-05-01 | D9: LIPU | E9: 3.55 | F9: 3.9963333 | G9: 355.58
A10: 14100729 | B10: LARIOS ALCARAZ EDUARDO | C10: 2017-05-01 | D10: LIPU | E10: 4.6324259 | F10: 4.444 | G10: 0
A11: 14100731 | B11: TABARES FLORES OSCAR ALEJANDRO | C11: 2022-09-02 | D11: LIPU | E11: 4.4326521 | F11: 4.66 | G11: 355.58
A12: 14100732 | B12: ROBLES DEADEL LAZARO | C12: 2017-05-01 | D12: LIPU | E12: 3.7835575 | F12: 3.804 | G12: 355.58
A13: 14100733 | B13: LINARES CISNEROS JOSE ANTONIO | C13: 2017-05-01 | D13: LIPU | F13: #N/A
A14: 14100740 | B14: OLIVARES HERNANDEZ GABRIEL | C14: 2021-11-17 | D14: LIPU | E14: 4.4923786 | F14: 4.6565 | G14: 355.58
A15: 14100751 | B15: FLORES GARCIA PEDRO | C15: 2025-10-10 | D15: LIPU | E15: 3.9643828 | F15: 3.8515 | G15: 0
A16: 14100777 | B16: GONZALEZ MANZO JAVIER OSWALDO | C16: 2017-05-01 | D16: LIPU | F16: #N/A
A17: 14100787 | B17: YEPEZ VAZQUEZ JOAN | C17: 2017-05-01 | D17: LIPU | E17: 3.7922536 | F17: 4.308 | G17: 355.58
A18: 14100795 | B18: BALTAZAR MENDOZA HORACIO | C18: 2017-05-01 | D18: LIPU | E18: 4.662251 | F18: 4.7065 | G18: 355.58
A19: 14100798 | B19: CARRILLO REYNOSO JESUS ALEJANDRO | C19: 2017-05-01 | D19: LIPU | E19: 4.0644462 | F19: 4.3165 | G19: 355.58
A20: 14100807 | B20: OSORIO HERNANDEZ DOMINGO | C20: 2023-05-12 | D20: LIPU | E20: 4.7317431 | F20: 4.80625 | G20: 355.58
A21: 14100823 | B21: FLORES ENRIQUEZ JUAN PABLO | C21: 2024-08-05 | D21: LIPU | E21: 4.14 | F21: 4.0935 | G21: 355.58
A22: 14100842 | B22: BECERRA LUNA GUILLERMO | C22: 2017-05-01 | D22: LIPU | E22: 4.1596 | F22: 4.101 | G22: 355.58
A23: 14100843 | B23: LOPEZ RAYMUNDO ROBERTO | C23: 2025-03-07 | D23: LIPU | E23: 3.5970917 | F23: 3.703 | G23: 355.58
A24: 14100858 | B24: REYNAGA SANCHEZ MARIO | C24: 2025-06-06 | D24: LIPU | E24: 3.7394146 | F24: 3.866 | G24: 355.58
A25: 14100863 | B25: MARTINEZ ZAVALA FRANCISCO ESPIRIDION | C25: 2017-05-01 | D25: LIPU | E25: 4.2266718 | F25: 4.27325 | G25: 355.58
A26: 14100902 | B26: SANCHEZ PONCE JOSE ALBERTO | C26: 2025-12-31 | D26: LIPU | E26: Descansero | F26: Descansero | G26: 355.58
A27: 14101881 | B27: MORALES AGUILAR ALBERTO | C27: 2017-05-24 | D27: LIPU | E27: 3.9 | F27: 4.235 | G27: 355.58
A28: 14101984 | B28: TABARES VAZQUEZ MARTIN | C28: 2018-11-29 | D28: LIPU | E28: Descansero | F28: Descansero | G28: 355.58
A29: 14102081 | B29: OLEA SANCHEZ JOSE LUIS | C29: 2017-07-07 | D29: LIPU | E29: 8.4446762 | F29: 7.244 | G29: 0
A30: 14102288 | B30: RAMOS ANGUIANO SERGIO DAVID | C30: 2017-08-15 | D30: LIPU | E30: 3.9448622 | F30: 4.3516667 | G30: 355.58
A31: 14102701 | B31: ORTIZ HERNANDEZ JESUS GUADALUPE | C31: 2017-11-06 | D31: LIPU | E31: 3.9 | F31: 3.97 | G31: 355.58
A32: 14102730 | B32: ESTRADA ALVAREZ FERNANDO | C32: 2017-11-13 | D32: LIPU | E32: 3.9751644 | F32: 4.338 | G32: 355.58
A33: 14102875 | B33: LARIOS SANCHEZ HECTOR ALEXANDER | C33: 2017-12-20 | D33: LIPU | E33: 3.1315812 | F33: 4.419 | G33: 355.58
A34: 14102890 | B34: GONZALEZ VALENCIA BARTOLO | C34: 2017-12-21 | D34: LIPU | F34: #N/A
A35: 14103061 | B35: SANCHEZ PEREZ CARLOS FORTINO | C35: 2023-06-01 | D35: LIPU | E35: 3.6322725 | F35: 3.471 | G35: 0
A36: 14103106 | B36: CORTES ARMENTA HERNAN | C36: 2018-02-02 | D36: LIPU | E36: 4.0644255 | F36: 4.396 | G36: 355.58
A37: 14103183 | B37: HERNANDEZ RON BLANCA HERLINDA | C37: 2018-02-27 | D37: LIPU | F37: #N/A
A38: 14103335 | B38: RIVERA MARTINEZ GUSTAVO | C38: 2018-04-09 | D38: LIPU | E38: 3.55 | F38: 3.607 | G38: 355.58
A39: 14103679 | B39: BAUTISTA SOLORIO JAIME | C39: 2018-06-29 | D39: LIPU | E39: 9.2205582 | F39: 10.199 | G39: 355.58
A40: 14103936 | B40: GUTIERREZ GALINDO CARLOS DE JESUS | C40: 2025-08-23 | D40: LIPU | E40: 3.9908682 | F40: 3.782 | G40: 0
A41: 14103952 | B41: HERNANDEZ ORTEGA RAUL | C41: 2018-08-23 | D41: LIPU | F41: #N/A
...

Sheet CONSULTA
B1: NÓMINA
B2: 14107293
B3: NOMBRE | C3: =IFERROR(VLOOKUP(CONSULTA!$B$2,BONOS!$A$6:$BM$650,$H3,FALSE),"") -> MAGAÑA CONTRERAS JOSE LUIS | H3: =IFERROR(MATCH("NOMBRE ",BONOS!$A$6:$BM$6,0),"") -> 2
B4: SINIESTROS | C4: =IFERROR(VLOOKUP(CONSULTA!$B$2,BONOS!$A$6:$BM$650,$D4,FALSE),"") -> SIN SINIESTRO | D4: =IFERROR(MATCH("SINIESTROS",BONOS!$A$6:$BM$6,0),"") -> 5 | E4: BONO DE SCORE | G4: =IFERROR(VLOOKUP(CONSULTA!$B$2,BONOS!$A$6:$BM$650,$H4,FALSE),"") -> NO | H4: =IFERROR(MATCH("BONO SCORE",BONOS!$A$6:$BM$6,0),"") -> 8
B5: QUEJAS | C5: =IFERROR(VLOOKUP(CONSULTA!$B$2,BONOS!$A$6:$BM$650,$D5,FALSE),"") -> SIN QUEJA | D5: =IFERROR(MATCH("QUEJAS",BONOS!$A$6:$BM$6,0),"") -> 6 | E5: PUNTUALIDAD | G5: =IFERROR(VLOOKUP(CONSULTA!$B$2,BONOS!$A$6:$BM$650,$H5,FALSE),"") -> OK | H5: =IFERROR(MATCH("PUNTUALIDAD",BONOS!$A$6:$BM$6,0),"") -> 9
B6: SCORE OBTENIDO | C6: =IFERROR(VLOOKUP(CONSULTA!$B$2,BONOS!$A$6:$BM$650,$D6,FALSE),"") | D6: =IFERROR(MATCH("SCORE OBTENIDO",BONOS!$A$6:$BM$6,0),"") -> 7 | E6: BONO LOGUEO | G6: =IFERROR(VLOOKUP(CONSULTA!$B$2,BONOS!$A$6:$BM$650,$H6,FALSE),"") -> NO LOGUEO | H6: =IFERROR(MATCH("BONO LOGUEO",BONOS!$A$6:$BM$6,0),"") -> 10
B8: RENDIMEINTO META | C8: =IFERROR(VLOOKUP(CONSULTA!$B$2,RENDIMIENTO!$A$2:$BM$650,$D8,FALSE),"") -> 0 | D8: =IFERROR(MATCH("META",RENDIMIENTO!$A$2:$BM$2,0),"") -> 5 | E8: BONO 0 SINIESTROS | G8: =IFERROR(VLOOKUP(CONSULTA!$B$2,BONOS!$A$6:$BM$650,$H8,FALSE),"") -> 0 | H8: =IFERROR(MATCH("BONO SINIESTROS",BONOS!$A$6:$BM$6,0),"") -> 11
B9: REDIMIENTO OBTENIDO | C9: =IFERROR(VLOOKUP(CONSULTA!$B$2,RENDIMIENTO!$A$2:$BM$650,$D9,FALSE),"") | D9: =IFERROR(MATCH("REDIMIENTO OBTENIDO ",RENDIMIENTO!$A$2:$BM$2,0),"") -> 6 | E9: BONO 0 QUEJAS | G9: =IFERROR(VLOOKUP(CONSULTA!$B$2,BONOS!$A$6:$BM$650,$H9,FALSE),"") -> 0 | H9: =IFERROR(MATCH("BONO QUEJAS",BONOS!$A$6:$BM$6,0),"") -> 12
B10: SEMANA 38 | E10: BONO SCORE | G10: =IFERROR(VLOOKUP(CONSULTA!$B$2,BONOS!$A$6:$BM$650,$H10,FALSE),"") -> 0 | H10: =IFERROR(MATCH("BONO SCORE1",BONOS!$A$6:$BM$6,0),"") -> 14
E11: BONO LOGUEO | G11: =IFERROR(VLOOKUP(CONSULTA!$B$2,BONOS!$A$6:$BM$650,$H11,FALSE),"") -> 0 | H11: =IFERROR(MATCH("BONO LOGUEO1",BONOS!$A$6:$BM$6,0),"") -> 15
